Workbook

Sheet SCM KPI FY26 DASHBOARD
B2: PIONEER SCM KPI FY26 DASHBOARD | F2: NOV
H3: Operational Objectives Dashboard
B4: KPI | C4: Budget/Target | D4: Actual | E4: Status
B6: Conversion Cost (SC only) | C6: 11 | D6: {=INDEX('2026 KPI TRACKER'!$E$8:$P$8,MATCH('SCM KPI FY26 DASHBOARD'!F2,'2026 KPI TRACKER'!E4:P4,0))} -> 9.9039022 | E6: ● | H6: Production Reports
B7: Conversion Cost (Overall) | C7: 15 | D7: {=INDEX('2026 KPI TRACKER'!$E$9:$P$9,MATCH('SCM KPI FY26 DASHBOARD'!F2,'2026 KPI TRACKER'!E4:P4,0))} -> 15.555569 | E7: ●
B8: Volume Produced MT | C8: {=INDEX('2026 KPI TRACKER'!$E$12:$P$12,MATCH('SCM KPI FY26 DASHBOARD'!F2,'2026 KPI TRACKER'!E4:P4,0))} -> 1414.9244 | D8: {=INDEX('2026 KPI TRACKER'!$E$11:$P$11,MATCH('SCM KPI FY26 DASHBOARD'!F2,'2026 KPI TRACKER'!E4:P4,0))} -> 1603.4058 | E8: ● | H8: OUTPUT VS TARGET | M8: MACHINE UTLIZATION | R8: RMPM SAVINGS (M) | W8: FORECAST ACCURACY
B9: Fill Rate | C9: 0.99 | D9: {=INDEX('2026 KPI TRACKER'!$E$15:$P$15,MATCH('SCM KPI FY26 DASHBOARD'!F2,'2026 KPI TRACKER'!E4:P4,0))} -> 0.8076873 | E9: ● | H9: {=INDEX('2026 KPI TRACKER'!$E$37:$P$37,MATCH('SCM KPI FY26 DASHBOARD'!F2,'2026 KPI TRACKER'!E4:P4,0))} -> 1569.3354 | J9: MT | R9: {=INDEX('2026 KPI TRACKER'!$E$168:$P$168,MATCH('SCM KPI FY26 DASHBOARD'!F2,'2026 KPI TRACKER'!E4:P4,0))/1000} -> 2428.4741 | T9: Php | W9: {=INDEX('2026 KPI TRACKER'!$E$105:$P$105,MATCH('SCM KPI FY26 DASHBOARD'!F2,'2026 KPI TRACKER'!E4:P4,0))} -> 0.41602569 | Z9: LOCAL
B10: OTIF | C10: 0.7 | D10: {=INDEX('2026 KPI TRACKER'!$E$16:$P$16,MATCH('SCM KPI FY26 DASHBOARD'!F2,'2026 KPI TRACKER'!E4:P4,0))} -> NO VALUE | E10: ● | K10: {=INDEX('2026 KPI TRACKER'!$E$36:$P$36,MATCH('SCM KPI FY26 DASHBOARD'!F2,'2026 KPI TRACKER'!E4:P4,0))} -> 0.99412883 | M10: {=INDEX('2026 KPI TRACKER'!$E$50:$P$50,MATCH('SCM KPI FY26 DASHBOARD'!F2,'2026 KPI TRACKER'!E4:P4,0))} -> 1.2688208 | U10: {=INDEX('2026 KPI TRACKER'!$E$170:$P$170,MATCH('SCM KPI FY26 DASHBOARD'!F2,'2026 KPI TRACKER'!E4:P4,0))} -> 0.72854224 | Z10: {=INDEX('2026 KPI TRACKER'!$E$122:$P$122,MATCH('SCM KPI FY26 DASHBOARD'!F2,'2026 KPI TRACKER'!E4:P4,0))} -> 0.37709718
B11: Operational Cost | C11: {=INDEX('2026 KPI TRACKER'!$E$21:$P$21,MATCH('SCM KPI FY26 DASHBOARD'!F2,'2026 KPI TRACKER'!E4:P4,0))} -> 16210988 | D11: {=INDEX('2026 KPI TRACKER'!$E$20:$P$20,MATCH('SCM KPI FY26 DASHBOARD'!F2,'2026 KPI TRACKER'!E4:P4,0))} -> 15879974 | E11: ● | P11: {=INDEX('2026 KPI TRACKER'!$E$54:$P$54,MATCH('SCM KPI FY26 DASHBOARD'!F2,'2026 KPI TRACKER'!E4:P4,0))} -> 23.65 | Z11: EXPORT
B12: Capital Expenditures | C12: {=INDEX('2026 KPI TRACKER'!$E$25:$P$25,MATCH('SCM KPI FY26 DASHBOARD'!F2,'2026 KPI TRACKER'!E4:P4,0))} -> 1966800 | D12: {=INDEX('2026 KPI TRACKER'!$E$24:$P$24,MATCH('SCM KPI FY26 DASHBOARD'!F2,'2026 KPI TRACKER'!E4:P4,0))} -> 2033330 | E12: ● | H12: {=INDEX('2026 KPI TRACKER'!$E$38:$P$38,MATCH('SCM KPI FY26 DASHBOARD'!F2,'2026 KPI TRACKER'!E4:P4,0))} -> 1578.6036 | J12: MT | P12: days | R12: {=INDEX('2026 KPI TRACKER'!$E$169:$P$169,MATCH('SCM KPI FY26 DASHBOARD'!F2,'2026 KPI TRACKER'!E4:P4,0))/1000} -> 3333.3333 | T12: Php | Z12: {=INDEX('2026 KPI TRACKER'!$E$130:$P$130,MATCH('SCM KPI FY26 DASHBOARD'!F2,'2026 KPI TRACKER'!E4:P4,0))} -> 0.12195203
B13: Variance Analysis
B14: Efficiency Ratio
B15: Progress on Strategic Initiatives | H15: PRODUCTIVE TIME | M15: DOWNTIME | R15: Inventory Accuracy | W15: FORECAST ACCURACY
B16: Risk Assessment | R16: {=INDEX('2026 KPI TRACKER'!$E$90:$P$90,MATCH('SCM KPI FY26 DASHBOARD'!F2,'2026 KPI TRACKER'!E4:P4,0))} -> 0.98675497 | U16: FG | W16: ='2026 KPI TRACKER'!B106 -> EPOXY (MARINE + CONSTRUCTION) | Y16: {=INDEX('2026 KPI TRACKER'!$E106:$P106,MATCH('SCM KPI FY26 DASHBOARD'!$F$2,'2026 KPI TRACKER'!$E$4:$P$4,0))} -> 0.45772562
B17: Resource Allocation | H17: {=INDEX('2026 KPI TRACKER'!$E$49:$P$49,MATCH('SCM KPI FY26 DASHBOARD'!F2,'2026 KPI TRACKER'!E4:P4,0))} -> 0.21150467 | M17: {=INDEX('2026 KPI TRACKER'!$E$39:$P$39,MATCH('SCM KPI FY26 DASHBOARD'!F2,'2026 KPI TRACKER'!E4:P4,0))} -> #ERROR! | W17: ='2026 KPI TRACKER'!B107 -> ELASTOSEAL | Y17: {=INDEX('2026 KPI TRACKER'!$E107:$P107,MATCH('SCM KPI FY26 DASHBOARD'!$F$2,'2026 KPI TRACKER'!$E$4:$P$4,0))} -> 0.76971992
K18: {=INDEX('2026 KPI TRACKER'!$E$54:$P$54,MATCH('SCM KPI FY26 DASHBOARD'!F2,'2026 KPI TRACKER'!E4:P4,0))} -> 23.65 | P18: {=INDEX('2026 KPI TRACKER'!$E$54:$P$54,MATCH('SCM KPI FY26 DASHBOARD'!F2,'2026 KPI TRACKER'!E4:P4,0))} -> 23.65 | R18: {=INDEX('2026 KPI TRACKER'!$E$91:$P$91,MATCH('SCM KPI FY26 DASHBOARD'!F2,'2026 KPI TRACKER'!E4:P4,0))} -> 0.98717949 | U18: RMPM | W18: ='2026 KPI TRACKER'!B108 -> MIGHTY BOND | Y18: {=INDEX('2026 KPI TRACKER'!$E108:$P108,MATCH('SCM KPI FY26 DASHBOARD'!$F$2,'2026 KPI TRACKER'!$E$4:$P$4,0))} -> 0.66919905
B19: Financial Trend FY26 | K19: days | P19: days | W19: ='2026 KPI TRACKER'!B109 -> PRO-EPOXY | Y19: {=INDEX('2026 KPI TRACKER'!$E109:$P109,MATCH('SCM KPI FY26 DASHBOARD'!$F$2,'2026 KPI TRACKER'!$E$4:$P$4,0))} -> 0.64811092
R20: {=INDEX('2026 KPI TRACKER'!$E$92:$P$92,MATCH('SCM KPI FY26 DASHBOARD'!F2,'2026 KPI TRACKER'!E4:P4,0))} -> NO DATA | U20: PROD | W20: ='2026 KPI TRACKER'!B110 -> BUILDERS BOND | Y20: {=INDEX('2026 KPI TRACKER'!$E110:$P110,MATCH('SCM KPI FY26 DASHBOARD'!$F$2,'2026 KPI TRACKER'!$E$4:$P$4,0))} -> 0.48097973
W21: ='2026 KPI TRACKER'!B111 -> COATING MARINE | Y21: {=INDEX('2026 KPI TRACKER'!$E111:$P111,MATCH('SCM KPI FY26 DASHBOARD'!$F$2,'2026 KPI TRACKER'!$E$4:$P$4,0))} -> 0.41566339
H22: DOWNTIME BREAKDOWN | M22: LABOR REPORTS | W22: ='2026 KPI TRACKER'!B112 -> TRASPORTATION | Y22: {=INDEX('2026 KPI TRACKER'!$E112:$P112,MATCH('SCM KPI FY26 DASHBOARD'!$F$2,'2026 KPI TRACKER'!$E$4:$P$4,0))} -> 0.27658279
H23: =Sheet1!G10 -> Idle time | K23: {=INDEX('2026 KPI TRACKER'!$E47:$P47,MATCH('SCM KPI FY26 DASHBOARD'!$F$2,'2026 KPI TRACKER'!$E$4:$P$4,0))} -> 0.0060530939 | M23: {=INDEX('2026 KPI TRACKER'!$E$137:$P$137,MATCH('SCM KPI FY26 DASHBOARD'!F2,'2026 KPI TRACKER'!E4:P4,0))} -> 36117.1 | O23: Reg hrs | R23: Warehouse Utlization | W23: ='2026 KPI TRACKER'!B113 -> OTHER CONSUMER | Y23: {=INDEX('2026 KPI TRACKER'!$E113:$P113,MATCH('SCM KPI FY26 DASHBOARD'!$F$2,'2026 KPI TRACKER'!$E$4:$P$4,0))} -> 0.0065382981
H24: =Sheet1!G3 -> Change Over Time | K24: {=INDEX('2026 KPI TRACKER'!$E40:$P40,MATCH('SCM KPI FY26 DASHBOARD'!$F$2,'2026 KPI TRACKER'!$E$4:$P$4,0))} -> 0.021621366 | P24: {=INDEX('2026 KPI TRACKER'!$E$139:$P$139,MATCH('SCM KPI FY26 DASHBOARD'!F2,'2026 KPI TRACKER'!E4:P4,0))} -> 0.32690886 | R24: {=INDEX('2026 KPI TRACKER'!$E$95:$P$95,MATCH('SCM KPI FY26 DASHBOARD'!F2,'2026 KPI TRACKER'!E4:P4,0))} -> 0.90973202 | W24: ='2026 KPI TRACKER'!B114 -> PRO-SEALANT | Y24: {=INDEX('2026 KPI TRACKER'!$E114:$P114,MATCH('SCM KPI FY26 DASHBOARD'!$F$2,'2026 KPI TRACKER'!$E$4:$P$4,0))} -> 0.50318328
H25: =Sheet1!G6 -> Start-up Time/Setup | K25: {=INDEX('2026 KPI TRACKER'!$E43:$P43,MATCH('SCM KPI FY26 DASHBOARD'!$F$2,'2026 KPI TRACKER'!$E$4:$P$4,0))} -> 0.020867854 | U25: FG | W25: ='2026 KPI TRACKER'!B115 -> PRO-WATERPROOFING | Y25: {=INDEX('2026 KPI TRACKER'!$E115:$P115,MATCH('SCM KPI FY26 DASHBOARD'!$F$2,'2026 KPI TRACKER'!$E$4:$P$4,0))} -> 0.535723
H26: =Sheet1!G8 -> Breaktime | K26: {=INDEX('2026 KPI TRACKER'!$E45:$P45,MATCH('SCM KPI FY26 DASHBOARD'!$F$2,'2026 KPI TRACKER'!$E$4:$P$4,0))} -> 0.019459878 | M26: {=INDEX('2026 KPI TRACKER'!$E$138:$P$138,MATCH('SCM KPI FY26 DASHBOARD'!F2,'2026 KPI TRACKER'!E4:P4,0))} -> 11807 | O26: OT hrs | W26: ='2026 KPI TRACKER'!B116 -> PRO-PAINTING | Y26: {=INDEX('2026 KPI TRACKER'!$E116:$P116,MATCH('SCM KPI FY26 DASHBOARD'!$F$2,'2026 KPI TRACKER'!$E$4:$P$4,0))} -> 0.69714382
H27: =Sheet1!G5 -> Sanitation Time | K27: {=INDEX('2026 KPI TRACKER'!$E42:$P42,MATCH('SCM KPI FY26 DASHBOARD'!$F$2,'2026 KPI TRACKER'!$E$4:$P$4,0))} -> 0.010041897 | R27: {=INDEX('2026 KPI TRACKER'!$E$96:$P$96,MATCH('SCM KPI FY26 DASHBOARD'!F2,'2026 KPI TRACKER'!E4:P4,0))} -> 1.2604273 | W27: ='2026 KPI TRACKER'!B117 -> PRO-ADHESIVES | Y27: {=INDEX('2026 KPI TRACKER'!$E117:$P117,MATCH('SCM KPI FY26 DASHBOARD'!$F$2,'2026 KPI TRACKER'!$E$4:$P$4,0))} -> 0.20556193
H28: =Sheet1!G4 -> Meeting | K28: {=INDEX('2026 KPI TRACKER'!$E41:$P41,MATCH('SCM KPI FY26 DASHBOARD'!$F$2,'2026 KPI TRACKER'!$E$4:$P$4,0))} -> 0.0015625665 | M28: LABOR REPORTS (Direct Labor) | U28: RMPM | W28: ='2026 KPI TRACKER'!B118 -> MINING | Y28: {=INDEX('2026 KPI TRACKER'!$E118:$P118,MATCH('SCM KPI FY26 DASHBOARD'!$F$2,'2026 KPI TRACKER'!$E$4:$P$4,0))} -> 0.15822785
H29: =Sheet1!G9 -> Breakdown | K29: {=INDEX('2026 KPI TRACKER'!$E46:$P46,MATCH('SCM KPI FY26 DASHBOARD'!$F$2,'2026 KPI TRACKER'!$E$4:$P$4,0))} -> 3.1473497e-05 | M29: {=INDEX('2026 KPI TRACKER'!$E$140:$P$140,MATCH('SCM KPI FY26 DASHBOARD'!F2,'2026 KPI TRACKER'!E4:P4,0))} -> 29807.03 | O29: OT hrs | W29: ='2026 KPI TRACKER'!B119 -> OTHERS | Y29: {=INDEX('2026 KPI TRACKER'!$E119:$P119,MATCH('SCM KPI FY26 DASHBOARD'!$F$2,'2026 KPI TRACKER'!$E$4:$P$4,0))} -> 0
H30: =Sheet1!G7 -> Testing Time | K30: {=INDEX('2026 KPI TRACKER'!$E44:$P44,MATCH('SCM KPI FY26 DASHBOARD'!$F$2,'2026 KPI TRACKER'!$E$4:$P$4,0))} -> 0.009783629 | P30: {=INDEX('2026 KPI TRACKER'!$E$142:$P$142,MATCH('SCM KPI FY26 DASHBOARD'!F2,'2026 KPI TRACKER'!E4:P4,0))} -> 0.33782299
H31: =Sheet1!G11 -> Preventive Maintenance | K31: {=INDEX('2026 KPI TRACKER'!$E48:$P48,MATCH('SCM KPI FY26 DASHBOARD'!$F$2,'2026 KPI TRACKER'!$E$4:$P$4,0))} -> #ERROR! | W31: FORECAST ACCURACY
M32: {=INDEX('2026 KPI TRACKER'!$E$141:$P$141,MATCH('SCM KPI FY26 DASHBOARD'!F2,'2026 KPI TRACKER'!E4:P4,0))} -> 10069.5 | O32: Reg hrs | W32: ='2026 KPI TRACKER'!B122 -> LOCAL PHILIPPINES | Y32: {=INDEX('2026 KPI TRACKER'!$E122:$P122,MATCH('SCM KPI FY26 DASHBOARD'!$F$2,'2026 KPI TRACKER'!$E$4:$P$4,0))} -> 0.37709718
H33: ABSENTEEISM | W33: ='2026 KPI TRACKER'!B123 -> GMA | Y33: {=INDEX('2026 KPI TRACKER'!$E123:$P123,MATCH('SCM KPI FY26 DASHBOARD'!$F$2,'2026 KPI TRACKER'!$E$4:$P$4,0))} -> 0.37469668
H34: {=INDEX('2026 KPI TRACKER'!$E$147:$P$147,MATCH('SCM KPI FY26 DASHBOARD'!F2,'2026 KPI TRACKER'!E4:P4,0))} -> 0.12107349 | K34: {=INDEX('2026 KPI TRACKER'!$E$150:$P$150,MATCH('SCM KPI FY26 DASHBOARD'!F2,'2026 KPI TRACKER'!E4:P4,0))} -> 23.65 | M34: LABOR REPORTS (Indirect Labor) | W34: ='2026 KPI TRACKER'!B124 -> NORTH LUZON | Y34: {=INDEX('2026 KPI TRACKER'!$E124:$P124,MATCH('SCM KPI FY26 DASHBOARD'!$F$2,'2026 KPI TRACKER'!$E$4:$P$4,0))} -> 0.49527923
K35: days | M35: {=INDEX('2026 KPI TRACKER'!$E$143:$P$143,MATCH('SCM KPI FY26 DASHBOARD'!F2,'2026 KPI TRACKER'!E4:P4,0))} -> 6310.07 | O35: OT hrs | W35: ='2026 KPI TRACKER'!B125 -> SOUTH LUZON | Y35: {=INDEX('2026 KPI TRACKER'!$E125:$P125,MATCH('SCM KPI FY26 DASHBOARD'!$F$2,'2026 KPI TRACKER'!$E$4:$P$4,0))} -> 0.39307041
J36: {=INDEX('2026 KPI TRACKER'!$E$148:$P$148,MATCH('SCM KPI FY26 DASHBOARD'!F2,'2026 KPI TRACKER'!E4:P4,0))} -> 183 | P36: {=INDEX('2026 KPI TRACKER'!$E$145:$P$145,MATCH('SCM KPI FY26 DASHBOARD'!F2,'2026 KPI TRACKER'!E4:P4,0))} -> 0.27535352 | W36: ='2026 KPI TRACKER'!B126 -> VISAYAS | Y36: {=INDEX('2026 KPI TRACKER'!$E126:$P126,MATCH('SCM KPI FY26 DASHBOARD'!$F$2,'2026 KPI TRACKER'!$E$4:$P$4,0))} -> 0.38475153
H37: {=INDEX('2026 KPI TRACKER'!$E$149:$P$149,MATCH('SCM KPI FY26 DASHBOARD'!F2,'2026 KPI TRACKER'!E4:P4,0))} -> 524 | I37: Absences | W37: ='2026 KPI TRACKER'!B127 -> MINDANAO | Y37: {=INDEX('2026 KPI TRACKER'!$E127:$P127,MATCH('SCM KPI FY26 DASHBOARD'!$F$2,'2026 KPI TRACKER'!$E$4:$P$4,0))} -> 0.29967189
J38: Manpower | M38: {=INDEX('2026 KPI TRACKER'!$E$144:$P$144,MATCH('SCM KPI FY26 DASHBOARD'!F2,'2026 KPI TRACKER'!E4:P4,0))} -> 1737.5 | O38: Reg hrs | W38: ='2026 KPI TRACKER'!B128 -> MODERN TRADE | Y38: {=INDEX('2026 KPI TRACKER'!$E128:$P128,MATCH('SCM KPI FY26 DASHBOARD'!$F$2,'2026 KPI TRACKER'!$E$4:$P$4,0))} -> 0.69221053
W39: ='2026 KPI TRACKER'!B129 -> PSBSI | Y39: {=INDEX('2026 KPI TRACKER'!$E129:$P129,MATCH('SCM KPI FY26 DASHBOARD'!$F$2,'2026 KPI TRACKER'!$E$4:$P$4,0))} -> 0
H40: ABSENTEEISM | W40: ='2026 KPI TRACKER'!B130 -> EXPORT | Y40: {=INDEX('2026 KPI TRACKER'!$E130:$P130,MATCH('SCM KPI FY26 DASHBOARD'!$F$2,'2026 KPI TRACKER'!$E$4:$P$4,0))} -> 0.12195203
H41: ='2026 KPI TRACKER'!B151 -> L06 - EPOXY | J41: {=INDEX('2026 KPI TRACKER'!$E151:$P151,MATCH('SCM KPI FY26 DASHBOARD'!$F$2,'2026 KPI TRACKER'!$E$4:$P$4,0))} -> 0.11250378 | W41: ='2026 KPI TRACKER'!B131 -> INDONESIA | Y41: {=INDEX('2026 KPI TRACKER'!$E131:$P131,MATCH('SCM KPI FY26 DASHBOARD'!$F$2,'2026 KPI TRACKER'!$E$4:$P$4,0))} -> 0.31872979
H42: ='2026 KPI TRACKER'!B152 -> L04B - ELASTO | J42: {=INDEX('2026 KPI TRACKER'!$E152:$P152,MATCH('SCM KPI FY26 DASHBOARD'!$F$2,'2026 KPI TRACKER'!$E$4:$P$4,0))} -> 0.15070201 | W42: ='2026 KPI TRACKER'!B132 -> INDIA | Y42: {=INDEX('2026 KPI TRACKER'!$E132:$P132,MATCH('SCM KPI FY26 DASHBOARD'!$F$2,'2026 KPI TRACKER'!$E$4:$P$4,0))} -> 0
...

Sheet 2026 KPI TRACKER
A1: PIONEER
A2: 2026 KPI TRACKER
B4: KPI | C4: UoM | D4: 2026 TARGET | E4: OCT | F4: NOV | G4: DEC | H4: JAN | I4: FEB | J4: MAR | K4: APR | L4: MAY | M4: JUN | N4: JUL | O4: AUG | P4: SEP | Q4: 2026 ACTUAL
A5: BUSINESS GOALS:
A6: =MAX($A$5:A5)+1 -> 1 | B6: FINANCIALS
B7: Conversion Cost
B8: Conversion Cost (SC only) | C8: PHP/KG | D8: ='FINANCE DEPT'!G6 -> 11 | E8: ='FINANCE DEPT'!I6 -> 10.929592 | F8: ='FINANCE DEPT'!J6 -> 9.9039022 | G8: ='FINANCE DEPT'!K6 -> 14.391261 | H8: ='FINANCE DEPT'!L6 -> 9.9342105 | I8: ='FINANCE DEPT'!M6 | J8: ='FINANCE DEPT'!N6 | K8: ='FINANCE DEPT'!O6 | L8: ='FINANCE DEPT'!P6 | ... P8: ='FINANCE DEPT'!T6
B9: ='FINANCE DEPT'!B7 -> Conversion Cost (Overall) | C9: PHP/KG | D9: ='FINANCE DEPT'!G7 -> 15 | E9: ='FINANCE DEPT'!I7 -> 18.577245 | F9: ='FINANCE DEPT'!J7 -> 15.555569 | G9: ='FINANCE DEPT'!K7 -> 23.639818 | H9: ='FINANCE DEPT'!L7 -> 15.056688 | I9: ='FINANCE DEPT'!M7 | J9: ='FINANCE DEPT'!N7 | K9: ='FINANCE DEPT'!O7 | L9: ='FINANCE DEPT'!P7 | ... P9: ='FINANCE DEPT'!T7
B10: Conversion Cost (SC only) vs Target | C10: % | E10: =IFERROR(E8/D8,0) -> 0.99359929 | F10: =IFERROR(F8/#REF!,0) -> 0 | G10: =IFERROR(G8/E8,0) -> 1.3167244 | H10: =IFERROR(H8/F8,0) -> 1.0030602 | I10: =IFERROR(I8/G8,0) -> 0 | J10: =IFERROR(J8/H8,0) -> 0 | K10: =IFERROR(K8/I8,0) -> 0 | L10: =IFERROR(L8/J8,0) -> 0 | M10: =IFERROR(M8/K8,0) -> 0 | N10: =IFERROR(N8/L8,0) -> 0 | ... P10: =IFERROR(P8/N8,0) -> 0
B11: Volume produced (MT) Actual | C11: MT | D11: ='FINANCE DEPT'!G8 -> 5574.716 | E11: ='FINANCE DEPT'!I8 -> 1235.0772 | F11: ='FINANCE DEPT'!J8 -> 1603.4058 | G11: ='FINANCE DEPT'!K8 -> 1115.1986 | H11: ='FINANCE DEPT'!L8 -> 1621.0345 | I11: ='FINANCE DEPT'!M8 | J11: ='FINANCE DEPT'!N8 | K11: ='FINANCE DEPT'!O8 | L11: ='FINANCE DEPT'!P8 | ... Q11: ='FINANCE DEPT'!U8 -> 5574.716
B12: Volume produced (MT) Target | C12: MT | D12: ='FINANCE DEPT'!G9 -> 18814 | E12: ='FINANCE DEPT'!I9 -> 1221.8656 | F12: ='FINANCE DEPT'!J9 -> 1414.9244 | G12: ='FINANCE DEPT'!K9 -> 1090.6968 | H12: ='FINANCE DEPT'!L9 -> 1561.4227 | I12: ='FINANCE DEPT'!M9 | J12: ='FINANCE DEPT'!N9 | K12: ='FINANCE DEPT'!O9 | L12: ='FINANCE DEPT'!P9 | ... Q12: ='FINANCE DEPT'!U9 -> 5288.9096
B13: Volume produced % | C13: % | D13: ='FINANCE DEPT'!G10 -> 0.29630679 | E13: ='FINANCE DEPT'!I10 -> 1.0108127 | F13: ='FINANCE DEPT'!J10 -> 1.1332095 | G13: ='FINANCE DEPT'!K10 -> 1.0224643 | H13: ='FINANCE DEPT'!L10 -> 1.0381779 | I13: ='FINANCE DEPT'!M10 | J13: ='FINANCE DEPT'!N10 | K13: ='FINANCE DEPT'!O10 | L13: ='FINANCE DEPT'!P10 | ... Q13: ='FINANCE DEPT'!U10 -> 1.0540388
A14: =MAX($A$5:A6)+1 -> 2 | B14: FILL RATE
B15: Achievement (Value) | C15: % | D15: 0.99 | E15: ='WHSE & LOGS'!G22 -> 0.59877975 | F15: ='WHSE & LOGS'!H22 -> 0.8076873 | G15: ='WHSE & LOGS'!I22 -> 0.87977398 | H15: ='WHSE & LOGS'!J22 -> 0.98941 | I15: ='WHSE & LOGS'!K22 -> 0 | J15: ='WHSE & LOGS'!L22 -> 0 | K15: ='WHSE & LOGS'!M22 -> 0 | L15: ='WHSE & LOGS'!N22 -> 0 | ... Q15: ='WHSE & LOGS'!S22 -> 0.83972508
A16: =MAX($A$5:A15)+1 -> 3 | B16: OTIF | E16: NO VALUE | F16: NO VALUE
B17: OTIF Rate | C17: % | D17: 0.7 | E17: ='WHSE & LOGS'!G11 -> 0 | F17: ='WHSE & LOGS'!H11 -> 0 | G17: ='WHSE & LOGS'!I11 -> 0 | H17: ='WHSE & LOGS'!J11 -> 0 | I17: ='WHSE & LOGS'!K11 -> 0 | J17: ='WHSE & LOGS'!L11 -> 0 | K17: ='WHSE & LOGS'!M11 -> 0 | L17: ='WHSE & LOGS'!N11 -> 0 | ... Q17: ='WHSE & LOGS'!S11 -> 0
A18: =MAX($A$5:A17)+1 -> 4 | B18: FINANCIALS
B19: Operational Cost
B20: Actual | E20: ='FINANCE DEPT'!I14 -> 13498890 | F20: ='FINANCE DEPT'!J14 -> 15879974
B21: Budget | E21: ='FINANCE DEPT'!I15 -> 16189431 | F21: ='FINANCE DEPT'!J15 -> 16210988
B22: Operational Cost % | E22: ='FINANCE DEPT'!I16 -> 0.8338088 | F22: ='FINANCE DEPT'!J16 -> 0.97958091
B23: Capital Expenditures
B24: Actual | E24: ='FINANCE DEPT'!I19 -> 2042360 | F24: ='FINANCE DEPT'!J19 -> 2033330
B25: Budget | E25: ='FINANCE DEPT'!I20 -> 1946800 | F25: ='FINANCE DEPT'!J20 -> 1966800
B26: Capital Expenditure % | E26: ='FINANCE DEPT'!I21 -> 1.0490857 | F26: ='FINANCE DEPT'!J21 -> 1.0338265
B27: Variance Analysis
B28: Efficiency Ratio
A29: 5 | B29: Project Status
B30: Progress on Strategic Initiatives
B31: Risk Assessment
B32: Resource Allocation
A34: OPERATIONAL OBJECTIVES
A35: =MAX($A$34:A34)+1 -> 1 | B35: Production Reports
B36: Output vs Target (planned) | C36: % | D36: 0.9 | E36: =PRODUCTION!G1255 -> 0.73483834 | F36: =PRODUCTION!H1255 -> 0.99412883 | G36: =PRODUCTION!I1255 -> 0.88294392 | H36: =PRODUCTION!J1255 -> 0.86916136 | I36: =PRODUCTION!K1255 -> 0 | J36: =PRODUCTION!L1255 -> 0 | K36: =PRODUCTION!M1255 -> 0 | L36: =PRODUCTION!N1255 -> 0 | ... Q36: =PRODUCTION!S1255 -> 0.86881847
B37: Output Actual | C37: MT | E37: =PRODUCTION!G1253/1000 -> 1185.1593 | F37: =PRODUCTION!H1253/1000 -> 1569.3354 | G37: =PRODUCTION!I1253/1000 -> 1103.3091 | H37: =PRODUCTION!J1253/1000 -> 1569.1495 | I37: =PRODUCTION!K1253/1000 -> 0 | J37: =PRODUCTION!L1253/1000 -> 0 | K37: =PRODUCTION!M1253/1000 -> 0 | L37: =PRODUCTION!N1253/1000 -> 0 | ... Q37: =PRODUCTION!S1253/1000 -> 5426.9533
B38: Output Target | C38: MT | E38: =PRODUCTION!G1254/1000 -> 1612.8164 | F38: =PRODUCTION!H1254/1000 -> 1578.6036 | G38: =PRODUCTION!I1254/1000 -> 1249.58 | H38: =PRODUCTION!J1254/1000 -> 1805.3604 | I38: =PRODUCTION!K1254/1000 -> 0 | J38: =PRODUCTION!L1254/1000 -> 0 | K38: =PRODUCTION!M1254/1000 -> 0 | L38: =PRODUCTION!N1254/1000 -> 0 | ... Q38: =PRODUCTION!S1254/1000 -> 6246.3604
B39: Downtime Analysis | C39: % | E39: =SUM(E40:E48) -> #ERROR! | F39: =SUM(F40:F48) -> #ERROR! | G39: =SUM(G40:G48) -> #ERROR! | H39: =SUM(H40:H48) -> #ERROR! | I39: =SUM(I40:I48) -> #ERROR! | J39: =SUM(J40:J48) -> #ERROR! | K39: =SUM(K40:K48) -> #ERROR! | L39: =SUM(L40:L48) -> #ERROR! | ... Q39: =SUM(Q40:Q48) -> #ERROR!
B40: Change Over Time | C40: % | E40: =PRODUCTION!G37 -> 0.016065308 | F40: =PRODUCTION!H37 -> 0.021621366 | G40: =PRODUCTION!I37 -> 0.018904734 | H40: =PRODUCTION!J37 -> 0 | I40: =PRODUCTION!K37 -> 0 | J40: =PRODUCTION!L37 -> 0 | K40: =PRODUCTION!M37 -> 0 | L40: =PRODUCTION!N37 -> 0 | ... Q40: =PRODUCTION!S37 -> 0.018838528
B41: Meeting | C41: % | E41: =PRODUCTION!G38 -> 0.0015941701 | F41: =PRODUCTION!H38 -> 0.0015625665 | G41: =PRODUCTION!I38 -> 0.00064686857 | H41: =PRODUCTION!J38 -> 0 | I41: =PRODUCTION!K38 -> 0 | J41: =PRODUCTION!L38 -> 0 | K41: =PRODUCTION!M38 -> 0 | L41: =PRODUCTION!N38 -> 0 | ... Q41: =PRODUCTION!S38 -> 0.0013569949
B42: Sanitation Time | C42: % | E42: =PRODUCTION!G39 -> 0.0086488727 | F42: =PRODUCTION!H39 -> 0.010041897 | G42: =PRODUCTION!I39 -> 0.0063745957 | H42: =PRODUCTION!J39 -> 0 | I42: =PRODUCTION!K39 -> 0 | J42: =PRODUCTION!L39 -> 0 | K42: =PRODUCTION!M39 -> 0 | L42: =PRODUCTION!N39 -> 0 | ... Q42: =PRODUCTION!S39 -> 0.0086341508
...

Sheet SCM - PLANNING
A1: PIONEER
A2: 2026 KPI TRACKER
A3: SC - PLANNING
G5: Q1 | H5: Q1 | I5: Q1 | J5: Q2 | K5: Q2 | L5: Q2 | M5: Q3 | N5: Q3 | O5: Q3 | P5: Q4 | Q5: Q4 | R5: Q4
C6: UoM | E6: 2026 ABP | G6: OCT | H6: NOV | I6: DEC | J6: JAN | K6: FEB | L6: MAR | M6: APR | N6: MAY | O6: JUN | P6: JUL | Q6: AUG | R6: SEP | S6: 2026 YTD | U6: Q1 | V6: Q2 | W6: Q3 | X6: Q4
A7: A. | B7: COMPLIANCE TO SCHEDULE
B8: COMPLIANCE
B9: L06 - EPOXY | C9: % | D9: L06 | S9: =IFERROR(AVERAGE(G9:R9),0) -> 0 | U9: =IFERROR(AVERAGEIF($G$5:$R$5,U$6,$G9:$R9),0) -> 0 | V9: =IFERROR(AVERAGEIF($G$5:$R$5,V$6,$G9:$R9),0) -> 0 | W9: =IFERROR(AVERAGEIF($G$5:$R$5,W$6,$G9:$R9),0) -> 0 | X9: =IFERROR(AVERAGEIF($G$5:$R$5,X$6,$G9:$R9),0) -> 0
B10: L04B - ELASTO | C10: % | D10: L04B | S10: =IFERROR(AVERAGE(G10:R10),0) -> 0 | U10: =IFERROR(AVERAGEIF($G$5:$R$5,U$6,$G10:$R10),0) -> 0 | V10: =IFERROR(AVERAGEIF($G$5:$R$5,V$6,$G10:$R10),0) -> 0 | W10: =IFERROR(AVERAGEIF($G$5:$R$5,W$6,$G10:$R10),0) -> 0 | X10: =IFERROR(AVERAGEIF($G$5:$R$5,X$6,$G10:$R10),0) -> 0
B11: L03 - CYANO TUBE | C11: % | D11: GIP L03 | S11: =IFERROR(AVERAGE(G11:R11),0) -> 0 | U11: =IFERROR(AVERAGEIF($G$5:$R$5,U$6,$G11:$R11),0) -> 0 | V11: =IFERROR(AVERAGEIF($G$5:$R$5,V$6,$G11:$R11),0) -> 0 | W11: =IFERROR(AVERAGEIF($G$5:$R$5,W$6,$G11:$R11),0) -> 0 | X11: =IFERROR(AVERAGEIF($G$5:$R$5,X$6,$G11:$R11),0) -> 0
B12: L01 - COATINGS | C12: % | D12: L01 | S12: =IFERROR(AVERAGE(G12:R12),0) -> 0 | U12: =IFERROR(AVERAGEIF($G$5:$R$5,U$6,$G12:$R12),0) -> 0 | V12: =IFERROR(AVERAGEIF($G$5:$R$5,V$6,$G12:$R12),0) -> 0 | W12: =IFERROR(AVERAGEIF($G$5:$R$5,W$6,$G12:$R12),0) -> 0 | X12: =IFERROR(AVERAGEIF($G$5:$R$5,X$6,$G12:$R12),0) -> 0
B13: L07 - EPOXY TUBE | C13: % | D13: GIP L07 | S13: =IFERROR(AVERAGE(G13:R13),0) -> 0 | U13: =IFERROR(AVERAGEIF($G$5:$R$5,U$6,$G13:$R13),0) -> 0 | V13: =IFERROR(AVERAGEIF($G$5:$R$5,V$6,$G13:$R13),0) -> 0 | W13: =IFERROR(AVERAGEIF($G$5:$R$5,W$6,$G13:$R13),0) -> 0 | X13: =IFERROR(AVERAGEIF($G$5:$R$5,X$6,$G13:$R13),0) -> 0
B14: LINE 9 - EPS | C14: % | D14: EPS | S14: =IFERROR(AVERAGE(G14:R14),0) -> 0 | U14: =IFERROR(AVERAGEIF($G$5:$R$5,U$6,$G14:$R14),0) -> 0 | V14: =IFERROR(AVERAGEIF($G$5:$R$5,V$6,$G14:$R14),0) -> 0 | W14: =IFERROR(AVERAGEIF($G$5:$R$5,W$6,$G14:$R14),0) -> 0 | X14: =IFERROR(AVERAGEIF($G$5:$R$5,X$6,$G14:$R14),0) -> 0
B15: L10 - CONTACT BOND | C15: % | D15: L10 | S15: =IFERROR(AVERAGE(G15:R15),0) -> 0 | U15: =IFERROR(AVERAGEIF($G$5:$R$5,U$6,$G15:$R15),0) -> 0 | V15: =IFERROR(AVERAGEIF($G$5:$R$5,V$6,$G15:$R15),0) -> 0 | W15: =IFERROR(AVERAGEIF($G$5:$R$5,W$6,$G15:$R15),0) -> 0 | X15: =IFERROR(AVERAGEIF($G$5:$R$5,X$6,$G15:$R15),0) -> 0
B16: L11 - SILICONE | C16: % | D16: GIP L11 | S16: =IFERROR(AVERAGE(G16:R16),0) -> 0 | U16: =IFERROR(AVERAGEIF($G$5:$R$5,U$6,$G16:$R16),0) -> 0 | V16: =IFERROR(AVERAGEIF($G$5:$R$5,V$6,$G16:$R16),0) -> 0 | W16: =IFERROR(AVERAGEIF($G$5:$R$5,W$6,$G16:$R16),0) -> 0 | X16: =IFERROR(AVERAGEIF($G$5:$R$5,X$6,$G16:$R16),0) -> 0
B17: L12 - SPECIAL - EPOXY BASED | C17: % | D17: L12 | S17: =IFERROR(AVERAGE(G17:R17),0) -> 0 | U17: =IFERROR(AVERAGEIF($G$5:$R$5,U$6,$G17:$R17),0) -> 0 | V17: =IFERROR(AVERAGEIF($G$5:$R$5,V$6,$G17:$R17),0) -> 0 | W17: =IFERROR(AVERAGEIF($G$5:$R$5,W$6,$G17:$R17),0) -> 0 | X17: =IFERROR(AVERAGEIF($G$5:$R$5,X$6,$G17:$R17),0) -> 0
B18: L13 - SPECIAL | C18: % | D18: L13 | S18: =IFERROR(AVERAGE(G18:R18),0) -> 0 | U18: =IFERROR(AVERAGEIF($G$5:$R$5,U$6,$G18:$R18),0) -> 0 | V18: =IFERROR(AVERAGEIF($G$5:$R$5,V$6,$G18:$R18),0) -> 0 | W18: =IFERROR(AVERAGEIF($G$5:$R$5,W$6,$G18:$R18),0) -> 0 | X18: =IFERROR(AVERAGEIF($G$5:$R$5,X$6,$G18:$R18),0) -> 0
B19: LINE 14 | C19: % | D19: L14 | S19: =IFERROR(AVERAGE(G19:R19),0) -> 0 | U19: =IFERROR(AVERAGEIF($G$5:$R$5,U$6,$G19:$R19),0) -> 0 | V19: =IFERROR(AVERAGEIF($G$5:$R$5,V$6,$G19:$R19),0) -> 0 | W19: =IFERROR(AVERAGEIF($G$5:$R$5,W$6,$G19:$R19),0) -> 0 | X19: =IFERROR(AVERAGEIF($G$5:$R$5,X$6,$G19:$R19),0) -> 0
B20: L05 - EPOXY CLAY | C20: % | D20: GIP L05 | S20: =IFERROR(AVERAGE(G20:R20),0) -> 0 | U20: =IFERROR(AVERAGEIF($G$5:$R$5,U$6,$G20:$R20),0) -> 0 | V20: =IFERROR(AVERAGEIF($G$5:$R$5,V$6,$G20:$R20),0) -> 0 | W20: =IFERROR(AVERAGEIF($G$5:$R$5,W$6,$G20:$R20),0) -> 0 | X20: =IFERROR(AVERAGEIF($G$5:$R$5,X$6,$G20:$R20),0) -> 0
B21: L02 - CYNO BOTTLE | C21: % | D21: L02 | S21: =IFERROR(AVERAGE(G21:R21),0) -> 0 | U21: =IFERROR(AVERAGEIF($G$5:$R$5,U$6,$G21:$R21),0) -> 0 | V21: =IFERROR(AVERAGEIF($G$5:$R$5,V$6,$G21:$R21),0) -> 0 | W21: =IFERROR(AVERAGEIF($G$5:$R$5,W$6,$G21:$R21),0) -> 0 | X21: =IFERROR(AVERAGEIF($G$5:$R$5,X$6,$G21:$R21),0) -> 0
B22: COMPLIANCE TO SCHEDULE | C22: % | S22: =IFERROR(AVERAGE(G22:R22),0) -> 0 | U22: =IFERROR(AVERAGEIF($G$5:$R$5,U$6,$G22:$R22),0) -> 0 | V22: =IFERROR(AVERAGEIF($G$5:$R$5,V$6,$G22:$R22),0) -> 0 | W22: =IFERROR(AVERAGEIF($G$5:$R$5,W$6,$G22:$R22),0) -> 0 | X22: =IFERROR(AVERAGEIF($G$5:$R$5,X$6,$G22:$R22),0) -> 0
A24: B. | B24: DIO (based on P&L COGS)
B25: DIO
B26: FG - Consignment | C26: DAYS | E26: 1 | S26: =R26 | U26: =IFERROR(AVERAGE(G26,H26,I26),0) -> 0 | V26: =IFERROR(AVERAGE(H26,I26,J26),0) -> 0 | W26: =IFERROR(AVERAGE(I26,J26,K26),0) -> 0 | X26: =IFERROR(AVERAGE(P26:R26),0) -> 0
B27: FG | C27: DAYS | E27: 25 | S27: =R27 | U27: =IFERROR(AVERAGE(G27:I27),0) -> 0 | V27: =IFERROR(AVERAGE(J27:L27),0) -> 0 | W27: =IFERROR(AVERAGE(M27:O27),0) -> 0 | X27: =IFERROR(AVERAGE(P27:R27),0) -> 0
B28: SFG | C28: DAYS | E28: 1 | S28: =R28 | U28: =IFERROR(AVERAGE(G28:I28),0) -> 0 | V28: =IFERROR(AVERAGE(J28:L28),0) -> 0 | W28: =IFERROR(AVERAGE(M28:O28),0) -> 0 | X28: =IFERROR(AVERAGE(P28:R28),0) -> 0
B29: BM | C29: DAYS | E29: 1 | S29: =R29 | U29: =IFERROR(AVERAGE(G29:I29),0) -> 0 | V29: =IFERROR(AVERAGE(J29:L29),0) -> 0 | W29: =IFERROR(AVERAGE(M29:O29),0) -> 0 | X29: =IFERROR(AVERAGE(P29:R29),0) -> 0
B30: RM | C30: DAYS | E30: 34 | S30: =R30 | U30: =IFERROR(AVERAGE(G30:I30),0) -> 0 | V30: =IFERROR(AVERAGE(J30:L30),0) -> 0 | W30: =IFERROR(AVERAGE(M30:O30),0) -> 0 | X30: =IFERROR(AVERAGE(P30:R30),0) -> 0
B31: PM | C31: DAYS | E31: 8 | S31: =R31 | U31: =IFERROR(AVERAGE(G31:I31),0) -> 0 | V31: =IFERROR(AVERAGE(J31:L31),0) -> 0 | W31: =IFERROR(AVERAGE(M31:O31),0) -> 0 | X31: =IFERROR(AVERAGE(P31:R31),0) -> 0
B33: DIO-SOH | C33: DAYS | E33: 69 | S33: =R33 | U33: =IFERROR(AVERAGE(G33:I33),0) -> 0 | V33: =IFERROR(AVERAGE(J33:L33),0) -> 0 | W33: =IFERROR(AVERAGE(M33:O33),0) -> 0 | X33: =IFERROR(AVERAGE(P33:R33),0) -> 0
B35: TOTAL-OTHERS | C35: DAYS | E35: 0 | S35: =R35 | U35: =IFERROR(AVERAGE(G35:I35),0) -> 0 | V35: =IFERROR(AVERAGE(J35:L35),0) -> 0 | W35: =IFERROR(AVERAGE(M35:O35),0) -> 0 | X35: =IFERROR(AVERAGE(P35:R35),0) -> 0
B37: FG In-transit | C37: DAYS | E37: 1 | S37: =R37 | U37: =IFERROR(AVERAGE(G37:I37),0) -> 0 | V37: =IFERROR(AVERAGE(J37:L37),0) -> 0 | W37: =IFERROR(AVERAGE(M37:O37),0) -> 0 | X37: =IFERROR(AVERAGE(P37:R37),0) -> 0
B38: RM In-transit | C38: DAYS | E38: 7 | S38: =R38 | U38: =IFERROR(AVERAGE(G38:I38),0) -> 0 | V38: =IFERROR(AVERAGE(J38:L38),0) -> 0 | W38: =IFERROR(AVERAGE(M38:O38),0) -> 0 | X38: =IFERROR(AVERAGE(P38:R38),0) -> 0
B39: TOTAL IN-TRANSIT | C39: DAYS | E39: =E37+E38 -> 8 | S39: =S37+S38 -> 0 | U39: =U37+U38 -> 0 | V39: =V37+V38 -> 0 | W39: =W37+W38 -> 0 | X39: =X37+X38 -> 0
B41: TOTAL INVENTORY | C41: DAYS | E41: 77 | G41: 107 | H41: 108 | S41: =R41 | U41: =IFERROR(AVERAGE(G41:I41),0) -> 107.5 | V41: =IFERROR(AVERAGE(J41:L41),0) -> 0 | W41: =IFERROR(AVERAGE(M41:O41),0) -> 0 | X41: =IFERROR(AVERAGE(P41:R41),0) -> 0
A43: C. | B43: DIO-SOH (net of consignment & SLOB Provisions)
B44: DIO-SOH
B45: FG | C45: DAYS | S45: =R45 | U45: =IFERROR(AVERAGE(G45:I45),0) -> 0 | V45: =IFERROR(AVERAGE(J45:L45),0) -> 0 | W45: =IFERROR(AVERAGE(M45:O45),0) -> 0 | X45: =IFERROR(AVERAGE(P45:R45),0) -> 0
B46: SFG | C46: DAYS | S46: =R46 | U46: =IFERROR(AVERAGE(G46:I46),0) -> 0 | V46: =IFERROR(AVERAGE(J46:L46),0) -> 0 | W46: =IFERROR(AVERAGE(M46:O46),0) -> 0 | X46: =IFERROR(AVERAGE(P46:R46),0) -> 0
B47: BM | C47: DAYS | S47: =R47 | U47: =IFERROR(AVERAGE(G47:I47),0) -> 0 | V47: =IFERROR(AVERAGE(J47:L47),0) -> 0 | W47: =IFERROR(AVERAGE(M47:O47),0) -> 0 | X47: =IFERROR(AVERAGE(P47:R47),0) -> 0
...

Sheet PURCHASING
A1: PIONEER
A2: 2026 KPI TRACKER
A3: SC - PROCUREMENT
I5: Q1 | J5: Q1 | K5: Q1 | L5: Q2 | M5: Q2 | N5: Q2 | O5: Q3 | P5: Q3 | Q5: Q3 | R5: Q4 | S5: Q4 | T5: Q4
C6: UoM | E6: 2025 ACTUAL | G6: 2026 ABP | I6: OCT | J6: NOV | K6: DEC | L6: JAN | M6: FEB | N6: MAR | O6: APR | P6: MAY | Q6: JUN | R6: JUL | S6: AUG | T6: SEP | U6: 2026 YTD | X6: Q1 | Y6: Q2 | Z6: Q3 | AA6: Q4
A7: A. | B7: SAVINGS
B8: SAVINGS (Actual) | C8: Php | E8: 60470276 | G8: =SUM(I8:T8) -> 4447024.5 | I8: 2018550.4 | J8: 2428474.1 | U8: =SUM(I8:T8) -> 4447024.5
B9: SAVINGS (Target) | C9: Php | E9: 50000000 | G9: 40000000 | I9: =G9/12 -> 3333333.3 | J9: =G9/12 -> 3333333.3 | U9: =SUM(I9:T9) -> 6666666.7
B10: SAVINGS | C10: Php | E10: =IFERROR(E8/E9,0) -> 1.2094055 | G10: =IFERROR(G8/G9,0) -> 0.11117561 | I10: =IFERROR(I8/I9,0) -> 0.60556511 | J10: =IFERROR(J8/J9,0) -> 0.72854224 | K10: =IFERROR(K8/K9,0) -> 0 | L10: =IFERROR(L8/L9,0) -> 0 | M10: =IFERROR(M8/M9,0) -> 0 | N10: =IFERROR(N8/N9,0) -> 0 | O10: =IFERROR(O8/O9,0) -> 0 | P10: =IFERROR(P8/P9,0) -> 0 | ... U10: =IFERROR(U8/U9,0) -> 0.66705367
A12: B. | B12: P.O CONFORMANCE | C12: AFTER PR APPROVED
B13: Average P.O. Cycle Time | X13: =SUMIFS($I13:$T13,$I$5:$T$5,X$6) -> 0 | Y13: =SUMIFS($I13:$T13,$I$5:$T$5,Y$6) -> 0 | Z13: =SUMIFS($I13:$T13,$I$5:$T$5,Z$6) -> 0 | AA13: =SUMIFS($I13:$T13,$I$5:$T$5,AA$6) -> 0
B14: P.O for RM | C14: DAY | G14: 10 | U14: =IFERROR(AVERAGE(I14:T14),0) -> 0 | X14: =SUMIFS($I14:$T14,$I$6:$T$6,X$6) -> 0 | Y14: =SUMIFS($I14:$T14,$I$6:$T$6,Y$6) -> 0 | Z14: =SUMIFS($I14:$T14,$I$6:$T$6,Z$6) -> 0 | AA14: =SUMIFS($I14:$T14,$I$6:$T$6,AA$6) -> 0
B15: P.O for PM | C15: DAY | G15: 10 | U15: =IFERROR(AVERAGE(I15:T15),0) -> 0 | X15: =SUMIFS($I15:$T15,$I$6:$T$6,X$6) -> 0 | Y15: =SUMIFS($I15:$T15,$I$6:$T$6,Y$6) -> 0 | Z15: =SUMIFS($I15:$T15,$I$6:$T$6,Z$6) -> 0 | AA15: =SUMIFS($I15:$T15,$I$6:$T$6,AA$6) -> 0
B16: P.O for MRO | C16: DAY | G16: 21 | U16: =IFERROR(AVERAGE(I16:T16),0) -> 0 | X16: =SUMIFS($I16:$T16,$I$6:$T$6,X$6) -> 0 | Y16: =SUMIFS($I16:$T16,$I$6:$T$6,Y$6) -> 0 | Z16: =SUMIFS($I16:$T16,$I$6:$T$6,Z$6) -> 0 | AA16: =SUMIFS($I16:$T16,$I$6:$T$6,AA$6) -> 0
B17: P.O for MARKETING | C17: DAY | G17: 21 | U17: =IFERROR(AVERAGE(I17:T17),0) -> 0 | X17: =SUMIFS($I17:$T17,$I$6:$T$6,X$6) -> 0 | Y17: =SUMIFS($I17:$T17,$I$6:$T$6,Y$6) -> 0 | Z17: =SUMIFS($I17:$T17,$I$6:$T$6,Z$6) -> 0 | AA17: =SUMIFS($I17:$T17,$I$6:$T$6,AA$6) -> 0
B19: P.O. Accuracy
B20: Total number of P.O. | C20: count | U20: =SUM(I20:T20) -> 0 | X20: =SUMIFS($I20:$T20,$I$6:$T$6,X$6) -> 0 | Y20: =SUMIFS($I20:$T20,$I$6:$T$6,Y$6) -> 0 | Z20: =SUMIFS($I20:$T20,$I$6:$T$6,Z$6) -> 0 | AA20: =SUMIFS($I20:$T20,$I$6:$T$6,AA$6) -> 0
B21: # of erroneous delivery | C21: count | U21: =SUM(I21:T21) -> 0 | X21: =SUMIFS($I21:$T21,$I$6:$T$6,X$6) -> 0 | Y21: =SUMIFS($I21:$T21,$I$6:$T$6,Y$6) -> 0 | Z21: =SUMIFS($I21:$T21,$I$6:$T$6,Z$6) -> 0 | AA21: =SUMIFS($I21:$T21,$I$6:$T$6,AA$6) -> 0
B22: # of emergency P.O. | C22: count | U22: =SUM(I22:T22) -> 0 | X22: =SUMIFS($I22:$T22,$I$6:$T$6,X$6) -> 0 | Y22: =SUMIFS($I22:$T22,$I$6:$T$6,Y$6) -> 0 | Z22: =SUMIFS($I22:$T22,$I$6:$T$6,Z$6) -> 0 | AA22: =SUMIFS($I22:$T22,$I$6:$T$6,AA$6) -> 0
B23: Accuracy Rate | C23: % | E23: =IFERROR((E20-E21)/E20,0) -> 0 | G23: =IFERROR((G20-G21)/G20,0) -> 0 | I23: =IFERROR((I20-I21)/I20,0) -> 0 | J23: =IFERROR((J20-J21)/J20,0) -> 0 | K23: =IFERROR((K20-K21)/K20,0) -> 0 | L23: =IFERROR((L20-L21)/L20,0) -> 0 | M23: =IFERROR((M20-M21)/M20,0) -> 0 | N23: =IFERROR((N20-N21)/N20,0) -> 0 | O23: =IFERROR((O20-O21)/O20,0) -> 0 | P23: =IFERROR((P20-P21)/P20,0) -> 0 | ... U23: =IFERROR((U20-U21)/U20,0) -> 0 | X23: =IFERROR((X20-X21)/X20,0) -> 0 | Y23: =IFERROR((Y20-Y21)/Y20,0) -> 0 | Z23: =IFERROR((Z20-Z21)/Z20,0) -> 0 | AA23: =IFERROR((AA20-AA21)/AA20,0) -> 0
B24: Emergency Purchase ratio | C24: % | E24: =IFERROR((E20-E22)/E20,0) -> 0 | G24: =IFERROR((G20-G22)/G20,0) -> 0 | I24: =IFERROR((I20-I22)/I20,0) -> 0 | J24: =IFERROR((J20-J22)/J20,0) -> 0 | K24: =IFERROR((K20-K22)/K20,0) -> 0 | L24: =IFERROR((L20-L22)/L20,0) -> 0 | M24: =IFERROR((M20-M22)/M20,0) -> 0 | N24: =IFERROR((N20-N22)/N20,0) -> 0 | O24: =IFERROR((O20-O22)/O20,0) -> 0 | P24: =IFERROR((P20-P22)/P20,0) -> 0 | ... U24: =IFERROR((U20-U22)/U20,0) -> 0 | X24: =IFERROR((X20-X22)/X20,0) -> 0 | Y24: =IFERROR((Y20-Y22)/Y20,0) -> 0 | Z24: =IFERROR((Z20-Z22)/Z20,0) -> 0 | AA24: =IFERROR((AA20-AA22)/AA20,0) -> 0
A26: C. | B26: RM/PM PRICE ANALYSIS
B27: RM | V27: Actual vs last purchase | W27: Actual vs budget
B28: CHEM EPOXY RESIN 8 | C28: PHP | E28: 106.5 | F28: 1 | G28: 120.7 | U28: =IFERROR(AVERAGE(I28:T28),0) -> 0 | V28: =IFERROR(U28/E28,0)-1 -> -1 | W28: =IFERROR(U28/G28,0)-1 -> -1 | X28: =SUMIFS($I28:$T28,$I$6:$T$6,X$6) -> 0 | Y28: =SUMIFS($I28:$T28,$I$6:$T$6,Y$6) -> 0 | Z28: =SUMIFS($I28:$T28,$I$6:$T$6,Z$6) -> 0 | AA28: =SUMIFS($I28:$T28,$I$6:$T$6,AA$6) -> 0
B29: CHEM HARDENER PA 7 | C29: PHP | E29: 216.3 | G29: 247.1 | U29: =IFERROR(AVERAGE(I29:T29),0) -> 0 | V29: =IFERROR(U29/E29,0)-1 -> -1 | W29: =IFERROR(U29/G29,0)-1 -> -1 | X29: =SUMIFS($I29:$T29,$I$6:$T$6,X$6) -> 0 | Y29: =SUMIFS($I29:$T29,$I$6:$T$6,Y$6) -> 0 | Z29: =SUMIFS($I29:$T29,$I$6:$T$6,Z$6) -> 0 | AA29: =SUMIFS($I29:$T29,$I$6:$T$6,AA$6) -> 0
B30: CHEM HARDENER PA 9 | C30: PHP | E30: 221.9 | G30: 245 | U30: =IFERROR(AVERAGE(I30:T30),0) -> 0 | V30: =IFERROR(U30/E30,0)-1 -> -1 | W30: =IFERROR(U30/G30,0)-1 -> -1 | X30: =SUMIFS($I30:$T30,$I$6:$T$6,X$6) -> 0 | Y30: =SUMIFS($I30:$T30,$I$6:$T$6,Y$6) -> 0 | Z30: =SUMIFS($I30:$T30,$I$6:$T$6,Z$6) -> 0 | AA30: =SUMIFS($I30:$T30,$I$6:$T$6,AA$6) -> 0
B31: CHEM EPOXY RESIN 4 | C31: PHP | E31: 136.6 | G31: 152.49 | U31: =IFERROR(AVERAGE(I31:T31),0) -> 0 | V31: =IFERROR(U31/E31,0)-1 -> -1 | W31: =IFERROR(U31/G31,0)-1 -> -1 | X31: =SUMIFS($I31:$T31,$I$6:$T$6,X$6) -> 0 | Y31: =SUMIFS($I31:$T31,$I$6:$T$6,Y$6) -> 0 | Z31: =SUMIFS($I31:$T31,$I$6:$T$6,Z$6) -> 0 | AA31: =SUMIFS($I31:$T31,$I$6:$T$6,AA$6) -> 0
B32: CHEM RUBBER 2 | C32: PHP | E32: 284.3 | G32: 311.9 | U32: =IFERROR(AVERAGE(I32:T32),0) -> 0 | V32: =IFERROR(U32/E32,0)-1 -> -1 | W32: =IFERROR(U32/G32,0)-1 -> -1 | X32: =SUMIFS($I32:$T32,$I$6:$T$6,X$6) -> 0 | Y32: =SUMIFS($I32:$T32,$I$6:$T$6,Y$6) -> 0 | Z32: =SUMIFS($I32:$T32,$I$6:$T$6,Z$6) -> 0 | AA32: =SUMIFS($I32:$T32,$I$6:$T$6,AA$6) -> 0
B33: CHEM HARDENER AM 1 | C33: PHP | E33: 268.3 | U33: =IFERROR(AVERAGE(I33:T33),0) -> 0 | V33: =IFERROR(U33/E33,0)-1 -> -1 | W33: =IFERROR(U33/G33,0)-1 -> -1 | X33: =SUMIFS($I33:$T33,$I$6:$T$6,X$6) -> 0 | Y33: =SUMIFS($I33:$T33,$I$6:$T$6,Y$6) -> 0 | Z33: =SUMIFS($I33:$T33,$I$6:$T$6,Z$6) -> 0 | AA33: =SUMIFS($I33:$T33,$I$6:$T$6,AA$6) -> 0
B34: CHEM SOLVENT 15 | C34: PHP | U34: =IFERROR(AVERAGE(I34:T34),0) -> 0 | V34: =IFERROR(U34/E34,0)-1 -> -1 | W34: =IFERROR(U34/G34,0)-1 -> -1 | X34: =SUMIFS($I34:$T34,$I$6:$T$6,X$6) -> 0 | Y34: =SUMIFS($I34:$T34,$I$6:$T$6,Y$6) -> 0 | Z34: =SUMIFS($I34:$T34,$I$6:$T$6,Z$6) -> 0 | AA34: =SUMIFS($I34:$T34,$I$6:$T$6,AA$6) -> 0
B35: CHEM TACKIFIER RESIN 7 | C35: PHP | U35: =IFERROR(AVERAGE(I35:T35),0) -> 0 | V35: =IFERROR(U35/E35,0)-1 -> -1 | W35: =IFERROR(U35/G35,0)-1 -> -1 | X35: =SUMIFS($I35:$T35,$I$6:$T$6,X$6) -> 0 | Y35: =SUMIFS($I35:$T35,$I$6:$T$6,Y$6) -> 0 | Z35: =SUMIFS($I35:$T35,$I$6:$T$6,Z$6) -> 0 | AA35: =SUMIFS($I35:$T35,$I$6:$T$6,AA$6) -> 0
B36: CHEM FILLER CLAY 10 | C36: PHP | U36: =IFERROR(AVERAGE(I36:T36),0) -> 0 | V36: =IFERROR(U36/E36,0)-1 -> -1 | W36: =IFERROR(U36/G36,0)-1 -> -1 | X36: =SUMIFS($I36:$T36,$I$6:$T$6,X$6) -> 0 | Y36: =SUMIFS($I36:$T36,$I$6:$T$6,Y$6) -> 0 | Z36: =SUMIFS($I36:$T36,$I$6:$T$6,Z$6) -> 0 | AA36: =SUMIFS($I36:$T36,$I$6:$T$6,AA$6) -> 0
B37: CHEM EPOXY RESIN 5 | C37: PHP | U37: =IFERROR(AVERAGE(I37:T37),0) -> 0 | V37: =IFERROR(U37/E37,0)-1 -> -1 | W37: =IFERROR(U37/G37,0)-1 -> -1 | X37: =SUMIFS($I37:$T37,$I$6:$T$6,X$6) -> 0 | Y37: =SUMIFS($I37:$T37,$I$6:$T$6,Y$6) -> 0 | Z37: =SUMIFS($I37:$T37,$I$6:$T$6,Z$6) -> 0 | AA37: =SUMIFS($I37:$T37,$I$6:$T$6,AA$6) -> 0
B38: CHEM EMULSION SA 1 | C38: PHP | U38: =IFERROR(AVERAGE(I38:T38),0) -> 0 | V38: =IFERROR(U38/E38,0)-1 -> -1 | W38: =IFERROR(U38/G38,0)-1 -> -1 | X38: =SUMIFS($I38:$T38,$I$6:$T$6,X$6) -> 0 | Y38: =SUMIFS($I38:$T38,$I$6:$T$6,Y$6) -> 0 | Z38: =SUMIFS($I38:$T38,$I$6:$T$6,Z$6) -> 0 | AA38: =SUMIFS($I38:$T38,$I$6:$T$6,AA$6) -> 0
B39: CHEM CYANO 5 | C39: PHP | U39: =IFERROR(AVERAGE(I39:T39),0) -> 0 | V39: =IFERROR(U39/E39,0)-1 -> -1 | W39: =IFERROR(U39/G39,0)-1 -> -1 | X39: =SUMIFS($I39:$T39,$I$6:$T$6,X$6) -> 0 | Y39: =SUMIFS($I39:$T39,$I$6:$T$6,Y$6) -> 0 | Z39: =SUMIFS($I39:$T39,$I$6:$T$6,Z$6) -> 0 | AA39: =SUMIFS($I39:$T39,$I$6:$T$6,AA$6) -> 0
B40: CHEM CONTACT CEMENT 1 | C40: PHP | U40: =IFERROR(AVERAGE(I40:T40),0) -> 0 | V40: =IFERROR(U40/E40,0)-1 -> -1 | W40: =IFERROR(U40/G40,0)-1 -> -1 | X40: =SUMIFS($I40:$T40,$I$6:$T$6,X$6) -> 0 | Y40: =SUMIFS($I40:$T40,$I$6:$T$6,Y$6) -> 0 | Z40: =SUMIFS($I40:$T40,$I$6:$T$6,Z$6) -> 0 | AA40: =SUMIFS($I40:$T40,$I$6:$T$6,AA$6) -> 0
B41: CHEM TACKIFIER RESIN 6 | C41: PHP | U41: =IFERROR(AVERAGE(I41:T41),0) -> 0 | V41: =IFERROR(U41/E41,0)-1 -> -1 | W41: =IFERROR(U41/G41,0)-1 -> -1 | X41: =SUMIFS($I41:$T41,$I$6:$T$6,X$6) -> 0 | Y41: =SUMIFS($I41:$T41,$I$6:$T$6,Y$6) -> 0 | Z41: =SUMIFS($I41:$T41,$I$6:$T$6,Z$6) -> 0 | AA41: =SUMIFS($I41:$T41,$I$6:$T$6,AA$6) -> 0
B42: CHEM - FILLER CALCIUM 39 | C42: PHP | U42: =IFERROR(AVERAGE(I42:T42),0) -> 0 | V42: =IFERROR(U42/E42,0)-1 -> -1 | W42: =IFERROR(U42/G42,0)-1 -> -1 | X42: =SUMIFS($I42:$T42,$I$6:$T$6,X$6) -> 0 | Y42: =SUMIFS($I42:$T42,$I$6:$T$6,Y$6) -> 0 | Z42: =SUMIFS($I42:$T42,$I$6:$T$6,Z$6) -> 0 | AA42: =SUMIFS($I42:$T42,$I$6:$T$6,AA$6) -> 0
B43: CHEM SOLVENT 7 | C43: PHP | U43: =IFERROR(AVERAGE(I43:T43),0) -> 0 | V43: =IFERROR(U43/E43,0)-1 -> -1 | W43: =IFERROR(U43/G43,0)-1 -> -1 | X43: =SUMIFS($I43:$T43,$I$6:$T$6,X$6) -> 0 | Y43: =SUMIFS($I43:$T43,$I$6:$T$6,Y$6) -> 0 | Z43: =SUMIFS($I43:$T43,$I$6:$T$6,Z$6) -> 0 | AA43: =SUMIFS($I43:$T43,$I$6:$T$6,AA$6) -> 0
B44: CHEM ALKYD RESIN 5 | C44: PHP | U44: =IFERROR(AVERAGE(I44:T44),0) -> 0 | V44: =IFERROR(U44/E44,0)-1 -> -1 | W44: =IFERROR(U44/G44,0)-1 -> -1 | X44: =SUMIFS($I44:$T44,$I$6:$T$6,X$6) -> 0 | Y44: =SUMIFS($I44:$T44,$I$6:$T$6,Y$6) -> 0 | Z44: =SUMIFS($I44:$T44,$I$6:$T$6,Z$6) -> 0 | AA44: =SUMIFS($I44:$T44,$I$6:$T$6,AA$6) -> 0
...

Sheet PRODUCTION
A1: PIONEER
A2: 2026 KPI TRACKER
A3: PRODUCTION
G5: Q1 | H5: Q1 | I5: Q1 | J5: Q2 | K5: Q2 | L5: Q2 | M5: Q3 | N5: Q3 | O5: Q3 | P5: Q4 | Q5: Q4 | R5: Q4
C6: UoM | E6: 2026 ABP | G6: OCT | H6: NOV | I6: DEC | J6: JAN | K6: FEB | L6: MAR | M6: APR | N6: MAY | O6: JUN | P6: JUL | Q6: AUG | R6: SEP | S6: 2026 YTD | U6: Q1 | V6: Q2 | W6: Q3 | X6: Q4
A7: A. | B7: MACHINE UTILIZATION - BY TIME
B8: SUMMARY OF ALL LINE
B9: Actual Productive Time | C9: HRS | E9: =E64+E118+E173+E228+E283+E338+E393+E448+E503+E558+E613+E668+E723+E778+E833+E862+E917 -> 0 | G9: =G64+G119+G174+G229+G284+G339+G394+G449+G504+G559+G614+G669+G724+G779+G863+G918 -> 5263.9167 | H9: =H64+H119+H174+H229+H284+H339+H394+H449+H504+H559+H614+H669+H724+H779+H863+H918 -> 6353.9167 | I9: =I64+I119+I174+I229+I284+I339+I394+I449+I504+I559+I614+I669+I724+I779+I863+I918 -> 4228.1667 | J9: =J64+J119+J174+J229+J284+J339+J394+J449+J504+J559+J614+J669+J724+J779+J863+J918 -> 0 | K9: =K64+K119+K174+K229+K284+K339+K394+K449+K504+K559+K614+K669+K724+K779+K863+K918 -> 0 | L9: =L64+L119+L174+L229+L284+L339+L394+L449+L504+L559+L614+L669+L724+L779+L863+L918 -> 0 | M9: =M64+M119+M174+M229+M284+M339+M394+M449+M504+M559+M614+M669+M724+M779+M863+M918 -> 0 | N9: =N64+N119+N174+N229+N284+N339+N394+N449+N504+N559+N614+N669+N724+N779+N863+N918 -> 0 | ... R9: =R64+R119+R174+R229+R284+R339+R394+R449+R504+R559+R614+R669+R724+R779+R863+R918 -> 0 | S9: =SUM(G9:R9) -> 15846 | U9: =SUMIFS($G9:$R9,$G$5:$R$5,U$6) -> 15846 | V9: =SUMIFS($G9:$R9,$G$5:$R$5,V$6) -> 0 | W9: =SUMIFS($G9:$R9,$G$5:$R$5,W$6) -> 0 | X9: =SUMIFS($G9:$R9,$G$5:$R$5,X$6) -> 0
B10: No Production Plan | C10: HRS | E10: =E65+E119+E174+E229+E284+E339+E394+E449+E504+E559+E614+E669+E724+E779+E834+E863+E918 -> 0 | G10: =G65+G120+G175+G230+G285+G340+G395+G450+G505+G560+G615+G670+G725+G781+G864+G919 -> 5350.9833 | H10: =H65+H120+H175+H230+H285+H340+H395+H450+H505+H560+H615+H670+H725+H781+H864+H919 -> 3808.05 | I10: =I65+I120+I175+I230+I285+I340+I395+I450+I505+I560+I615+I670+I725+I781+I864+I919 -> 1155.85 | J10: =J65+J120+J175+J230+J285+J340+J395+J450+J505+J560+J615+J670+J725+J781+J864+J919 -> 0 | K10: =K65+K120+K175+K230+K285+K340+K395+K450+K505+K560+K615+K670+K725+K781+K864+K919 -> 0 | L10: =L65+L120+L175+L230+L285+L340+L395+L450+L505+L560+L615+L670+L725+L781+L864+L919 -> 0 | M10: =M65+M120+M175+M230+M285+M340+M395+M450+M505+M560+M615+M670+M725+M781+M864+M919 -> 0 | N10: =N65+N120+N175+N230+N285+N340+N395+N450+N505+N560+N615+N670+N725+N781+N864+N919 -> 0 | ... R10: =R65+R120+R175+R230+R285+R340+R395+R450+R505+R560+R615+R670+R725+R781+R864+R919 -> 0 | S10: =SUM(G10:R10) -> 10314.883 | U10: =SUMIFS($G10:$R10,$G$5:$R$5,U$6) -> 10314.883 | V10: =SUMIFS($G10:$R10,$G$5:$R$5,V$6) -> 0 | W10: =SUMIFS($G10:$R10,$G$5:$R$5,W$6) -> 0 | X10: =SUMIFS($G10:$R10,$G$5:$R$5,X$6) -> 0
B11: No Head Count Allocation | C11: HRS | E11: =E66+E120+E175+E230+E285+E340+E395+E450+E505+E560+E615+E670+E725+E780+E835+E864+E919 -> 0 | G11: =G66+G121+G176+G231+G286+G341+G396+G451+G506+G561+G616+G671+G726+G782+G865+G920 -> 2996.7 | H11: =H66+H121+H176+H231+H286+H341+H396+H451+H506+H561+H616+H671+H726+H782+H865+H920 -> 3600.15 | I11: =I66+I121+I176+I231+I286+I341+I396+I451+I506+I561+I616+I671+I726+I782+I865+I920 -> 2839.7667 | J11: =J66+J121+J176+J231+J286+J341+J396+J451+J506+J561+J616+J671+J726+J782+J865+J920 -> 0 | K11: =K66+K121+K176+K231+K286+K341+K396+K451+K506+K561+K616+K671+K726+K782+K865+K920 -> 0 | L11: =L66+L121+L176+L231+L286+L341+L396+L451+L506+L561+L616+L671+L726+L782+L865+L920 -> 0 | M11: =M66+M121+M176+M231+M286+M341+M396+M451+M506+M561+M616+M671+M726+M782+M865+M920 -> 0 | N11: =N66+N121+N176+N231+N286+N341+N396+N451+N506+N561+N616+N671+N726+N782+N865+N920 -> 0 | ... R11: =R66+R121+R176+R231+R286+R341+R396+R451+R506+R561+R616+R671+R726+R782+R865+R920 -> 0 | S11: =SUM(G11:R11) -> 9436.6167 | U11: =SUMIFS($G11:$R11,$G$5:$R$5,U$6) -> 9436.6167 | V11: =SUMIFS($G11:$R11,$G$5:$R$5,V$6) -> 0 | W11: =SUMIFS($G11:$R11,$G$5:$R$5,W$6) -> 0 | X11: =SUMIFS($G11:$R11,$G$5:$R$5,X$6) -> 0
B12: Change Over Time | C12: HRS | E12: =E67+E121+E176+E231+E286+E341+E396+E451+E506+E561+E616+E671+E726+E781+E836+E865+E920 -> 0 | G12: =G67+G122+G177+G232+G287+G342+G397+G452+G507+G562+G617+G672+G727+G783+G866+G921 -> 294.6 | H12: =H67+H122+H177+H232+H287+H342+H397+H452+H507+H562+H617+H672+H727+H783+H866+H921 -> 389.28333 | I12: =I67+I122+I177+I232+I287+I342+I397+I452+I507+I562+I617+I672+I727+I783+I866+I921 -> 214.31667 | J12: =J67+J122+J177+J232+J287+J342+J397+J452+J507+J562+J617+J672+J727+J783+J866+J921 -> 0 | K12: =K67+K122+K177+K232+K287+K342+K397+K452+K507+K562+K617+K672+K727+K783+K866+K921 -> 0 | L12: =L67+L122+L177+L232+L287+L342+L397+L452+L507+L562+L617+L672+L727+L783+L866+L921 -> 0 | M12: =M67+M122+M177+M232+M287+M342+M397+M452+M507+M562+M617+M672+M727+M783+M866+M921 -> 0 | N12: =N67+N122+N177+N232+N287+N342+N397+N452+N507+N562+N617+N672+N727+N783+N866+N921 -> 0 | ... R12: =R67+R122+R177+R232+R287+R342+R397+R452+R507+R562+R617+R672+R727+R783+R866+R921 -> 0 | S12: =SUM(G12:R12) -> 898.2 | U12: =SUMIFS($G12:$R12,$G$5:$R$5,U$6) -> 898.2 | V12: =SUMIFS($G12:$R12,$G$5:$R$5,V$6) -> 0 | W12: =SUMIFS($G12:$R12,$G$5:$R$5,W$6) -> 0 | X12: =SUMIFS($G12:$R12,$G$5:$R$5,X$6) -> 0
B13: Meeting | C13: HRS | E13: =E68+E122+E177+E232+E287+E342+E397+E452+E507+E562+E617+E672+E727+E782+E837+E866+E921 -> 0 | G13: =G68+G123+G178+G233+G288+G343+G398+G453+G508+G563+G618+G673+G728+G784+G867+G922 -> 29.233333 | H13: =H68+H123+H178+H233+H288+H343+H398+H453+H508+H563+H618+H673+H728+H784+H867+H922 -> 28.133333 | I13: =I68+I123+I178+I233+I288+I343+I398+I453+I508+I563+I618+I673+I728+I784+I867+I922 -> 7.3333333 | J13: =J68+J123+J178+J233+J288+J343+J398+J453+J508+J563+J618+J673+J728+J784+J867+J922 -> 0 | K13: =K68+K123+K178+K233+K288+K343+K398+K453+K508+K563+K618+K673+K728+K784+K867+K922 -> 0 | L13: =L68+L123+L178+L233+L288+L343+L398+L453+L508+L563+L618+L673+L728+L784+L867+L922 -> 0 | M13: =M68+M123+M178+M233+M288+M343+M398+M453+M508+M563+M618+M673+M728+M784+M867+M922 -> 0 | N13: =N68+N123+N178+N233+N288+N343+N398+N453+N508+N563+N618+N673+N728+N784+N867+N922 -> 0 | ... R13: =R68+R123+R178+R233+R288+R343+R398+R453+R508+R563+R618+R673+R728+R784+R867+R922 -> 0 | S13: =SUM(G13:R13) -> 64.7 | U13: =SUMIFS($G13:$R13,$G$5:$R$5,U$6) -> 64.7 | V13: =SUMIFS($G13:$R13,$G$5:$R$5,V$6) -> 0 | W13: =SUMIFS($G13:$R13,$G$5:$R$5,W$6) -> 0 | X13: =SUMIFS($G13:$R13,$G$5:$R$5,X$6) -> 0
B14: Sanitation Time | C14: HRS | E14: =E69+E123+E178+E233+E288+E343+E398+E453+E508+E563+E618+E673+E728+E783+E838+E867+E922 -> 0 | G14: =G69+G124+G179+G234+G289+G344+G399+G454+G509+G564+G619+G674+G729+G785+G868+G923 -> 158.6 | H14: =H69+H124+H179+H234+H289+H344+H399+H454+H509+H564+H619+H674+H729+H785+H868+H923 -> 180.8 | I14: =I69+I124+I179+I234+I289+I344+I399+I454+I509+I564+I619+I674+I729+I785+I868+I923 -> 72.266667 | J14: =J69+J124+J179+J234+J289+J344+J399+J454+J509+J564+J619+J674+J729+J785+J868+J923 -> 0 | K14: =K69+K124+K179+K234+K289+K344+K399+K454+K509+K564+K619+K674+K729+K785+K868+K923 -> 0 | L14: =L69+L124+L179+L234+L289+L344+L399+L454+L509+L564+L619+L674+L729+L785+L868+L923 -> 0 | M14: =M69+M124+M179+M234+M289+M344+M399+M454+M509+M564+M619+M674+M729+M785+M868+M923 -> 0 | N14: =N69+N124+N179+N234+N289+N344+N399+N454+N509+N564+N619+N674+N729+N785+N868+N923 -> 0 | ... R14: =R69+R124+R179+R234+R289+R344+R399+R454+R509+R564+R619+R674+R729+R785+R868+R923 -> 0 | S14: =SUM(G14:R14) -> 411.66667 | U14: =SUMIFS($G14:$R14,$G$5:$R$5,U$6) -> 411.66667 | V14: =SUMIFS($G14:$R14,$G$5:$R$5,V$6) -> 0 | W14: =SUMIFS($G14:$R14,$G$5:$R$5,W$6) -> 0 | X14: =SUMIFS($G14:$R14,$G$5:$R$5,X$6) -> 0
B15: Start-up Time/Setup | C15: HRS | E15: =E70+E124+E179+E234+E289+E344+E399+E454+E509+E564+E619+E674+E729+E784+E839+E868+E923 -> 0 | G15: =G70+G125+G180+G235+G290+G345+G400+G455+G510+G565+G620+G675+G730+G786+G869+G924 -> 306.63333 | H15: =H70+H125+H180+H235+H290+H345+H400+H455+H510+H565+H620+H675+H730+H786+H869+H924 -> 375.71667 | I15: =I70+I125+I180+I235+I290+I345+I400+I455+I510+I565+I620+I675+I730+I786+I869+I924 -> 127.65 | J15: =J70+J125+J180+J235+J290+J345+J400+J455+J510+J565+J620+J675+J730+J786+J869+J924 -> 0 | K15: =K70+K125+K180+K235+K290+K345+K400+K455+K510+K565+K620+K675+K730+K786+K869+K924 -> 0 | L15: =L70+L125+L180+L235+L290+L345+L400+L455+L510+L565+L620+L675+L730+L786+L869+L924 -> 0 | M15: =M70+M125+M180+M235+M290+M345+M400+M455+M510+M565+M620+M675+M730+M786+M869+M924 -> 0 | N15: =N70+N125+N180+N235+N290+N345+N400+N455+N510+N565+N620+N675+N730+N786+N869+N924 -> 0 | ... R15: =R70+R125+R180+R235+R290+R345+R400+R455+R510+R565+R620+R675+R730+R786+R869+R924 -> 0 | S15: =SUM(G15:R15) -> 810 | U15: =SUMIFS($G15:$R15,$G$5:$R$5,U$6) -> 810 | V15: =SUMIFS($G15:$R15,$G$5:$R$5,V$6) -> 0 | W15: =SUMIFS($G15:$R15,$G$5:$R$5,W$6) -> 0 | X15: =SUMIFS($G15:$R15,$G$5:$R$5,X$6) -> 0
B16: Shutdown/cooldown | C16: HRS | E16: =E71+E125+E180+E235+E290+E345+E400+E455+E510+E565+E620+E675+E730+E785+E840+E869+E924 -> 0 | G16: =G71+G126+G181+G236+G291+G346+G401+G456+G511+G566+G621+G676+G731+G787+G870+G925 -> 0.83333333 | H16: =H71+H126+H181+H236+H291+H346+H401+H456+H511+H566+H621+H676+H731+H787+H870+H925 -> 0 | I16: =I71+I126+I181+I236+I291+I346+I401+I456+I511+I566+I621+I676+I731+I787+I870+I925 -> 0 | J16: =J71+J126+J181+J236+J291+J346+J401+J456+J511+J566+J621+J676+J731+J787+J870+J925 -> 0 | K16: =K71+K126+K181+K236+K291+K346+K401+K456+K511+K566+K621+K676+K731+K787+K870+K925 -> 0 | L16: =L71+L126+L181+L236+L291+L346+L401+L456+L511+L566+L621+L676+L731+L787+L870+L925 -> 0 | M16: =M71+M126+M181+M236+M291+M346+M401+M456+M511+M566+M621+M676+M731+M787+M870+M925 -> 0 | N16: =N71+N126+N181+N236+N291+N346+N401+N456+N511+N566+N621+N676+N731+N787+N870+N925 -> 0 | ... R16: =R71+R126+R181+R236+R291+R346+R401+R456+R511+R566+R621+R676+R731+R787+R870+R925 -> 0 | S16: =SUM(G16:R16) -> 0.83333333 | U16: =SUMIFS($G16:$R16,$G$5:$R$5,U$6) -> 0.83333333 | V16: =SUMIFS($G16:$R16,$G$5:$R$5,V$6) -> 0 | W16: =SUMIFS($G16:$R16,$G$5:$R$5,W$6) -> 0 | X16: =SUMIFS($G16:$R16,$G$5:$R$5,X$6) -> 0
B17: Testing Time | C17: HRS | E17: =E72+E126+E181+E236+E291+E346+E401+E456+E511+E566+E621+E676+E731+E786+E841+E870+E925 -> 0 | G17: =G72+G127+G182+G237+G292+G347+G402+G457+G512+G567+G622+G677+G732+G788+G871+G926 -> 118.1 | H17: =H72+H127+H182+H237+H292+H347+H402+H457+H512+H567+H622+H677+H732+H788+H871+H926 -> 176.15 | I17: =I72+I127+I182+I237+I292+I347+I402+I457+I512+I567+I622+I677+I732+I788+I871+I926 -> 8.4 | J17: =J72+J127+J182+J237+J292+J347+J402+J457+J512+J567+J622+J677+J732+J788+J871+J926 -> 0 | K17: =K72+K127+K182+K237+K292+K347+K402+K457+K512+K567+K622+K677+K732+K788+K871+K926 -> 0 | L17: =L72+L127+L182+L237+L292+L347+L402+L457+L512+L567+L622+L677+L732+L788+L871+L926 -> 0 | M17: =M72+M127+M182+M237+M292+M347+M402+M457+M512+M567+M622+M677+M732+M788+M871+M926 -> 0 | N17: =N72+N127+N182+N237+N292+N347+N402+N457+N512+N567+N622+N677+N732+N788+N871+N926 -> 0 | ... R17: =R72+R127+R182+R237+R292+R347+R402+R457+R512+R567+R622+R677+R732+R788+R871+R926 -> 0 | S17: =SUM(G17:R17) -> 302.65 | U17: =SUMIFS($G17:$R17,$G$5:$R$5,U$6) -> 302.65 | V17: =SUMIFS($G17:$R17,$G$5:$R$5,V$6) -> 0 | W17: =SUMIFS($G17:$R17,$G$5:$R$5,W$6) -> 0 | X17: =SUMIFS($G17:$R17,$G$5:$R$5,X$6) -> 0
B18: Breaktime | C18: HRS | E18: =E73+E127+E182+E237+E292+E347+E402+E457+E512+E567+E622+E677+E732+E787+E842+E871+E926 -> 0 | G18: =G73+G128+G183+G238+G293+G348+G403+G458+G513+G568+G623+G678+G733+G789+G872+G927 -> 276.4 | H18: =H73+H128+H183+H238+H293+H348+H403+H458+H513+H568+H623+H678+H733+H789+H872+H927 -> 350.36667 | I18: =I73+I128+I183+I238+I293+I348+I403+I458+I513+I568+I623+I678+I733+I789+I872+I927 -> 194.46667 | J18: =J73+J128+J183+J238+J293+J348+J403+J458+J513+J568+J623+J678+J733+J789+J872+J927 -> 0 | K18: =K73+K128+K183+K238+K293+K348+K403+K458+K513+K568+K623+K678+K733+K789+K872+K927 -> 0 | L18: =L73+L128+L183+L238+L293+L348+L403+L458+L513+L568+L623+L678+L733+L789+L872+L927 -> 0 | M18: =M73+M128+M183+M238+M293+M348+M403+M458+M513+M568+M623+M678+M733+M789+M872+M927 -> 0 | N18: =N73+N128+N183+N238+N293+N348+N403+N458+N513+N568+N623+N678+N733+N789+N872+N927 -> 0 | ... R18: =R73+R128+R183+R238+R293+R348+R403+R458+R513+R568+R623+R678+R733+R789+R872+R927 -> 0 | S18: =SUM(G18:R18) -> 821.23333 | U18: =SUMIFS($G18:$R18,$G$5:$R$5,U$6) -> 821.23333 | V18: =SUMIFS($G18:$R18,$G$5:$R$5,V$6) -> 0 | W18: =SUMIFS($G18:$R18,$G$5:$R$5,W$6) -> 0 | X18: =SUMIFS($G18:$R18,$G$5:$R$5,X$6) -> 0
B19: Preventitve Maintenance | C19: HRS | E19: =E74+E128+E183+E238+E293+E348+E403+E458+E513+E568+E623+E678+E733+E788+E843+E872+E927 -> 0 | G19: =G74+G129+G184+G239+G294+G349+G404+G459+G514+G569+G624+G679+G734+G790+G873+G928 -> 3 | H19: =H74+H129+H184+H239+H294+H349+H404+H459+H514+H569+H624+H679+H734+H790+H873+H928 -> 1.3333333 | I19: =I74+I129+I184+I239+I294+I349+I404+I459+I514+I569+I624+I679+I734+I790+I873+I928 -> 3.85 | J19: =J74+J129+J184+J239+J294+J349+J404+J459+J514+J569+J624+J679+J734+J790+J873+J928 -> 0 | K19: =K74+K129+K184+K239+K294+K349+K404+K459+K514+K569+K624+K679+K734+K790+K873+K928 -> 0 | L19: =L74+L129+L184+L239+L294+L349+L404+L459+L514+L569+L624+L679+L734+L790+L873+L928 -> 0 | M19: =M74+M129+M184+M239+M294+M349+M404+M459+M514+M569+M624+M679+M734+M790+M873+M928 -> 0 | N19: =N74+N129+N184+N239+N294+N349+N404+N459+N514+N569+N624+N679+N734+N790+N873+N928 -> 0 | ... R19: =R74+R129+R184+R239+R294+R349+R404+R459+R514+R569+R624+R679+R734+R790+R873+R928 -> 0 | S19: =SUM(G19:R19) -> 8.1833333 | U19: =SUMIFS($G19:$R19,$G$5:$R$5,U$6) -> 8.1833333 | V19: =SUMIFS($G19:$R19,$G$5:$R$5,V$6) -> 0 | W19: =SUMIFS($G19:$R19,$G$5:$R$5,W$6) -> 0 | X19: =SUMIFS($G19:$R19,$G$5:$R$5,X$6) -> 0
B20: Force Majeure | C20: HRS | E20: =E75+E129+E184+E239+E294+E349+E404+E459+E514+E569+E624+E679+E734+E789+E844+E873+E928 -> 0 | G20: =G75+G130+G185+G240+G295+G350+G405+G460+G515+G570+G625+G680+G735+G791+G874+G929 -> 48 | H20: =H75+H130+H185+H240+H295+H350+H405+H460+H515+H570+H625+H680+H735+H791+H874+H929 -> 0 | I20: =I75+I130+I185+I240+I295+I350+I405+I460+I515+I570+I625+I680+I735+I791+I874+I929 -> 0 | J20: =J75+J130+J185+J240+J295+J350+J405+J460+J515+J570+J625+J680+J735+J791+J874+J929 -> 0 | K20: =K75+K130+K185+K240+K295+K350+K405+K460+K515+K570+K625+K680+K735+K791+K874+K929 -> 0 | L20: =L75+L130+L185+L240+L295+L350+L405+L460+L515+L570+L625+L680+L735+L791+L874+L929 -> 0 | M20: =M75+M130+M185+M240+M295+M350+M405+M460+M515+M570+M625+M680+M735+M791+M874+M929 -> 0 | N20: =N75+N130+N185+N240+N295+N350+N405+N460+N515+N570+N625+N680+N735+N791+N874+N929 -> 0 | ... R20: =R75+R130+R185+R240+R295+R350+R405+R460+R515+R570+R625+R680+R735+R791+R874+R929 -> 0 | S20: =SUM(G20:R20) -> 48 | U20: =SUMIFS($G20:$R20,$G$5:$R$5,U$6) -> 48 | V20: =SUMIFS($G20:$R20,$G$5:$R$5,V$6) -> 0 | W20: =SUMIFS($G20:$R20,$G$5:$R$5,W$6) -> 0 | X20: =SUMIFS($G20:$R20,$G$5:$R$5,X$6) -> 0
B21: Electrical Breakdown | C21: HRS | E21: =E76+E130+E185+E240+E295+E350+E405+E460+E515+E570+E625+E680+E735+E790+E845+E874+E929 -> 0 | G21: =G76+G131+G186+G241+G296+G351+G406+G461+G516+G571+G626+G681+G736+G792+G875+G930 -> 0.25 | H21: =H76+H131+H186+H241+H296+H351+H406+H461+H516+H571+H626+H681+H736+H792+H875+H930 -> 0.56666667 | I21: =I76+I131+I186+I241+I296+I351+I406+I461+I516+I571+I626+I681+I736+I792+I875+I930 -> 1 | J21: =J76+J131+J186+J241+J296+J351+J406+J461+J516+J571+J626+J681+J736+J792+J875+J930 -> 0 | K21: =K76+K131+K186+K241+K296+K351+K406+K461+K516+K571+K626+K681+K736+K792+K875+K930 -> 0 | L21: =L76+L131+L186+L241+L296+L351+L406+L461+L516+L571+L626+L681+L736+L792+L875+L930 -> 0 | M21: =M76+M131+M186+M241+M296+M351+M406+M461+M516+M571+M626+M681+M736+M792+M875+M930 -> 0 | N21: =N76+N131+N186+N241+N296+N351+N406+N461+N516+N571+N626+N681+N736+N792+N875+N930 -> 0 | ... R21: =R76+R131+R186+R241+R296+R351+R406+R461+R516+R571+R626+R681+R736+R792+R875+R930 -> 0 | S21: =SUM(G21:R21) -> 1.8166667 | U21: =SUMIFS($G21:$R21,$G$5:$R$5,U$6) -> 1.8166667 | V21: =SUMIFS($G21:$R21,$G$5:$R$5,V$6) -> 0 | W21: =SUMIFS($G21:$R21,$G$5:$R$5,W$6) -> 0 | X21: =SUMIFS($G21:$R21,$G$5:$R$5,X$6) -> 0
... B30: Transfer | C30: HRS | E30: =E85+E139+E194+E249+E304+E359+E414+E469+E524+E579+E634+E689+E744+E799+E854+E883+E938 -> 0 | G30: =G85+G140+G195+G250+G305+G360+G415+G470+G525+G580+G635+G690+G745+G801+G884+G939 -> 495.91667 | H30: =H85+H140+H195+H250+H305+H360+H415+H470+H525+H580+H635+H690+H745+H801+H884+H939 -> 540.5 | I30: =I85+I140+I195+I250+I305+I360+I415+I470+I525+I580+I635+I690+I745+I801+I884+I939 -> 60.75 | J30: =J85+J140+J195+J250+J305+J360+J415+J470+J525+J580+J635+J690+J745+J801+J884+J939 -> 0 | K30: =K85+K140+K195+K250+K305+K360+K415+K470+K525+K580+K635+K690+K745+K801+K884+K939 -> 0 | L30: =L85+L140+L195+L250+L305+L360+L415+L470+L525+L580+L635+L690+L745+L801+L884+L939 -> 0 | M30: =M85+M140+M195+M250+M305+M360+M415+M470+M525+M580+M635+M690+M745+M801+M884+M939 -> 0 | N30: =N85+N140+N195+N250+N305+N360+N415+N470+N525+N580+N635+N690+N745+N801+N884+N939 -> 0 | ... R30: =R85+R140+R195+R250+R305+R360+R415+R470+R525+R580+R635+R690+R745+R801+R884+R939 -> 0 | S30: =SUM(G30:R30) -> 1097.1667 | U30: =SUMIFS($G30:$R30,$G$5:$R$5,U$6) -> 1097.1667 | V30: =SUMIFS($G30:$R30,$G$5:$R$5,V$6) -> 0 | W30: =SUMIFS($G30:$R30,$G$5:$R$5,W$6) -> 0 | X30: =SUMIFS($G30:$R30,$G$5:$R$5,X$6) -> 0
B31: Idle time | C31: HRS | E31: =E86+E158+E213+E268+E323+E378+E433+E488+E543+E600+E653+E708+E763+E818+E850+E902+E957 -> 0 | G31: =G86+G141+G196+G251+G306+G361+G416+G471+G526+G581+G636+G691+G746+G801+G885+G940 -> 82.466667 | H31: =H86+H141+H196+H251+H306+H361+H416+H471+H526+H581+H636+H691+H746+H801+H885+H940 -> 108.98333 | I31: =I86+I141+I196+I251+I306+I361+I416+I471+I526+I581+I636+I691+I746+I801+I885+I940 -> 56.083333 | J31: =J86+J141+J196+J251+J306+J361+J416+J471+J526+J581+J636+J691+J746+J801+J885+J940 -> 0 | K31: =K86+K141+K196+K251+K306+K361+K416+K471+K526+K581+K636+K691+K746+K801+K885+K940 -> 0 | L31: =L86+L141+L196+L251+L306+L361+L416+L471+L526+L581+L636+L691+L746+L801+L885+L940 -> 0 | M31: =M86+M141+M196+M251+M306+M361+M416+M471+M526+M581+M636+M691+M746+M801+M885+M940 -> 0 | N31: =N86+N141+N196+N251+N306+N361+N416+N471+N526+N581+N636+N691+N746+N801+N885+N940 -> 0 | ... R31: =R86+R141+R196+R251+R306+R361+R416+R471+R526+R581+R636+R691+R746+R801+R885+R940 -> 0 | S31: =SUM(G31:R31) -> 247.53333 | U31: =SUMIFS($G31:$R31,$G$5:$R$5,U$6) -> 247.53333 | V31: =SUMIFS($G31:$R31,$G$5:$R$5,V$6) -> 0 | W31: =SUMIFS($G31:$R31,$G$5:$R$5,W$6) -> 0 | X31: =SUMIFS($G31:$R31,$G$5:$R$5,X$6) -> 0
B32: TOTAL | C32: HRS | E32: =E87+E161+E214+E271+E326+E381+E434+E491+E546+E601+E656+E711+E766+E821+E851+E905+E960 -> #REF! | G32: =G87+G142+G197+G252+G307+G362+G417+G472+G527+G582+G637+G692+G747+G802+G886+G941 -> 18337.65 | H32: =H87+H142+H197+H252+H307+H362+H417+H472+H527+H582+H637+H692+H747+H802+H886+H941 -> 18004.567 | I32: =I87+I142+I197+I252+I307+I362+I417+I472+I527+I582+I637+I692+I747+I802+I886+I941 -> 11336.667 | J32: =J87+J142+J197+J252+J307+J362+J417+J472+J527+J582+J637+J692+J747+J802+J886+J941 -> 0 | K32: =K87+K142+K197+K252+K307+K362+K417+K472+K527+K582+K637+K692+K747+K802+K886+K941 -> 0 | L32: =L87+L142+L197+L252+L307+L362+L417+L472+L527+L582+L637+L692+L747+L802+L886+L941 -> 0 | M32: =M87+M142+M197+M252+M307+M362+M417+M472+M527+M582+M637+M692+M747+M802+M886+M941 -> 0 | N32: =N87+N142+N197+N252+N307+N362+N417+N472+N527+N582+N637+N692+N747+N802+N886+N941 -> 0 | ... R32: =R87+R142+R197+R252+R307+R362+R417+R472+R527+R582+R637+R692+R747+R802+R886+R941 -> 0 | S32: =SUM(G32:R32) -> 47678.883 | U32: =SUMIFS($G32:$R32,$G$5:$R$5,U$6) -> 47678.883 | V32: =SUMIFS($G32:$R32,$G$5:$R$5,V$6) -> 0 | W32: =SUMIFS($G32:$R32,$G$5:$R$5,W$6) -> 0 | X32: =SUMIFS($G32:$R32,$G$5:$R$5,X$6) -> 0
B34: Actual Productive Time | C34: % | E34: =IFERROR(E8/E$32,0) -> 0 | G34: =IFERROR(G9/G$32,0) -> 0.28705514 | H34: =IFERROR(H9/H$32,0) -> 0.35290584 | I34: =IFERROR(I9/I$32,0) -> 0.37296383 | J34: =IFERROR(J9/J$32,0) -> 0 | K34: =IFERROR(K9/K$32,0) -> 0 | L34: =IFERROR(L9/L$32,0) -> 0 | M34: =IFERROR(M9/M$32,0) -> 0 | N34: =IFERROR(N9/N$32,0) -> 0 | ... S34: =IFERROR(S9/S$32,0) -> 0.33234839 | U34: =IFERROR(U9/U$32,0) -> 0.33234839 | V34: =IFERROR(V9/V$32,0) -> 0 | W34: =IFERROR(W9/W$32,0) -> 0 | X34: =IFERROR(X9/X$32,0) -> 0
B35: No Production Plan | C35: % | E35: =IFERROR(E9/E$32,0) -> 0 | G35: =IFERROR(G10/G$32,0) -> 0.29180311 | H35: =IFERROR(H10/H$32,0) -> 0.21150467 | I35: =IFERROR(I10/I$32,0) -> 0.10195678 | J35: =IFERROR(J10/J$32,0) -> 0 | K35: =IFERROR(K10/K$32,0) -> 0 | L35: =IFERROR(L10/L$32,0) -> 0 | M35: =IFERROR(M10/M$32,0) -> 0 | N35: =IFERROR(N10/N$32,0) -> 0 | ... S35: =IFERROR(S10/S$32,0) -> 0.21634071 | U35: =IFERROR(U10/U$32,0) -> 0.21634071 | V35: =IFERROR(V10/V$32,0) -> 0 | W35: =IFERROR(W10/W$32,0) -> 0 | X35: =IFERROR(X10/X$32,0) -> 0
B36: No Head Count Allocation | C36: % | E36: =IFERROR(E10/E$32,0) -> 0 | G36: =IFERROR(G11/G$32,0) -> 0.16341789 | H36: =IFERROR(H11/H$32,0) -> 0.1999576 | I36: =IFERROR(I11/I$32,0) -> 0.25049397 | J36: =IFERROR(J11/J$32,0) -> 0 | K36: =IFERROR(K11/K$32,0) -> 0 | L36: =IFERROR(L11/L$32,0) -> 0 | M36: =IFERROR(M11/M$32,0) -> 0 | N36: =IFERROR(N11/N$32,0) -> 0 | ... S36: =IFERROR(S11/S$32,0) -> 0.19792025 | U36: =IFERROR(U11/U$32,0) -> 0.19792025 | V36: =IFERROR(V11/V$32,0) -> 0 | W36: =IFERROR(W11/W$32,0) -> 0 | X36: =IFERROR(X11/X$32,0) -> 0
B37: Change Over Time | C37: % | E37: =IFERROR(E11/E$32,0) -> 0 | G37: =IFERROR(G12/G$32,0) -> 0.016065308 | H37: =IFERROR(H12/H$32,0) -> 0.021621366 | I37: =IFERROR(I12/I$32,0) -> 0.018904734 | J37: =IFERROR(J12/J$32,0) -> 0 | K37: =IFERROR(K12/K$32,0) -> 0 | L37: =IFERROR(L12/L$32,0) -> 0 | M37: =IFERROR(M12/M$32,0) -> 0 | N37: =IFERROR(N12/N$32,0) -> 0 | ... S37: =IFERROR(S12/S$32,0) -> 0.018838528 | U37: =IFERROR(U12/U$32,0) -> 0.018838528 | V37: =IFERROR(V12/V$32,0) -> 0 | W37: =IFERROR(W12/W$32,0) -> 0 | X37: =IFERROR(X12/X$32,0) -> 0
