Workbook
Name blank: [1]Program!$B$9
Name Department: [2]Department!$A$1:$K$1
Name Itemcodes: [1]Itemlist!$A$4:$A$827
Name Problem: '[3]Raw Data'!$A$2:$A$11
Name PRODUCTION_TICKET_DETAILS: Data!$A$1:$D$2077
Name Section: [4]Section!$A$1:$A$14
Name Sectionlist: [5]Sectionlist!$A$1:$A$14
Name Sections: [6]Sections!$A$1:$A$19

Sheet SAMPLE DPR rev1
B1: DAILY PRODUCTION REPORT | V1: HOURLY BOTTLENECK MANAGEMENT
B4: Item code: | D4: 1E2M5846 | I4: PRD No. : | J4: 15039 | Q4: Production Date: | T4: Feb 2,2024 | V4: Process Name: | Y4: FILLING | AB4: Rated Speed: | AD4: 780 pcs | AH4: Ideal Rate (per min) : | AJ4: 13 pcs
B5: Item Description : | Q5: Production Line: | T5: Elasto | V5: Machine Name: | Z5: M/C 3 | AD5: Machine Name: | AH5: M/C 4
B6: PPRO ELASTOSEAL PISILITO | Q6: Batch No. | S6: 26020383 | V6: Time | W6: UP Time | Y6: Plan Output | Z6: Actual Output | AB6: Reject Output | AD6: Time | AE6: UP Time | AG6: Plan Output | AH6: Actual Output | AJ6: Reject Output
B7: I. RAW AND PACKAGING MATERIALS USED | V7: 6-7 | W7: 60 | Y7: 780 | Z7: 780 | AB7: 0 | AD7: 6-7 | AE7: 60
B8: No. | C8: ITEM CODE | G8: Description | J8: Batch/Lot No | Q8: Consumption | T8: Wastage | U8: Remarks | V8: 7-8 | W8: 45 | Y8: 780 | Z8: 600 | AB8: 10 | AD8: 7-8 | AE8: 60
B9: 1 | C9: 4P520001 | G9: POUCH-PISILITO 85G | J9: 118272 | Q9: 2700 | T9: 80 | U9: damage | V9: 9-10 | W9: 30 | Y9: =780/2 -> 390 | Z9: 300 | AB9: 0 | AD9: 9-10 | AE9: 30
B10: 2 | C10: 4XEP1000 | G10: P.BOX-PISILITO 100G | J10: 1172746 | Q10: 16 | T10: 0 | V10: 11-12 | W10: 16 | Y10: 780 | Z10: 60 | AB10: 20 | AD10: 11-12 | AE10: 60
B11: 3 | V11: 12-1 | W11: 60 | Y11: 780 | Z11: 780 | AB11: - | AD11: 12-1 | AE11: 60
B12: 4 | V12: 1-2 | W12: 60 | Y12: 780 | Z12: 0 | AB12: 0 | AD12: 1-2 | AE12: 60
B13: 5 | V13: 2-3 | W13: - | Y13: - | Z13: - | AB13: - | AD13: 2-3 | AE13: 45
B14: 6 | V14: 3-4 | W14: - | Y14: - | Z14: - | AB14: - | AD14: 3-4 | AE14: 60
B15: 7 | V15: 4-5 | W15: - | Y15: - | Z15: - | AB15: - | AD15: 4-5 | AE15: 60
B16: 8 | V16: 5-6 | W16: - | Y16: - | Z16: - | AB16: - | AD16: 5-6 | AE16: 60
B17: 9 | V17: Downtime Activities | AD17: Downtime Activities
B19: 10 | V19: Planned Downtime: 9:30 to 10am - 30 mins Breakdown 7:15 to 8am - Change Kettle 11:17 to 12pm - Change Over Unplanned Downtime: 1pm to 2pm - Machine Breakdown (Sealer Problem) | AD19: NO PRODUCTION
B20: II. QUALITY | S20: Quality Remarks
B21: Total Actual Output | H21: Total Accepted Output | M21: Total Rejected Output | S21: PASSED FG
B22: 2780 | H22: 2700 | M22: 80
B25: III. MANPOWER / PRODUCTIVITY | O25: QR CODE BATCH NO Approved by: / Date | V25: Machine Name: | Z25: M/C 5 | AD25: Machine Name:
B26: No. | C26: Name of Associates | F26: Assignment | I26: Machine Used | M26: Signature | V26: Time | W26: UP Time | Y26: Plan Output | Z26: Actual Output | AB26: Reject Output | AD26: Time | AE26: UP Time | AG26: Plan Output | AH26: Actual Output | AJ26: Reject Output
B27: 1 | V27: 6-7 | W27: 60 | AD27: 6-7 | AE27: 60
B28: 2 | V28: 7-8 | W28: 60 | AD28: 7-8 | AE28: 60
B29: 3 | V29: 9-10 | W29: 30 | AD29: 9-10 | AE29: 30
B30: 4 | V30: 11-12 | W30: 60 | AD30: 11-12 | AE30: 60
B31: 5 | V31: 12-1 | W31: 60 | AD31: 12-1 | AE31: 60
B32: 6 | V32: 1-2 | W32: 60 | AD32: 1-2 | AE32: 60
B33: 7 | V33: 2-3 | W33: 45 | AD33: 2-3 | AE33: 45
B34: 8 | V34: 3-4 | W34: 60 | AD34: 3-4 | AE34: 60
B35: 9 | V35: 4-5 | W35: 60 | AD35: 4-5 | AE35: 60
B36: 10 | V36: 5-6 | W36: 60 | AD36: 5-6 | AE36: 60
B37: IV. SYSTEM REPORTING | O37: Prepared By: | V37: Downtime Activities | AD37: Downtime Activities
B38: Date Reported: | I38: Transfer No. | V38: NO PRODUCTION | AD38: NO PRODUCTION
O39: Production Team Leader
B40: Reported By: | I40: Shipment No.
O41: Reviewed By:
B42: Docpro Remarks:
O43: Production Section Head

Sheet Data
A1: Formula ID | B1: Description | C1: Input ID | D1: Description
A2: 1APC2009 | B2: ALL PURPOSE EPOXY GALLON | C2: 4CL02000 | D2: C.LABEL GALLON B
A3: 1APC2009 | B3: ALL PURPOSE EPOXY GALLON | C3: 4C010000 | D3: T.CAN-GALLON W/ HANDLE
A4: 1APC2009 | B4: ALL PURPOSE EPOXY GALLON | C4: 4CL01000 | D4: C.LABEL GALLON A
A5: 1APC2009 | B5: ALL PURPOSE EPOXY GALLON | C5: P45780085 | D5: P.BOX- GALLON (PRINTED)
A6: 1APC2010 | B6: ALL PURPOSE EPOXY QUART | C6: 4CL03000 | D6: C.LABEL QUART A
A7: 1APC2010 | B7: ALL PURPOSE EPOXY QUART | C7: 4CL04000 | D7: C.LABEL- QUART B
A8: 1APC2010 | B8: ALL PURPOSE EPOXY QUART | C8: 4C020000 | D8: T.CAN-QUART
A9: 1APC2010 | B9: ALL PURPOSE EPOXY QUART | C9: P45780083 | D9: P.BOX QUART (PRINTED)
A10: 1APC2012 | B10: ALL PURPOSE EPOXY PINT | C10: 4CL05000 | D10: C.LABEL- PINT A
A11: 1APC2012 | B11: ALL PURPOSE EPOXY PINT | C11: 4C030000 | D11: T.CAN-PINT
A12: 1APC2012 | B12: ALL PURPOSE EPOXY PINT | C12: P45780081 | D12: P.BOX PINT (PRINTED)
... A2077: GIP000053 | B2077: GIP-MIGHTY BOND SHOES 3G | C2077: PM000107 | D2077: A.TUBE-MIGHTY BOND SHOES 3G

Sheet SAMPLE BLANK FORM rev1
B1: DAILY PRODUCTION REPORT | V1: HOURLY BOTTLENECK MANAGEMENT
B4: Item code: | I4: PRD No. : | Q4: Production Date: | V4: Process Name: | AB4: Rated Speed: | AH4: Ideal Rate (per min) :
B5: Item Description : | Q5: Production Line: | V5: Machine Name: | AD5: Machine Name:
Q6: Batch No. | V6: Time | W6: Loading Time | Y6: Plan Output | Z6: Actual Output | AB6: Reject Output | AD6: Time | AE6: Loading Time | AG6: Plan Output | AH6: Actual Output | AJ6: Reject Output
B7: I. RAW AND PACKAGING MATERIALS USED | V7: 6-7 | AD7: 6-7 | AE7: 60
B8: No. | C8: ITEM CODE | G8: Description | J8: Batch/Lot No | Q8: Consumption | T8: Wastage | U8: Remarks | V8: 7-8 | AD8: 7-8 | AE8: 60
B9: 1 | V9: 9-10 | AD9: 9-10 | AE9: 30
B10: 2 | V10: 11-12 | AD10: 11-12 | AE10: 60
B11: 3 | V11: 12-1 | AD11: 12-1 | AE11: 60
B12: 4 | V12: 1-2 | AD12: 1-2 | AE12: 60
B13: 5 | V13: 2-3 | AD13: 2-3 | AE13: 45
B14: 6 | V14: 3-4 | AD14: 3-4 | AE14: 60
B15: 7 | V15: 4-5 | AD15: 4-5 | AE15: 60
B16: 8 | V16: 5-6 | AD16: 5-6 | AE16: 60
B17: 9 | V17: Downtime Activities | AD17: Downtime Activities
B19: 10
B20: II. QUALITY | S20: Quality Remarks
B21: Total Actual Output | H21: Total Accepted Output | M21: Total Rejected Output
B25: III. MANPOWER / PRODUCTIVITY | O25: QR CODE BATCH NO Approved by: / Date | V25: Machine Name: | Z25: M/C 5 | AD25: Machine Name:
B26: No. | C26: Name of Associates | F26: Assignment | I26: Machine Used | M26: Signature | V26: Time | W26: Loading Time | Y26: Plan Output | Z26: Actual Output | AB26: Reject Output | AD26: Time | AE26: Loading Time | AG26: Plan Output | AH26: Actual Output | AJ26: Reject Output
B27: 1 | V27: 6-7 | W27: 60 | AD27: 6-7 | AE27: 60
B28: 2 | V28: 7-8 | W28: 60 | AD28: 7-8 | AE28: 60
B29: 3 | V29: 9-10 | W29: 30 | AD29: 9-10 | AE29: 30
B30: 4 | V30: 11-12 | W30: 60 | AD30: 11-12 | AE30: 60
B31: 5 | V31: 12-1 | W31: 60 | AD31: 12-1 | AE31: 60
B32: 6 | V32: 1-2 | W32: 60 | AD32: 1-2 | AE32: 60
B33: 7 | V33: 2-3 | W33: 45 | AD33: 2-3 | AE33: 45
B34: 8 | V34: 3-4 | W34: 60 | AD34: 3-4 | AE34: 60
B35: 9 | V35: 4-5 | W35: 60 | AD35: 4-5 | AE35: 60
B36: 10 | V36: 5-6 | W36: 60 | AD36: 5-6 | AE36: 60
B37: IV. SYSTEM REPORTING | O37: Prepared By: | V37: Downtime Activities | AD37: Downtime Activities
B38: Date Reported: | I38: Transfer No.
O39: Production Team Leader
B40: Reported By: | I40: Shipment No.
O41: Reviewed By:
B42: Docpro Remarks:
O43: Production Section Head

Sheet R1(2)
B1: DAILY PRODUCTION REPORT | T1: HOURLY BOTTLENECK MANAGEMENT
B3: Item code: | D3: 1APC2016 | G3: PRD No. : | O3: Date: | R3: Line No: | T3: Machine Name: | Y3: Rated Speed: | AB3: Ideal Rate (per min) : | AG3: Schedule Shift:
B4: Item Description : | E4: =IFERROR(INDEX(Data!$B:$B,MATCH('R1(2)'!D3,Data!$A:$A,0)),"") -> ALL PURPOSE EPOXY 1/2 PINT | O4: Batch No. : | T4: Time | U4: UP Time | W4: Plan Output | X4: Actual Output | Z4: Variance Output | AB4: Downtime Activities
B6: I. RAW AND PACKAGING MATERIALS USED | T6: 6-7
B7: No. | C7: ITEM CODE | E7: Description | L7: Batch/Lot No | P7: Consumption | R7: Wastage | S7: Remarks | T7: 7-8
B8: 1 | C8: {=IFERROR(INDEX(Data!$C:$C,SMALL(IF(('R1(2)'!D$3=Data!$A:$A)*(COUNTIF('R1(2)'!$C$7:C7,Data!$C:$C)=0),ROW(Data!$C:$C)-MIN(ROW(Data!$A:$A))+1,""),1)),"")} -> 4CL07000 | E8: =IFERROR(INDEX(Data!$D:$D,MATCH('R1(2)'!$C8,Data!$C:$C,0)),"") -> C.LABEL- 1/2 PINT A | T8: 8-9
B9: 2 | C9: {=IFERROR(INDEX(Data!$C:$C,SMALL(IF(('R1(2)'!D$3=Data!$A:$A)*(COUNTIF('R1(2)'!$C$7:C8,Data!$C:$C)=0),ROW(Data!$C:$C)-MIN(ROW(Data!$A:$A))+1,""),1)),"")} -> 4CL08000 | E9: =IFERROR(INDEX(Data!$D:$D,MATCH('R1(2)'!$C9,Data!$C:$C,0)),"") -> C.LABEL- 1/2 PINT B | T9: 9-10
B10: 3 | C10: {=IFERROR(INDEX(Data!$C:$C,SMALL(IF(('R1(2)'!D$3=Data!$A:$A)*(COUNTIF('R1(2)'!$C$7:C9,Data!$C:$C)=0),ROW(Data!$C:$C)-MIN(ROW(Data!$A:$A))+1,""),1)),"")} -> 4C040000 | E10: =IFERROR(INDEX(Data!$D:$D,MATCH('R1(2)'!$C10,Data!$C:$C,0)),"") -> T.CAN-1/2 PINT | T10: 10-11
B11: 4 | C11: {=IFERROR(INDEX(Data!$C:$C,SMALL(IF(('R1(2)'!D$3=Data!$A:$A)*(COUNTIF('R1(2)'!$C$7:C10,Data!$C:$C)=0),ROW(Data!$C:$C)-MIN(ROW(Data!$A:$A))+1,""),1)),"")} -> P45780084 | E11: =IFERROR(INDEX(Data!$D:$D,MATCH('R1(2)'!$C11,Data!$C:$C,0)),"") -> P.BOX 1/2 PINT (PRINTED) | T11: 11-12
B12: 5 | C12: {=IFERROR(INDEX(Data!$C:$C,SMALL(IF(('R1(2)'!D$3=Data!$A:$A)*(COUNTIF('R1(2)'!$C$7:C11,Data!$C:$C)=0),ROW(Data!$C:$C)-MIN(ROW(Data!$A:$A))+1,""),1)),"")} | E12: =IFERROR(INDEX(Data!$D:$D,MATCH('R1(2)'!$C12,Data!$C:$C,0)),"") | T12: 12-1
B13: 6 | C13: {=IFERROR(INDEX(Data!$C:$C,SMALL(IF(('R1(2)'!D$3=Data!$A:$A)*(COUNTIF('R1(2)'!$C$7:C12,Data!$C:$C)=0),ROW(Data!$C:$C)-MIN(ROW(Data!$A:$A))+1,""),1)),"")} | E13: =IFERROR(INDEX(Data!$D:$D,MATCH('R1(2)'!$C13,Data!$C:$C,0)),"") | T13: 1-2
B14: 7 | C14: {=IFERROR(INDEX(Data!$C:$C,SMALL(IF(('R1(2)'!D$3=Data!$A:$A)*(COUNTIF('R1(2)'!$C$7:C13,Data!$C:$C)=0),ROW(Data!$C:$C)-MIN(ROW(Data!$A:$A))+1,""),1)),"")} | E14: =IFERROR(INDEX(Data!$D:$D,MATCH('R1(2)'!$C14,Data!$C:$C,0)),"") | T14: 2-3
B15: 8 | C15: {=IFERROR(INDEX(Data!$C:$C,SMALL(IF(('R1(2)'!D$3=Data!$A:$A)*(COUNTIF('R1(2)'!$C$7:C14,Data!$C:$C)=0),ROW(Data!$C:$C)-MIN(ROW(Data!$A:$A))+1,""),1)),"")} | E15: =IFERROR(INDEX(Data!$D:$D,MATCH('R1(2)'!$C15,Data!$C:$C,0)),"") | T15: 3-4
B16: 9 | C16: {=IFERROR(INDEX(Data!$C:$C,SMALL(IF(('R1(2)'!D$3=Data!$A:$A)*(COUNTIF('R1(2)'!$C$7:C15,Data!$C:$C)=0),ROW(Data!$C:$C)-MIN(ROW(Data!$A:$A))+1,""),1)),"")} | E16: =IFERROR(INDEX(Data!$D:$D,MATCH('R1(2)'!$C16,Data!$C:$C,0)),"") | T16: 4-5
B17: 10 | C17: {=IFERROR(INDEX(Data!$C:$C,SMALL(IF(('R1(2)'!D$3=Data!$A:$A)*(COUNTIF('R1(2)'!$C$7:C16,Data!$C:$C)=0),ROW(Data!$C:$C)-MIN(ROW(Data!$A:$A))+1,""),1)),"")} | E17: =IFERROR(INDEX(Data!$D:$D,MATCH('R1(2)'!$C17,Data!$C:$C,0)),"") | T17: 5-6
B18: II. QUALITY | Q18: Quality Remarks | T18: Machine Name: | Y18: Rated Speed: | AB18: Ideal Rate (per min) : | AG18: Schedule Shift:
B19: Total Actual Output | F19: Total Accepted Output | K19: Total Rejected Output
T20: Time | U20: UP Time | W20: Plan Output | X20: Actual Output | Z20: Variance Output | AB20: Downtime Activities
B22: III. MANPOWER / PRODUCTIVITY | P22: QR CODE BATCH NO Approved by: / Date | T22: 6-7
B23: No. | C23: Name of Associates | F23: Assignment | H23: Machine Used | T23: 7-8
B24: 1 | T24: 8-9
B25: 2 | T25: 9-10
B26: 3 | T26: 10-11
B27: 4 | T27: 11-12
B28: 5 | T28: 12-1
B29: 6 | T29: 1-2
B30: 7 | T30: 2-3
B31: 8 | T31: 3-4
B32: 9 | T32: 4-5
B33: 10 | T33: 5-6
B34: IV. SYSTEM REPORTING | AC34: V. OEE ENCODING
B35: Date Reported: | G35: Reported By: | AC35: Date Encoded:
B37: Transaction (PTR) No. | P37: Prepared By: | V37: Reviewed By:
AC38: Encoded By:
B39: Transfer (TTF) No. | G39: Shipment (WSS) No.
Q40: Production Team Leader | V40: Production Section Head

Sheet R1(3)
B1: DAILY PRODUCTION REPORT | T1: HOURLY BOTTLENECK MANAGEMENT
B2: Item code: | D2: 1APC2012 | G2: PRD No. : | O2: Date: | R2: Line: | T2: Machine Name: | Y2: Rated Speed: | AB2: Ideal Rate (per min) : | AG2: Schedule Shift:
B3: Item Description : | F3: =IFERROR(INDEX(Data!$B:$B,MATCH('R1(3)'!D2,Data!$A:$A,0)),"") -> ALL PURPOSE EPOXY PINT | O3: Batch No. : | T3: Time | U3: UP Time | W3: Plan Output | X3: Actual Output | Z3: Variance Output | AB3: Downtime Activities
B4: I. RAW AND PACKAGING MATERIALS USED | T4: 6-7
B5: No. | C5: ITEM CODE | F5: Description | L5: Batch/Lot No | P5: Consumption | R5: Wastage | S5: Remarks
B6: 1 | C6: {=IFERROR(INDEX(Data!$C:$C,SMALL(IF(('R1(3)'!D$2=Data!$A:$A)*(COUNTIF('R1(3)'!$C$5:C5,Data!$C:$C)=0),ROW(Data!$C:$C)-MIN(ROW(Data!$A:$A))+1,""),1)),"")} -> 4CL05000 | F6: =IFERROR(INDEX(Data!$D:$D,MATCH('R1(3)'!$C6,Data!$C:$C,0)),"") -> C.LABEL- PINT A | T6: 7-8
B7: 2 | C7: {=IFERROR(INDEX(Data!$C:$C,SMALL(IF(('R1(3)'!D$2=Data!$A:$A)*(COUNTIF('R1(3)'!$C$5:C6,Data!$C:$C)=0),ROW(Data!$C:$C)-MIN(ROW(Data!$A:$A))+1,""),1)),"")} -> 4C030000 | F7: =IFERROR(INDEX(Data!$D:$D,MATCH('R1(3)'!$C7,Data!$C:$C,0)),"") -> T.CAN-PINT | T7: 8-9
B8: 3 | C8: {=IFERROR(INDEX(Data!$C:$C,SMALL(IF(('R1(3)'!D$2=Data!$A:$A)*(COUNTIF('R1(3)'!$C$5:C7,Data!$C:$C)=0),ROW(Data!$C:$C)-MIN(ROW(Data!$A:$A))+1,""),1)),"")} -> P45780081 | F8: =IFERROR(INDEX(Data!$D:$D,MATCH('R1(3)'!$C8,Data!$C:$C,0)),"") -> P.BOX PINT (PRINTED) | T8: 9-10
B9: 4 | C9: {=IFERROR(INDEX(Data!$C:$C,SMALL(IF(('R1(3)'!D$2=Data!$A:$A)*(COUNTIF('R1(3)'!$C$5:C8,Data!$C:$C)=0),ROW(Data!$C:$C)-MIN(ROW(Data!$A:$A))+1,""),1)),"")} -> 4CL06000 | F9: =IFERROR(INDEX(Data!$D:$D,MATCH('R1(3)'!$C9,Data!$C:$C,0)),"") -> C.LABEL- PINT B | T9: 10-11
B10: 5 | C10: {=IFERROR(INDEX(Data!$C:$C,SMALL(IF(('R1(3)'!D$2=Data!$A:$A)*(COUNTIF('R1(3)'!$C$5:C9,Data!$C:$C)=0),ROW(Data!$C:$C)-MIN(ROW(Data!$A:$A))+1,""),1)),"")} | F10: =IFERROR(INDEX(Data!$D:$D,MATCH('R1(3)'!$C10,Data!$C:$C,0)),"") | T10: 11-12
B11: 6 | C11: {=IFERROR(INDEX(Data!$C:$C,SMALL(IF(('R1(3)'!D$2=Data!$A:$A)*(COUNTIF('R1(3)'!$C$5:C10,Data!$C:$C)=0),ROW(Data!$C:$C)-MIN(ROW(Data!$A:$A))+1,""),1)),"")} | F11: =IFERROR(INDEX(Data!$D:$D,MATCH('R1(3)'!$C11,Data!$C:$C,0)),"") | T11: 12-1
B12: 7 | C12: {=IFERROR(INDEX(Data!$C:$C,SMALL(IF(('R1(3)'!D$2=Data!$A:$A)*(COUNTIF('R1(3)'!$C$5:C11,Data!$C:$C)=0),ROW(Data!$C:$C)-MIN(ROW(Data!$A:$A))+1,""),1)),"")} | F12: =IFERROR(INDEX(Data!$D:$D,MATCH('R1(3)'!$C12,Data!$C:$C,0)),"") | T12: 1-2
B13: 8 | C13: {=IFERROR(INDEX(Data!$C:$C,SMALL(IF(('R1(3)'!D$2=Data!$A:$A)*(COUNTIF('R1(3)'!$C$5:C12,Data!$C:$C)=0),ROW(Data!$C:$C)-MIN(ROW(Data!$A:$A))+1,""),1)),"")} | F13: =IFERROR(INDEX(Data!$D:$D,MATCH('R1(3)'!$C13,Data!$C:$C,0)),"") | T13: Machine Name: | Y13: Rated Speed: | AB13: Ideal Rate (per min) : | AG13: Schedule Shift:
B14: 9 | C14: {=IFERROR(INDEX(Data!$C:$C,SMALL(IF(('R1(3)'!D$2=Data!$A:$A)*(COUNTIF('R1(3)'!$C$5:C13,Data!$C:$C)=0),ROW(Data!$C:$C)-MIN(ROW(Data!$A:$A))+1,""),1)),"")} | F14: =IFERROR(INDEX(Data!$D:$D,MATCH('R1(3)'!$C14,Data!$C:$C,0)),"") | T14: Time | U14: UP Time | W14: Plan Output | X14: Actual Output | Z14: Variance Output | AB14: Downtime Activities
B15: 10 | C15: {=IFERROR(INDEX(Data!$C:$C,SMALL(IF(('R1(3)'!D$2=Data!$A:$A)*(COUNTIF('R1(3)'!$C$5:C14,Data!$C:$C)=0),ROW(Data!$C:$C)-MIN(ROW(Data!$A:$A))+1,""),1)),"")} | F15: =IFERROR(INDEX(Data!$D:$D,MATCH('R1(3)'!$C15,Data!$C:$C,0)),"") | T15: 6-7
B16: II. QUALITY | P16: Quality Remarks | T16: 7-8
B17: Total Actual Output | F17: Total Accepted Output | K17: Total Rejected Output
T18: 8-9
T19: 9-10
B20: III. MANPOWER / PRODUCTIVITY | P20: QR CODE BATCH NO Approved by: / Date
B21: No. | C21: Name of Associates | F21: Assignment | H21: Machine Used | T21: 10-11
B22: 1 | T22: 11-12
B23: 2 | T23: 12-1
B24: 3 | T24: 1-2
B25: 4 | T25: Machine Name: | Y25: Rated Speed: | AB25: Ideal Rate (per min) : | AG25: Schedule Shift:
B26: 5 | T26: Time | U26: UP Time | W26: Plan Output | X26: Actual Output | Z26: Variance Output | AB26: Downtime Activities
B27: 6 | T27: 6-7
B28: 7 | T28: 7-8
B29: 8 | T29: 8-9
B30: 9 | T30: 9-10
B31: 10 | T31: 10-11
B32: IV. SYSTEM REPORTING | P32: V. OEE ENCODING | T32: 11-12
B33: Date Reported: | G33: Reported By: | P33: Encoded Date: | T33: 12-1
T34: 1-2
B35: Transaction (PTR) No. | U35: Prepared By: | AB35: Reviewed By:
P36: Encoded By:
B37: Transfer (TTF) No. | G37: Shipment (WSS) No. | U37: Production Team Leader | AB37: Production Section Head

Sheet R2 (2)
B1: LONG PAPER ONLY
B2: DAILY PRODUCTION REPORT | S2: HOURLY BOTTLENECK MANAGEMENT
B4: Item code: | D4: 1WTT572W | H4: PRD No. : | J4: Date: | M4: Batch No. | S4: Machine Name: | W4: Rated Speed: | AA4: Ideal Rate (per min) : | AF4: Schedule Shift:
B5: Item Description : | E5: =IFERROR(INDEX(Data!$B:$B,MATCH('R2 (2)'!D4,Data!$A:$A,0)),"") -> WATER-TITE 100 POUCH | J5: Line No: | S5: Time | T5: UP Time | V5: Plan Output | W5: Actual Output | Y5: Variance Output | AA5: Downtime Activities
B6: I. RAW AND PACKAGING MATERIALS USED | S6: 6-7
B7: No. | F7: Description | J7: Batch/Lot No | N7: Consumption | P7: Wastage | Q7: Remarks
B8: 1 | C8: {=IFERROR(INDEX(Data!$C:$C,SMALL(IF(('R2 (2)'!D$4=Data!$A:$A)*(COUNTIF('R2 (2)'!$C$7:C7,Data!$C:$C)=0),ROW(Data!$C:$C)-MIN(ROW(Data!$A:$A))+1,""),1)),"")} -> 4X290000 | F8: =IFERROR(INDEX(Data!$D:$D,MATCH('R2 (2)'!$C8,Data!$C:$C,0)),"") -> P.BOX-WATERTITE 100 POUCH | S8: 7-8
B9: 2 | C9: {=IFERROR(INDEX(Data!$C:$C,SMALL(IF(('R2 (2)'!D$4=Data!$A:$A)*(COUNTIF('R2 (2)'!$C$7:C8,Data!$C:$C)=0),ROW(Data!$C:$C)-MIN(ROW(Data!$A:$A))+1,""),1)),"")} -> 4PWT1000 | F9: =IFERROR(INDEX(Data!$D:$D,MATCH('R2 (2)'!$C9,Data!$C:$C,0)),"") -> POUCH-WATERTITE 100 200G | S9: 8-9
B10: 3 | C10: {=IFERROR(INDEX(Data!$C:$C,SMALL(IF(('R2 (2)'!D$4=Data!$A:$A)*(COUNTIF('R2 (2)'!$C$7:C9,Data!$C:$C)=0),ROW(Data!$C:$C)-MIN(ROW(Data!$A:$A))+1,""),1)),"")} | F10: =IFERROR(INDEX(Data!$D:$D,MATCH('R2 (2)'!$C10,Data!$C:$C,0)),"") | S10: 9-10
B11: 4 | C11: {=IFERROR(INDEX(Data!$C:$C,SMALL(IF(('R2 (2)'!D$4=Data!$A:$A)*(COUNTIF('R2 (2)'!$C$7:C10,Data!$C:$C)=0),ROW(Data!$C:$C)-MIN(ROW(Data!$A:$A))+1,""),1)),"")} | F11: =IFERROR(INDEX(Data!$D:$D,MATCH('R2 (2)'!$C11,Data!$C:$C,0)),"") | S11: 10-11
B12: 5 | C12: {=IFERROR(INDEX(Data!$C:$C,SMALL(IF(('R2 (2)'!D$4=Data!$A:$A)*(COUNTIF('R2 (2)'!$C$7:C11,Data!$C:$C)=0),ROW(Data!$C:$C)-MIN(ROW(Data!$A:$A))+1,""),1)),"")} | F12: =IFERROR(INDEX(Data!$D:$D,MATCH('R2 (2)'!$C12,Data!$C:$C,0)),"") | S12: 11-12
B13: 6 | C13: {=IFERROR(INDEX(Data!$C:$C,SMALL(IF(('R2 (2)'!D$4=Data!$A:$A)*(COUNTIF('R2 (2)'!$C$7:C12,Data!$C:$C)=0),ROW(Data!$C:$C)-MIN(ROW(Data!$A:$A))+1,""),1)),"")} | F13: =IFERROR(INDEX(Data!$D:$D,MATCH('R2 (2)'!$C13,Data!$C:$C,0)),"") | S13: 12-1
B14: 7 | C14: {=IFERROR(INDEX(Data!$C:$C,SMALL(IF(('R2 (2)'!D$4=Data!$A:$A)*(COUNTIF('R2 (2)'!$C$7:C13,Data!$C:$C)=0),ROW(Data!$C:$C)-MIN(ROW(Data!$A:$A))+1,""),1)),"")} | F14: =IFERROR(INDEX(Data!$D:$D,MATCH('R2 (2)'!$C14,Data!$C:$C,0)),"") | S14: 1-2
B15: 8 | C15: {=IFERROR(INDEX(Data!$C:$C,SMALL(IF(('R2 (2)'!D$4=Data!$A:$A)*(COUNTIF('R2 (2)'!$C$7:C14,Data!$C:$C)=0),ROW(Data!$C:$C)-MIN(ROW(Data!$A:$A))+1,""),1)),"")} | F15: =IFERROR(INDEX(Data!$D:$D,MATCH('R2 (2)'!$C15,Data!$C:$C,0)),"") | S15: 2-3
B16: 9 | C16: {=IFERROR(INDEX(Data!$C:$C,SMALL(IF(('R2 (2)'!D$4=Data!$A:$A)*(COUNTIF('R2 (2)'!$C$7:C15,Data!$C:$C)=0),ROW(Data!$C:$C)-MIN(ROW(Data!$A:$A))+1,""),1)),"")} | F16: =IFERROR(INDEX(Data!$D:$D,MATCH('R2 (2)'!$C16,Data!$C:$C,0)),"") | S16: 3-4
B17: 10 | C17: {=IFERROR(INDEX(Data!$C:$C,SMALL(IF(('R2 (2)'!D$4=Data!$A:$A)*(COUNTIF('R2 (2)'!$C$7:C16,Data!$C:$C)=0),ROW(Data!$C:$C)-MIN(ROW(Data!$A:$A))+1,""),1)),"")} | F17: =IFERROR(INDEX(Data!$D:$D,MATCH('R2 (2)'!$C17,Data!$C:$C,0)),"") | S17: 4-5
B18: II. QUALITY | N18: Quality Remarks | S18: 5-6
B19: Total Actual Output | G19: Total Accepted Output | J19: Total Rejected Output
S20: Machine Name: | W20: Rated Speed: | AA20: Ideal Rate (per min) : | AF20: Schedule Shift:
N21: QR CODE BATCH NO Approved by: / Date | S21: Time | T21: UP Time | V21: Plan Output | W21: Actual Output | Y21: Variance Output | AA21: Downtime Activities
B22: III. MANPOWER / PRODUCTIVITY | S22: 6-7
B23: No. | C23: Name of Associates | H23: Assignment | J23: Machine Used
B24: 1 | S24: 7-8
B25: 2
B26: 3 | S26: 8-9
B27: 4
B28: 5 | S28: 9-10
B29: 6
B30: 7 | S30: 10-11
B31: 8
B32: 9 | S32: 11-12
B33: 10
B34: IV. SYSTEM REPORTING | J34: V. OEE ENCODING | N34: Prepared By: | S34: 12-1
B35: Reported Date: | J35: Encoded Date:
S36: 1-2
B37: Reported By:
O38: Production Team Leader | S38: 2-3
B39: Transaction (PTR) No. :
J40: Encoded By: | N40: Reviewed By: | S40: 3-4
B41: Transfer (TTF) No. :
...

Sheet DPRr1
A1: LONG PAPER ONLY
A2: DAILY PRODUCTION REPORT | R2: HOURLY BOTTLENECK MANAGEMENT
A4: Item code: | D4: 1E2M2033 | G4: PRD No. : | I4: Date: | L4: Batch No. | R4: Machine Name: | V4: Rated Speed: | Z4: Ideal Rate (per min) : | AE4: Schedule Shift:
D5: =IFERROR(INDEX(Data!$B:$B,MATCH(DPRr1!D4,Data!$A:$A,0)),"") -> ELASTOSEAL 1L | I5: Line No: | R5: Time | S5: UP Time | U5: Plan Output | V5: Actual Output | X5: Variance Output | Z5: Downtime Activities
A6: I. RAW AND PACKAGING MATERIALS USED | R6: 6-7
A7: No. | E7: Description | I7: Batch/Lot No | M7: Consumption | O7: Wastage | P7: Remarks
A8: 1 | B8: {=IFERROR(INDEX(Data!$C:$C,SMALL(IF((DPRr1!D$4=Data!$A:$A)*(COUNTIF(DPRr1!$B$7:B7,Data!$C:$C)=0),ROW(Data!$C:$C)-MIN(ROW(Data!$A:$A))+1,""),1)),"")} -> 4CLE1000 | E8: =IFERROR(INDEX(Data!$D:$D,MATCH(DPRr1!$B8,Data!$C:$C,0)),"") -> C.LABEL-ELASTOSEAL 1L(ND) | R8: 7-8
A9: 2 | B9: {=IFERROR(INDEX(Data!$C:$C,SMALL(IF((DPRr1!D$4=Data!$A:$A)*(COUNTIF(DPRr1!$B$7:B8,Data!$C:$C)=0),ROW(Data!$C:$C)-MIN(ROW(Data!$A:$A))+1,""),1)),"")} -> 4XE10000 | E9: =IFERROR(INDEX(Data!$D:$D,MATCH(DPRr1!$B9,Data!$C:$C,0)),"") -> P.BOX-ELASTOSEAL 1L X 12 | R9: 8-9
A10: 3 | B10: {=IFERROR(INDEX(Data!$C:$C,SMALL(IF((DPRr1!D$4=Data!$A:$A)*(COUNTIF(DPRr1!$B$7:B9,Data!$C:$C)=0),ROW(Data!$C:$C)-MIN(ROW(Data!$A:$A))+1,""),1)),"")} -> 4C090000 | E10: =IFERROR(INDEX(Data!$D:$D,MATCH(DPRr1!$B10,Data!$C:$C,0)),"") -> T.CAN-1 LITER | R10: 9-10
A11: 4 | B11: {=IFERROR(INDEX(Data!$C:$C,SMALL(IF((DPRr1!D$4=Data!$A:$A)*(COUNTIF(DPRr1!$B$7:B10,Data!$C:$C)=0),ROW(Data!$C:$C)-MIN(ROW(Data!$A:$A))+1,""),1)),"")} | E11: =IFERROR(INDEX(Data!$D:$D,MATCH(DPRr1!$B11,Data!$C:$C,0)),"") | R11: 10-11
A12: 5 | B12: {=IFERROR(INDEX(Data!$C:$C,SMALL(IF((DPRr1!D$4=Data!$A:$A)*(COUNTIF(DPRr1!$B$7:B11,Data!$C:$C)=0),ROW(Data!$C:$C)-MIN(ROW(Data!$A:$A))+1,""),1)),"")} | E12: =IFERROR(INDEX(Data!$D:$D,MATCH(DPRr1!$B12,Data!$C:$C,0)),"") | R12: 11-12
A13: 6 | B13: {=IFERROR(INDEX(Data!$C:$C,SMALL(IF((DPRr1!D$4=Data!$A:$A)*(COUNTIF(DPRr1!$B$7:B12,Data!$C:$C)=0),ROW(Data!$C:$C)-MIN(ROW(Data!$A:$A))+1,""),1)),"")} | E13: =IFERROR(INDEX(Data!$D:$D,MATCH(DPRr1!$B13,Data!$C:$C,0)),"") | R13: 12-1
A14: 7 | B14: {=IFERROR(INDEX(Data!$C:$C,SMALL(IF((DPRr1!D$4=Data!$A:$A)*(COUNTIF(DPRr1!$B$7:B13,Data!$C:$C)=0),ROW(Data!$C:$C)-MIN(ROW(Data!$A:$A))+1,""),1)),"")} | E14: =IFERROR(INDEX(Data!$D:$D,MATCH(DPRr1!$B14,Data!$C:$C,0)),"") | R14: 1-2
A15: 8 | B15: {=IFERROR(INDEX(Data!$C:$C,SMALL(IF((DPRr1!D$4=Data!$A:$A)*(COUNTIF(DPRr1!$B$7:B14,Data!$C:$C)=0),ROW(Data!$C:$C)-MIN(ROW(Data!$A:$A))+1,""),1)),"")} | E15: =IFERROR(INDEX(Data!$D:$D,MATCH(DPRr1!$B15,Data!$C:$C,0)),"") | R15: 2-3
A16: 9 | B16: {=IFERROR(INDEX(Data!$C:$C,SMALL(IF((DPRr1!D$4=Data!$A:$A)*(COUNTIF(DPRr1!$B$7:B15,Data!$C:$C)=0),ROW(Data!$C:$C)-MIN(ROW(Data!$A:$A))+1,""),1)),"")} | E16: =IFERROR(INDEX(Data!$D:$D,MATCH(DPRr1!$B16,Data!$C:$C,0)),"") | R16: 3-4
A17: 10 | B17: {=IFERROR(INDEX(Data!$C:$C,SMALL(IF((DPRr1!D$4=Data!$A:$A)*(COUNTIF(DPRr1!$B$7:B16,Data!$C:$C)=0),ROW(Data!$C:$C)-MIN(ROW(Data!$A:$A))+1,""),1)),"")} | E17: =IFERROR(INDEX(Data!$D:$D,MATCH(DPRr1!$B17,Data!$C:$C,0)),"") | R17: 4-5
A18: II. QUALITY | M18: Quality Remarks | R18: 5-6
A19: Total Actual Output | F19: Total Accepted Output | I19: Total Rejected Output
R20: Machine Name: | V20: Rated Speed: | Z20: Ideal Rate (per min) : | AE20: Schedule Shift:
M21: QR CODE BATCH NO Approved by: / Date | R21: Time | S21: UP Time | U21: Plan Output | V21: Actual Output | X21: Variance Output | Z21: Downtime Activities
A22: III. MANPOWER / PRODUCTIVITY | R22: 6-7
A23: No. | B23: Name of Associates | G23: Assignment | I23: Machine Used
A24: 1 | R24: 7-8
A25: 2
A26: 3 | R26: 8-9
A27: 4
A28: 5 | R28: 9-10
A29: 6
A30: 7 | R30: 10-11
A31: 8
A32: 9 | R32: 11-12
A33: 10
A34: IV. SYSTEM REPORTING | I34: V. OEE ENCODING | M34: Prepared By: | R34: 12-1
A35: Reported Date: | I35: Encoded Date:
R36: 1-2
A37: Reported By:
N38: Production Team Leader | R38: 2-3
A39: Transaction (PTR) No. :
I40: Encoded By: | M40: Reviewed By: | R40: 3-4
A41: Transfer (TTF) No. :
...

Sheet LINE 4 OPCR
B1: OPERATOR PROCESS CONTROL RECORD
B2: LINE 4 - ELASTO FILLING
B3: RPOA NO.: | K3: ITEM CODE: | Y3: PRODUCTION DATE:
B4: FILLING LINE: | K4: ITEM DESCRIPTION: | Y4: SHIFT:
B5: I. MATERIALS CONTROL
B8: NO. | C8: CONTROL PARAMETER | K8: BATCH NUMBER
K10: 6:00-7:00 | M10: 7:00-8:00 | O10: 8:00-9:00 | Q10: 9:00-10:00 | S10: 10:00-11:00 | U10: 11:00-12:00 | W10: 12:00-1:00 | Y10: 1:00-2:00 | AA10: 2:00-3:00 | AC10: 3:00-4:00 | AE10: 4:00-5:00 | AG10: 5:00-6:00
K11: Good | L11: No-good (QTY) | M11: Good | N11: No-good (QTY) | O11: Good | P11: No-good (QTY) | Q11: Good | R11: No-good (QTY) | S11: Good | T11: No-good (QTY) | U11: Good | V11: No-good (QTY) | W11: Good | X11: No-good (QTY) | Y11: Good | Z11: No-good (QTY) | AA11: Good | AB11: No-good (QTY) | AC11: Good | AD11: No-good (QTY) | AE11: Good | AF11: No-good (QTY) | AG11: Good | AH11: No-good (QTY)
B12: 1 | C12: BULKMIX - Passed to the standard specifications.
B13: 2 | C13: CONTAINER / POUCH - Maayos, Malinis, Walang punit o sira
B14: 3 | C14: LABEL - Tama ang label, tama ang batch code, lahat ng cans ay may label, walang loose o detached label.
B15: 4 | C15: CAN - Walang rust o kalawang, malinis, walang leak o butas, walang major dent
B16: 5 | C16: BOX - Walang butas o punit at may nakadikit na QR code.
B17: 6 | C17: QR CODE - Tama ang batch code at FG Description, Readable o nababasa at kumpleto ang digits o characters
B18: REMARKS
B19: DONE BY(Ilagay ang pangalan at pirma):
B20: lI. IN-PROCESS QUALITY CONTROL CHECKLIST
B21: NO. | C21: CONTROL PARAMETER | K21: BATCH NUMBER
K23: Good | L23: No-good | M23: Good | N23: No-good | O23: Good | P23: No-good | Q23: Good | R23: No-good | S23: Good | T23: No-good | U23: Good | V23: No-good | W23: Good | X23: No-good | Y23: Good | Z23: No-good | AA23: Good | AB23: No-good | AC23: Good | AD23: No-good | AE23: Good | AF23: No-good | AG23: Good | AH23: No-good
B24: 1 | C24: WEIGHT MATRIX - Tama at controlled ang weight matrix na naka-post sa linya ayon sa schedule.
B25: 2 | C25: WEIGHING SCALE - Mayroong weighing scale sa linya.
B26: REMARKS
B27: DONE BY(Ilagay ang pangalan at pirma):
B28: CRITICAL PROCESS PARAMETER | K28: ACTUAL HOURLY MONITORING
B29: 3 | C29: WEIGHT VARIATION (Pneumatic Machine Setting) | K29: 6:00-7:00 | M29: 7:00-8:00 | O29: 8:00-9:00 | Q29: 9:00-10:00 | S29: 10:00-11:00 | U29: 11:00-12:00 | W29: 12:00-1:00 | Y29: 1:00-2:00 | AA29: 2:00-3:00 | AC29: 3:00-4:00 | AE29: 4:00-5:00 | AG29: 5:00-6:00
C30: MIN | F30: SET | I30: MAX
B32: REMARKS
C33: Recorded by: (Ilagay ang initials at pirma):
B34: 4 | C34: SEALING, Walang Leak at sira | K34: Good | L34: No-good | M34: Good | N34: No-good | O34: Good | P34: No-good | Q34: Good | R34: No-good | S34: Good | T34: No-good | U34: Good | V34: No-good | W34: Good | X34: No-good | Y34: Good | Z34: No-good | AA34: Good | AB34: No-good | AC34: Good | AD34: No-good | AE34: Good | AF34: No-good | AG34: Good | AH34: No-good
D35: Induction Sealer Setting Temp: _____________ Dwelling time: _____________ Plunger Manual
B36: REMARKS
B37: Inspected by: (Ilagay ang initials at pirma):
B38: IV. MANPOWER / PRODUCTIVITY
B39: MANPOWER LIST | I39: ASSIGNMENT | M39: MACHINE USED | S39: NAV ENCODER
B40: 1 | S40: ENCODED BY: | W40: PREPARED BY:
B41: 2 | S41: DATE FINISHED:
B42: 3 | S42: TS NO. : | W42: REVIEWED BY:
B43: 4
B45: lII. FINISHED GOODS QUALITY CONTROL CHECKLIST
B46: NO. | C46: CONTROL PARAMETER | K46: BATCH NUMBER
...

Sheet LINE 4 OPCR (2)
B1: OPERATOR PROCESS CONTROL RECORD
B2: LINE 4 - ELASTO FILLING
B3: RPOA NO.: | K3: ITEM CODE: | Y3: PRODUCTION DATE:
B4: FILLING LINE: | K4: ITEM DESCRIPTION: | Y4: SHIFT:
B5: I. MATERIALS CONTROL
B8: NO. | C8: CONTROL PARAMETER | K8: BATCH NUMBER
K10: 6:00-7:00 | M10: 7:00-8:00 | O10: 8:00-9:00 | Q10: 9:00-10:00 | S10: 10:00-11:00 | U10: 11:00-12:00 | W10: 12:00-1:00 | Y10: 1:00-2:00 | AA10: 2:00-3:00 | AC10: 3:00-4:00 | AE10: 4:00-5:00 | AG10: 5:00-6:00
K11: Good | L11: No-good (QTY) | M11: Good | N11: No-good (QTY) | O11: Good | P11: No-good (QTY) | Q11: Good | R11: No-good (QTY) | S11: Good | T11: No-good (QTY) | U11: Good | V11: No-good (QTY) | W11: Good | X11: No-good (QTY) | Y11: Good | Z11: No-good (QTY) | AA11: Good | AB11: No-good (QTY) | AC11: Good | AD11: No-good (QTY) | AE11: Good | AF11: No-good (QTY) | AG11: Good | AH11: No-good (QTY)
B12: 1 | C12: BULKMIX - Passed to the standard specifications.
B13: 2 | C13: CONTAINER / POUCH - Maayos, Malinis, Walang punit o sira
B14: 3 | C14: LABEL - Tama ang label, tama ang batch code, lahat ng cans ay may label, walang loose o detached label.
B15: 4 | C15: CAN - Walang rust o kalawang, malinis, walang leak o butas, walang major dent
B16: 5 | C16: BOX - Walang butas o punit at may nakadikit na QR code.
B17: 6 | C17: QR CODE - Tama ang batch code at FG Description, Readable o nababasa at kumpleto ang digits o characters
B18: REMARKS
B19: DONE BY(Ilagay ang pangalan at pirma):
B20: lI. IN-PROCESS QUALITY CONTROL CHECKLIST
B21: NO. | C21: CONTROL PARAMETER | K21: BATCH NUMBER
K23: Good | L23: No-good | M23: Good | N23: No-good | O23: Good | P23: No-good | Q23: Good | R23: No-good | S23: Good | T23: No-good | U23: Good | V23: No-good | W23: Good | X23: No-good | Y23: Good | Z23: No-good | AA23: Good | AB23: No-good | AC23: Good | AD23: No-good | AE23: Good | AF23: No-good | AG23: Good | AH23: No-good
B24: 1 | C24: WEIGHT MATRIX - Tama at controlled ang weight matrix na naka-post sa linya ayon sa schedule.
B25: 2 | C25: WEIGHING SCALE - Mayroong weighing scale sa linya.
B26: REMARKS
B27: DONE BY(Ilagay ang pangalan at pirma):
B28: CRITICAL PROCESS PARAMETER | K28: ACTUAL HOURLY MONITORING
B29: 3 | C29: WEIGHT VARIATION (Pneumatic Machine Setting) | K29: 6:00-7:00 | M29: 7:00-8:00 | O29: 8:00-9:00 | Q29: 9:00-10:00 | S29: 10:00-11:00 | U29: 11:00-12:00 | W29: 12:00-1:00 | Y29: 1:00-2:00 | AA29: 2:00-3:00 | AC29: 3:00-4:00 | AE29: 4:00-5:00 | AG29: 5:00-6:00
C30: MIN | F30: SET | I30: MAX
B32: REMARKS
C33: Recorded by: (Ilagay ang initials at pirma):
B34: 4 | C34: SEALING, Walang Leak at sira | K34: Good | L34: No-good | M34: Good | N34: No-good | O34: Good | P34: No-good | Q34: Good | R34: No-good | S34: Good | T34: No-good | U34: Good | V34: No-good | W34: Good | X34: No-good | Y34: Good | Z34: No-good | AA34: Good | AB34: No-good | AC34: Good | AD34: No-good | AE34: Good | AF34: No-good | AG34: Good | AH34: No-good
D35: Induction Sealer Setting Temp: _____________ Dwelling time: _____________ Plunger Manual
B36: REMARKS
B37: Inspected by: (Ilagay ang initials at pirma):
B38: IV. MANPOWER / PRODUCTIVITY
B39: MANPOWER LIST | I39: ASSIGNMENT | M39: MACHINE USED | S39: NAV ENCODER
B40: 1 | S40: ENCODED BY: | W40: PREPARED BY:
B41: 2 | S41: DATE FINISHED:
B42: 3 | S42: TS NO. : | W42: REVIEWED BY:
B43: 4
B45: lII. FINISHED GOODS QUALITY CONTROL CHECKLIST
B46: NO. | C46: CONTROL PARAMETER | K46: BATCH NUMBER
...

Sheet LINE 3
A1: LONG PAPER ONLY
A2: DAILY PRODUCTION REPORT | R2: HOURLY BOTTLENECK MANAGEMENT
A4: Item code: | C4: 1M2C2009 | G4: PRD No. : | I4: Date: | L4: Batch No. | R4: Machine Name: | V4: Rated Speed: | Z4: Ideal Rate (per min) : | AE4: Schedule Shift:
A5: Item Description : | D5: =IFERROR(INDEX(Data!$B:$B,MATCH('LINE 3'!C4,Data!$A:$A,0)),"") -> MARINE EPOXY GALLON | I5: Line No: | R5: Time | S5: UP Time | U5: Plan Output | V5: Actual Output | X5: Variance Output | Z5: Downtime Activities
A6: I. RAW AND PACKAGING MATERIALS USED | R6: 6-7
A7: No. | E7: Description | I7: Batch/Lot No | M7: Consumption | O7: Wastage | P7: Remarks
A8: 1 | B8: {=IFERROR(INDEX(Data!$C:$C,SMALL(IF(('LINE 3'!C$4=Data!$A:$A)*(COUNTIF('LINE 3'!$B$7:B7,Data!$C:$C)=0),ROW(Data!$C:$C)-MIN(ROW(Data!$A:$A))+1,""),1)),"")} -> 4E640000 | E8: =IFERROR(INDEX(Data!$D:$D,MATCH('LINE 3'!$B8,Data!$C:$C,0)),"") -> C.LABEL-MARINE GALLON A | R8: 7-8
A9: 2 | B9: {=IFERROR(INDEX(Data!$C:$C,SMALL(IF(('LINE 3'!C$4=Data!$A:$A)*(COUNTIF('LINE 3'!$B$7:B8,Data!$C:$C)=0),ROW(Data!$C:$C)-MIN(ROW(Data!$A:$A))+1,""),1)),"")} -> 4E650000 | E9: =IFERROR(INDEX(Data!$D:$D,MATCH('LINE 3'!$B9,Data!$C:$C,0)),"") -> C.LABEL-MARINE GALLON B | R9: 8-9
A10: 3 | B10: {=IFERROR(INDEX(Data!$C:$C,SMALL(IF(('LINE 3'!C$4=Data!$A:$A)*(COUNTIF('LINE 3'!$B$7:B9,Data!$C:$C)=0),ROW(Data!$C:$C)-MIN(ROW(Data!$A:$A))+1,""),1)),"")} -> 4C010000 | E10: =IFERROR(INDEX(Data!$D:$D,MATCH('LINE 3'!$B10,Data!$C:$C,0)),"") -> T.CAN-GALLON W/ HANDLE | R10: 9-10
A11: 4 | B11: {=IFERROR(INDEX(Data!$C:$C,SMALL(IF(('LINE 3'!C$4=Data!$A:$A)*(COUNTIF('LINE 3'!$B$7:B10,Data!$C:$C)=0),ROW(Data!$C:$C)-MIN(ROW(Data!$A:$A))+1,""),1)),"")} -> 4X01A000 | E11: =IFERROR(INDEX(Data!$D:$D,MATCH('LINE 3'!$B11,Data!$C:$C,0)),"") -> P.BOX-GALLON X 2 | R11: 10-11
A12: 5 | B12: {=IFERROR(INDEX(Data!$C:$C,SMALL(IF(('LINE 3'!C$4=Data!$A:$A)*(COUNTIF('LINE 3'!$B$7:B11,Data!$C:$C)=0),ROW(Data!$C:$C)-MIN(ROW(Data!$A:$A))+1,""),1)),"")} -> PM000138 | E12: =IFERROR(INDEX(Data!$D:$D,MATCH('LINE 3'!$B12,Data!$C:$C,0)),"") -> P.LABEL-1M2C2009 MARINE EPOXY | R12: 11-12
A13: 6 | B13: {=IFERROR(INDEX(Data!$C:$C,SMALL(IF(('LINE 3'!C$4=Data!$A:$A)*(COUNTIF('LINE 3'!$B$7:B12,Data!$C:$C)=0),ROW(Data!$C:$C)-MIN(ROW(Data!$A:$A))+1,""),1)),"")} | E13: =IFERROR(INDEX(Data!$D:$D,MATCH('LINE 3'!$B13,Data!$C:$C,0)),"") | R13: 12-1
A14: 7 | B14: {=IFERROR(INDEX(Data!$C:$C,SMALL(IF(('LINE 3'!C$4=Data!$A:$A)*(COUNTIF('LINE 3'!$B$7:B13,Data!$C:$C)=0),ROW(Data!$C:$C)-MIN(ROW(Data!$A:$A))+1,""),1)),"")} | E14: =IFERROR(INDEX(Data!$D:$D,MATCH('LINE 3'!$B14,Data!$C:$C,0)),"") | R14: 1-2
A15: 8 | B15: {=IFERROR(INDEX(Data!$C:$C,SMALL(IF(('LINE 3'!C$4=Data!$A:$A)*(COUNTIF('LINE 3'!$B$7:B14,Data!$C:$C)=0),ROW(Data!$C:$C)-MIN(ROW(Data!$A:$A))+1,""),1)),"")} | E15: =IFERROR(INDEX(Data!$D:$D,MATCH('LINE 3'!$B15,Data!$C:$C,0)),"") | R15: 2-3
A16: 9 | B16: {=IFERROR(INDEX(Data!$C:$C,SMALL(IF(('LINE 3'!C$4=Data!$A:$A)*(COUNTIF('LINE 3'!$B$7:B15,Data!$C:$C)=0),ROW(Data!$C:$C)-MIN(ROW(Data!$A:$A))+1,""),1)),"")} | E16: =IFERROR(INDEX(Data!$D:$D,MATCH('LINE 3'!$B16,Data!$C:$C,0)),"") | R16: 3-4
A17: 10 | B17: {=IFERROR(INDEX(Data!$C:$C,SMALL(IF(('LINE 3'!C$4=Data!$A:$A)*(COUNTIF('LINE 3'!$B$7:B16,Data!$C:$C)=0),ROW(Data!$C:$C)-MIN(ROW(Data!$A:$A))+1,""),1)),"")} | E17: =IFERROR(INDEX(Data!$D:$D,MATCH('LINE 3'!$B17,Data!$C:$C,0)),"") | R17: 4-5
A18: II. QUALITY | M18: Quality Remarks | R18: 5-6
A19: Total Actual Output | F19: Total Accepted Output | I19: Total Rejected Output
R20: Machine Name: | V20: Rated Speed: | Z20: Ideal Rate (per min) : | AE20: Schedule Shift:
M21: QR CODE BATCH NO Approved by: / Date | R21: Time | S21: UP Time | U21: Plan Output | V21: Actual Output | X21: Variance Output | Z21: Downtime Activities
A22: III. MANPOWER / PRODUCTIVITY | R22: 6-7
A23: No. | B23: Name of Associates | G23: Assignment | I23: Machine Used
A24: 1 | R24: 7-8
A25: 2
A26: 3 | R26: 8-9
A27: 4
A28: 5 | R28: 9-10
A29: 6
A30: 7 | R30: 10-11
A31: 8
A32: 9 | R32: 11-12
A33: 10
A34: IV. SYSTEM REPORTING | I34: V. OEE ENCODING | M34: Prepared By: | R34: 12-1
A35: Reported Date: | I35: Encoded Date:
R36: 1-2
A37: Reported By:
N38: Production Team Leader | R38: 2-3
A39: Transaction (PTR) No. :
I40: Encoded By: | M40: Reviewed By: | R40: 3-4
A41: Transfer (TTF) No. :
...

Sheet DPRr1 (2)
A1: HOURLY BOTTLENECK MANAGEMENT
A2: Date: | F2: Line: | J2: Machine Name: | O2: Shift Schedule:
A4: Time | B4: UP Time | D4: Plan Output | E4: Actual Output | G4: Variance Output | I4: Product Description | J4: Ideal Rate (per min) | K4: Activities
A5: 6-7
A6: 7-8
A7: 8-9
A8: 9-10
A9: 10-11
A10: 11-12
A11: 12-1
A12: 1-2
A13: 2-3
A14: 3-4
A15: 4-5
A16: 5-6

Sheet Sheet3
D2: FALSE | E2: 1st Shift (6-2pm)
D3: FALSE | E3: 2nd Shift (2-10pm)
D4: FALSE | E4: 3rd Shift (10-6am)
D5: FALSE | E5: Dayshift (6am-6pm)
D6: FALSE | E6: Nightshift (6pm-6am)

Sheet FORM
A1: HOURLY BOTTLENECK MANAGEMENT
A2: Date: | F2: Line | J2: Machine Name: | O2: Shift Schedule
A4: Time | B4: UP Time | D4: Plan Output | E4: Actual Output | G4: Reject Qty | I4: Product Description | J4: Ideal Rate (per min) | K4: Activities
A5: 6-7
A6: 7-8
A7: 8-9
A8: 9-10
A9: 10-11
A10: 11-12
A11: 12-1
A12: 1-2
A13: 2-3
A14: 3-4
A15: 4-5
A16: 5-6
D18: TOTAL GOOD OUTPUT: | J18: PREPARED BY:
D20: TOTAL REJECT: | J20: REVIEWED BY:
A22: Legend:
A39: NOTE/ REMARKS:

Sheet HBM2
A1: HOURLY BOTTLENECK MANAGEMENT
A2: Date: | F2: Line: | J2: Machine Name: | O2: Shift Schedule:
A4: Time | B4: UP Time | D4: Plan Output | E4: Actual Output | G4: Reject Qty | I4: Product Description | J4: Ideal Rate (per min) | K4: Activities
A5: 6-7
A6: 7-8
A7: 8-9
A8: 9-10
A9: 10-11
A10: 11-12
A11: 12-1
A12: 1-2
A13: 2-3
A14: 3-4
A15: 4-5
A16: 5-6
D18: TOTAL OUTPUT: | J18: PREPARED BY:
D20: TOTAL REJECT: | J20: REVIEWED BY:
A21: Legend:
A39: NOTE/ REMARKS:

Sheet Sheet7
S6: 1. Correct warehouse transfer & location
S8: 2. toback to wrong warehouse & location
S9: due to wrong # declaration in report
S10: PROD It should be RPM
S12: 3. kaya nun binalik sa FGL ang stocks
S13: galing na sa PROD whse.
S16: wrong batch # reason bat nag TOBACK
S17: batch number should be 8 digits
S18: declared batch # is only 7 digits

Sheet LEGEND
A1: CODE | B1: PLANNED DOWNTIME | D1: CODE | E1: BREAKDOWN & FAILURES | G1: CODE | H1: UNPLANNED DOWNTIME | J1: CODE | K1: UNPLANNED DOWNTIME
A2: A1 | B2: 5S, Sanitation | D2: B1 | E2: Gear Box Problem | G2: C1 | H2: Lack of Manpower | J2: F1 | K2: Early Stop
A3: A2 | B3: Break Time | D3: B2 | E3: Bearing Problem | G3: C2 | H3: Technical Downtime (QA & RND) - HOLD | J3: F2 | K3: Overbreak
A4: A3 | B4: CLAIR | D4: B3 | E4: Compress Air Low Pressure | G4: C3 | H4: Manpower Transfer | J4: F3 | K4: Idle - Others (If the downtime is not provided in the list)
A5: A4 | B5: Changeover, Set up/Start up, Change Kettle | D5: B4 | E5: Heater Problem | G5: C4 | H5: No OT (Go home)
A6: A5 | B6: PM (Preventive Maintenance) | D6: B5 | E6: Rampost Aluminum Piston Seal Problem | G6: C5 | H6: UDT-Meeting
A7: A6 | B7: Flag Ceremony | D7: B6 | E7: Sensor Problem
A8: A7 | B8: General Assembly | D8: B7 | E8: Weight Problem (Leak)
A9: A8 | B9: Performance Dialogue | D9: B8 | E9: Weight Problem (Hoper Pressure -OPCR Check) | G9: CODE | H9: IDLING AND MINOR STOPPAGE | J9: CODE | K9: SET-UP AND ADJUSTMENTS
A10: A9 | B10: Trial Run | D10: B9 | E10: Pressure Gauge Problem | G10: D1 | H10: Materials Supply (Late issuance RMPM) | J10: G1 | K10: Excess Set Up (Adjustment)
A11: A10 | B11: Training, Meetings | D11: B10 | E11: Deffective - Foot Swith Problem | G11: D2 | H11: Materials Supply (No available/OOS RMPM) | J11: G2 | K11: Excess Breaktime
A12: A11 | B12: Company Activities | D12: B11 | E12: Deffective -Air Motor Problem | G12: D3 | H12: No Bulkmix / No Kettle | J12: G3 | K12: Excess Changeover
A13: A12 | B13: Emergency Drills | D13: B12 | E13: Deffective -Lower Extrusion Pump Problem | G13: D4 | H13: Sorting/Reworking
A14: A13 | B14: No Production Plan | D14: B13 | E14: Deffective Slot Chain-Conveyor Problem
A15: A14 | B15: No Head Count Allocation | D15: B14 | E15: Deffective-Can Closer | G15: CODE
D16: B15 | E16: Crimping Problem | G16: E1 | H16: Power Shortage
D17: B16 | E17: Follower Plate Problem (Rampest) | G17: E2 | H17: Safety Stop
D18: B17 | E18: Follower Plate Problem(Deformed) | G18: E3 | H18: Force Majeure (Eartquake, Fire, Typhoon, etc.)
G32: F1 | H32: Early Stop
G33: F2 | H33: Overbreak
G34: F3 | H34: Idle - Others (If the downtime is not provided in the list)

Sheet LEGEND (2)
A1: CODE | B1: PLANNED DOWNTIME | D1: CODE | E1: BREAKDOWN & FAILURES | G1: CODE | H1: UNPLANNED DOWNTIME | J1: CODE | K1: IDLE AND MINOR STOPPAGE
A2: A1 | B2: 5S, Sanitation | D2: B1 | E2: Gear Box Problem | G2: C1 | H2: UDT-Force Majeure | J2: D1 | K2: Delay Issuance Materials Supply (PM)
A3: A2 | B3: Break Time | D3: B2 | E3: Bearing Problem | G3: C2 | H3: UDT-Grid Power Failure | J3: D2 | K3: Delay Issuance Materials Supply (RM)
A4: A3 | B4: CLAIR | D4: B3 | E4: Compress Air Low Pressure | G4: C3 | H4: UDT-Supply Chain Discuption | J4: D3 | K4: Out Stocks (RMPM)
A5: A4 | B5: Changeover, Set up/Start up, Change Kettle | D5: B4 | E5: Heater Problem | G5: C4 | H5: UDT-Gov't/Regulatory Issues | J5: D4 | K5: Sorting/Reworking
A6: A5 | B6: PM (Preventive Maintenance) | D6: B5 | E6: Rampost Aluminum Piston Seal Problem | G6: C5 | H6: UDT-External Insfastructure failures | J6: D5 | K6: Quality Problem
A7: A6 | B7: Flag Ceremony | D7: B6 | E7: Sensor Problem | G7: C6 | H7: UDT-Labor related external issues | J7: D6 | K7: Absent Manpower
A8: A7 | B8: General Assembly | D8: B7 | E8: Weight Problem (Leak) | G8: C7 | H8: UDT-Late Shuttle Service | J8: D7 | K8: Not Rendered Overtime (OT)
A9: A8 | B9: Performance Dialogue | D9: B8 | E9: Weight Problem (Hopper Pressure) | J9: D8 | K9: Unplanned Meeting
A10: A9 | B10: Trial Run | D10: B9 | E10: Pressure Gauge Problem | J10: D9 | K10: No available Bulkmix/Kettle
A11: A10 | B11: Training, Meetings | D11: B10 | E11: Defective - Foot Swith Problem | G11: CODE | H11: SET-UP AND ADJUSTMENTS | J11: D10 | K11: Waiting for Bulkmix Approval
A12: A11 | B12: Company Activities | D12: B11 | E12: Defective -Air Motor Problem | G12: E1 | H12: Excess Set Up (Adjustment) | J12: D11 | K12: Over Breaktime
A13: A12 | B13: Emergency Drills | D13: B12 | E13: Defective -Lower Extrusion Pump Problem | G13: E2 | H13: Excess Changeover | J13: D12 | K13: Equipment Mishandling
A14: A13 | B14: No Production Plan | D14: B13 | E14: Defective Slot Chain-Conveyor Problem | J14: D13 | K14: Waiting for Forklift
A15: A14 | B15: No Head Count Allocation | D15: B14 | E15: Defective-Can Closer | J15: D14 | K15: Early Quitting
D16: B15 | E16: Crimping Problem | J16: D15 | K16: Idle - Others (If the downtime is not provided in the list)
D17: B16 | E17: Follower Plate Problem (Rampant)
D18: B17 | E18: Follower Plate Problem(Deformed)
D19: B18 | E19: Orientator Promblem
D20: B19 | E20: Loader Promblem

Sheet REVISED LINE 3 OPCR
B1: OPERATOR PROCESS CONTROL RECORD
B2: TUBE FILLING LINE
B3: RPOA NO.: | K3: ITEM CODE: | Y3: PRODUCTION DATE:
B4: FILLING LINE: | K4: ITEM DESCRIPTION: | Y4: SHIFT:
B5: I. MATERIALS CONTROL
B8: NO. | C8: CONTROL PARAMETER | K8: BATCH NUMBER
K10: 6:00-7:00 | M10: 7:00-8:00 | O10: 8:00-9:00 | Q10: 9:00-10:00 | S10: 10:00-11:00 | U10: 11:00-12:00 | W10: 12:00-1:00 | Y10: 1:00-2:00 | AA10: 2:00-3:00 | AC10: 3:00-4:00 | AE10: 4:00-5:00 | AG10: 5:00-6:00
K11: Good | L11: No-good (QTY) | M11: Good | N11: No-good (QTY) | O11: Good | P11: No-good (QTY) | Q11: Good | R11: No-good (QTY) | S11: Good | T11: No-good (QTY) | U11: Good | V11: No-good (QTY) | W11: Good | X11: No-good (QTY) | Y11: Good | Z11: No-good (QTY) | AA11: Good | AB11: No-good (QTY) | AC11: Good | AD11: No-good (QTY) | AE11: Good | AF11: No-good (QTY) | AG11: Good | AH11: No-good (QTY)
B12: 1 | C12: BULKMIX - Passed to the standard specifications.
B13: 2 | C13: CONTAINER / TUBES - Maayos, Malinis, Walang punit o sira
B14: 5 | C14: BOX - Walang butas o punit at may nakadikit na QR code.
B15: 6 | C15: QR CODE - Tama ang batch code at FG Description, Readable o nababasa at kumpleto ang digits o characters
B16: REMARKS
B17: Inspected by (Ilagay ang pangalan at pirma):
B18: lI. IN-PROCESS QUALITY CONTROL CHECKLIST
B19: NO. | C19: CONTROL PARAMETER | K19: BATCH NUMBER
K21: Good | L21: No-good | M21: Good | N21: No-good | O21: Good | P21: No-good | Q21: Good | R21: No-good | S21: Good | T21: No-good | U21: Good | V21: No-good | W21: Good | X21: No-good | Y21: Good | Z21: No-good | AA21: Good | AB21: No-good | AC21: Good | AD21: No-good | AE21: Good | AF21: No-good | AG21: Good | AH21: No-good
B22: 1 | C22: WEIGHT MATRIX - Tama at controlled ang weight matrix na naka-post sa linya ayon sa schedule.
B23: 2 | C23: WEIGHING SCALE - Mayroong weighing scale sa linya.
B24: Inspected by (Ilagay ang pangalan at pirma):
B25: CRITICAL PROCESS PARAMETER | K25: ACTUAL HOURLY MONITORING
B26: 3 | C26: WEIGHT VARIATION (Pneumatic Machine Setting) | K26: 6:00-7:00 | M26: 7:00-8:00 | O26: 8:00-9:00 | Q26: 9:00-10:00 | S26: 10:00-11:00 | U26: 11:00-12:00 | W26: 12:00-1:00 | Y26: 1:00-2:00 | AA26: 2:00-3:00 | AC26: 3:00-4:00 | AE26: 4:00-5:00 | AG26: 5:00-6:00
C28: REMARKS:
C29: Recorded by: (Ilagay ang initials at pirma):
B30: 4 | C30: SEALING, Walang Leak at sira | K30: BATCH NUMBER
K32: Good | L32: No-good | M32: Good | N32: No-good | O32: Good | P32: No-good | Q32: Good | R32: No-good | S32: Good | T32: No-good | U32: Good | V32: No-good | W32: Good | X32: No-good | Y32: Good | Z32: No-good | AA32: Good | AB32: No-good | AC32: Good | AD32: No-good | AE32: Good | AF32: No-good | AG32: Good | AH32: No-good
D33: CRIMPING Settings: ___________________________ Batch Coding
C34: REMARKS:
B35: Inspected by: (Ilagay ang initials at pirma):
B36: IV. MANPOWER / PRODUCTIVITY
B37: MANPOWER LIST | I37: ASSIGNMENT | M37: MACHINE USED | S37: NAV ENCODER
B38: 1 | S38: ENCODED BY: | W38: PREPARED BY:
B39: 2 | S39: DATE FINISHED:
B40: 3 | S40: TS NO. : | W40: REVIEWED BY:
B41: 4
B43: lII. FINISHED GOODS QUALITY CONTROL CHECKLIST
B44: NO. | C44: CONTROL PARAMETER | K44: BATCH NUMBER
K46: Good | L46: No-good | M46: Good | N46: No-good | O46: Good | P46: No-good | Q46: Good | R46: No-good | S46: Good | T46: No-good | U46: Good | V46: No-good | W46: Good | X46: No-good | Y46: Good | Z46: No-good | AA46: Good | AB46: No-good | AC46: Good | AD46: No-good | AE46: Good | AF46: No-good | AG46: Good | AH46: No-good
B47: 1 | C47: Kumpleto at tama ang laman ng box.
B48: 2 | C48: Tama ang sealing ng box (using PAI Tape).
...

Sheet Sheet1
A1: OPERATOR PROCESS CONTROL RECORD LABELLING
A5: PRODUCT DESCRIPTION | H5: ITEM CODE | N5: PRODUCTION DATE | R5: TIME
A6: BATCH NUMBER | H6: RPOA No. | N6: SHIFT | R6: START | S6: END
C8: I. PACKAGING MATERIALS
A9: TIME | C9: ITEM CODE | D9: ITEM DESCRIPTION | I9: BATCH / LOT NO | L9: GOOD | M9: NO GOOD (QTY) | N9: REMARKS | Q9: DONE BY/ DATE:
A10: START | B10: END
Q19: Printed Name/Sign
C20: II. MATERIAL CONTROL
A21: TIME | C21: No. | D21: CONTROL PARAMETER | L21: GOOD | M21: NO GOOD (QTY) | N21: REMARKS | Q21: INSPECTED BY:
A22: START | B22: END | C22: 1 | D22: LABELS - Tama ang label base sa Finished Goods Profile, walang sira, may tamang tag
C23: 2 | D23: CONTAINER - walang rust o kalawang, malinis, walang leak o butas, walang major dent
C24: 3 | D24: BOX - Walang butas o punit at may nakadikit na QR code. | Q24: Printed Name/Sign
C25: III. IN-PROCESS CONTROL
A26: TIME | C26: No. | D26: CONTROL PARAMETER | L26: GOOD | M26: NO GOOD (QTY) | N26: REMARKS | Q26: DONE BY/ DATE:
A27: START | B27: END | C27: 1 | D27: BATCH CODING :
C29: * Important Reminder: Start-up samples must be approved first prior to mass production. Team Leader to check at least 5 samples and attach 1 pc approved sample in this OPCR.
A30: TIME | C30: No. | D30: CONTROL PARAMETER | L30: GOOD | M30: NO GOOD (QTY) | N30: REMARKS | Q30: INSPECTED BY:
A31: START | B31: END | C31: 1 | D31: Tama ang Batch Code
C32: 2 | D32: Walang sira ang mga labels
C33: 3 | D33: Walang ibang produkto sa area (site clearing) | Q33: Printed Name/Sign
A35: TIME | C35: CRITICAL PROCESS PARAMETER | Q35: DONE BY:
A36: START | B36: END | C36: LABELLING | G36: QTY. PRODUCED | I36: QTY. REJECTED | K36: DEFECT DESCRIPTION | O36: REMARKS
L40: INSPECTED BY/ SIGN : | Q40: Printed Name/Sign
C41: IV. OUTPUT
A42: TIME | C42: NO. | D42: CONTROL PARAMETER | L42: GOOD | M42: NO GOOD | N42: REMARKS | Q42: INSPECTED BY:
A43: START | B43: END | C43: 1 | D43: Tama and Batch Code (Correct Batch Code Format)
C44: 2 | D44: Malinaw at tama ang impormasyon nakasulat (Readability, No smudge)
C45: 3 | D45: Tama and lokasyon (Correct orientation, location, alignment) | P45: AC QTY:
C46: 4 | D46: Walang natatanggal / maluwag na label (No detached / loose label) | P46: RE QTY :
C47: 5 | D47: Walang Sira ang mga labels at lata | P47: % REJ : | Q47: Printed Name/Sign
J48: REVIEWED AND VERIFIED BY:
J49: TEAM LEADER (NAME/SIGNATURE/DATE)

Sheet R2
B2: DAILY PRODUCTION REPORT | S2: HOURLY BOTTLENECK MANAGEMENT
B4: Item code: | E4: 1APC2010 | H4: PRD No. : | J4: Date: | M4: Batch No. | S4: Machine Name: | W4: Rated Speed: | AA4: Ideal Rate (per min) : | AF4: Schedule Shift:
B5: Item Description : | E5: =IFERROR(INDEX(Data!$B:$B,MATCH('R2'!E4,Data!$A:$A,0)),"") -> ALL PURPOSE EPOXY QUART | J5: Line No: | S5: Time | T5: UP Time | V5: Plan Output | W5: Actual Output | Y5: Variance Output | AA5: Downtime Activities
B6: I. RAW AND PACKAGING MATERIALS USED | S6: 6-7
B7: No. | C7: ITEM CODE | F7: Description | J7: Batch/Lot No | N7: Consumption | P7: Wastage | Q7: Remarks
B8: 1 | C8: {=IFERROR(INDEX(Data!$C:$C,SMALL(IF(('R2'!E$4=Data!$A:$A)*(COUNTIF('R2'!$C$7:C7,Data!$C:$C)=0),ROW(Data!$C:$C)-MIN(ROW(Data!$A:$A))+1,""),1)),"")} -> 4CL03000 | F8: =IFERROR(INDEX(Data!$D:$D,MATCH('R2'!$C8,Data!$C:$C,0)),"") -> C.LABEL QUART A | S8: 7-8
B9: 2 | C9: {=IFERROR(INDEX(Data!$C:$C,SMALL(IF(('R2'!E$4=Data!$A:$A)*(COUNTIF('R2'!$C$7:C8,Data!$C:$C)=0),ROW(Data!$C:$C)-MIN(ROW(Data!$A:$A))+1,""),1)),"")} -> 4CL04000 | F9: =IFERROR(INDEX(Data!$D:$D,MATCH('R2'!$C9,Data!$C:$C,0)),"") -> C.LABEL- QUART B | S9: 8-9
B10: 3 | C10: {=IFERROR(INDEX(Data!$C:$C,SMALL(IF(('R2'!E$4=Data!$A:$A)*(COUNTIF('R2'!$C$7:C9,Data!$C:$C)=0),ROW(Data!$C:$C)-MIN(ROW(Data!$A:$A))+1,""),1)),"")} -> 4C020000 | F10: =IFERROR(INDEX(Data!$D:$D,MATCH('R2'!$C10,Data!$C:$C,0)),"") -> T.CAN-QUART | S10: 9-10
B11: 4 | C11: {=IFERROR(INDEX(Data!$C:$C,SMALL(IF(('R2'!E$4=Data!$A:$A)*(COUNTIF('R2'!$C$7:C10,Data!$C:$C)=0),ROW(Data!$C:$C)-MIN(ROW(Data!$A:$A))+1,""),1)),"")} -> P45780083 | F11: =IFERROR(INDEX(Data!$D:$D,MATCH('R2'!$C11,Data!$C:$C,0)),"") -> P.BOX QUART (PRINTED) | S11: 10-11
B12: 5 | C12: {=IFERROR(INDEX(Data!$C:$C,SMALL(IF(('R2'!E$4=Data!$A:$A)*(COUNTIF('R2'!$C$7:C11,Data!$C:$C)=0),ROW(Data!$C:$C)-MIN(ROW(Data!$A:$A))+1,""),1)),"")} | F12: =IFERROR(INDEX(Data!$D:$D,MATCH('R2'!$C12,Data!$C:$C,0)),"") | S12: 11-12
B13: 6 | C13: {=IFERROR(INDEX(Data!$C:$C,SMALL(IF(('R2'!E$4=Data!$A:$A)*(COUNTIF('R2'!$C$7:C12,Data!$C:$C)=0),ROW(Data!$C:$C)-MIN(ROW(Data!$A:$A))+1,""),1)),"")} | F13: =IFERROR(INDEX(Data!$D:$D,MATCH('R2'!$C13,Data!$C:$C,0)),"") | S13: 12-1
B14: 7 | C14: {=IFERROR(INDEX(Data!$C:$C,SMALL(IF(('R2'!E$4=Data!$A:$A)*(COUNTIF('R2'!$C$7:C13,Data!$C:$C)=0),ROW(Data!$C:$C)-MIN(ROW(Data!$A:$A))+1,""),1)),"")} | F14: =IFERROR(INDEX(Data!$D:$D,MATCH('R2'!$C14,Data!$C:$C,0)),"") | S14: 1-2
B15: 8 | C15: {=IFERROR(INDEX(Data!$C:$C,SMALL(IF(('R2'!E$4=Data!$A:$A)*(COUNTIF('R2'!$C$7:C14,Data!$C:$C)=0),ROW(Data!$C:$C)-MIN(ROW(Data!$A:$A))+1,""),1)),"")} | F15: =IFERROR(INDEX(Data!$D:$D,MATCH('R2'!$C15,Data!$C:$C,0)),"") | S15: Machine Name: | W15: Rated Speed: | AA15: Ideal Rate (per min) : | AF15: Schedule Shift:
B16: 9 | C16: {=IFERROR(INDEX(Data!$C:$C,SMALL(IF(('R2'!E$4=Data!$A:$A)*(COUNTIF('R2'!$C$7:C15,Data!$C:$C)=0),ROW(Data!$C:$C)-MIN(ROW(Data!$A:$A))+1,""),1)),"")} | F16: =IFERROR(INDEX(Data!$D:$D,MATCH('R2'!$C16,Data!$C:$C,0)),"") | S16: Time | T16: UP Time | V16: Plan Output | W16: Actual Output | Y16: Variance Output | AA16: Downtime Activities
B17: 10 | C17: {=IFERROR(INDEX(Data!$C:$C,SMALL(IF(('R2'!E$4=Data!$A:$A)*(COUNTIF('R2'!$C$7:C16,Data!$C:$C)=0),ROW(Data!$C:$C)-MIN(ROW(Data!$A:$A))+1,""),1)),"")} | F17: =IFERROR(INDEX(Data!$D:$D,MATCH('R2'!$C17,Data!$C:$C,0)),"") | S17: 6-7
B18: II. QUALITY | N18: Quality Remarks | S18: 7-8
B19: Total Actual Output | G19: Total Accepted Output | J19: Total Rejected Output
S20: 8-9
S21: 9-10
B22: III. MANPOWER / PRODUCTIVITY | N22: QR CODE BATCH NO Approved by: / Date | S22: 10-11
B23: No. | C23: Name of Associates | H23: Assignment | J23: Machine Used
B24: 1 | S24: 11-12
B25: 2
B26: 3 | S26: 12-1
B27: 4
B28: 5 | S28: 1-2
B29: 6
B30: 7 | S30: Machine Name: | W30: Rated Speed: | AA30: Ideal Rate (per min) : | AF30: Schedule Shift:
B31: 8
B32: 9 | S32: Time | T32: UP Time | V32: Plan Output | W32: Actual Output | Y32: Variance Output | AA32: Downtime Activities
B33: 10
B34: IV. SYSTEM REPORTING | J34: V. OEE ENCODING | N34: Prepared By:
B35: Reported Date: | J35: Encoded Date:
B37: Reported By:
O38: Production Team Leader
B39: Transaction (PTR) No. :
J40: Encoded By: | N40: Reviewed By:
B41: Transfer (TTF) No. :
B43: Shipment (WSS) No. : | O43: Production Section Head
B45: QF-P-MFG004-009-R00

Sheet 2 machine
B1: DAILY PRODUCTION REPORT | V1: HOURLY BOTTLENECK MANAGEMENT
B4: Item code: | I4: PRD No. : | Q4: Production Date: | V4: Machine Name: | AB4: Rated Speed: | AH4: Ideal Rate (per min) :
B5: Item Description : | Q5: Batch No. : | V5: Time | W5: UP Time | Y5: Plan Output | Z5: Actual Output | AB5: Reject Output | AD5: Downtime Activities
Q6: Production Line:
B7: I. RAW AND PACKAGING MATERIALS USED | V7: 6-7
B8: No. | C8: ITEM CODE | G8: Description | J8: Batch/Lot No | Q8: Consumption | T8: Wastage | U8: Remarks | V8: 7-8
B9: 1 | V9: 8-9
B10: 2 | V10: 9-10
B11: 3 | V11: 10-11
B12: 4 | V12: 11-12
B13: 5 | V13: 12-1
B14: 6 | V14: 1-2
B15: 7 | V15: 2-3
B16: 8 | V16: 3-4
B17: 9 | V17: 4-5
B19: 10 | V19: 5-6
B20: II. QUALITY | S20: Quality Remarks | V20: Machine Name: | AB20: Rated Speed: | AH20: Ideal Rate (per min) :
B21: Total Actual Output | H21: Total Accepted Output | M21: Total Rejected Output
V22: Time | W22: UP Time | Y22: Plan Output | Z22: Actual Output | AB22: Reject Output | AD22: Downtime Activities
B25: III. MANPOWER / PRODUCTIVITY | O25: QR CODE BATCH NO Approved by: / Date | V25: 6-7
B26: No. | C26: Name of Associates | F26: Assignment | I26: Machine Used | M26: Signature | V26: 7-8
B27: 1 | V27: 8-9
B28: 2 | V28: 9-10
B29: 3 | V29: 10-11
B30: 4 | V30: 11-12
B31: 5 | V31: 12-1
B32: 6 | V32: 1-2
B33: 7 | V33: 2-3
B34: 8 | V34: 3-4
B35: 9 | V35: 4-5
B36: 10 | V36: 5-6
B37: IV. SYSTEM REPORTING | V37: HBM Remarks:
B38: Date Reported: | I38: Reported By: | O38: Docpro Remarks:
B40: PTR No.
V41: Prepared By: | AE41: Reviewed By:
B42: Shipment No. | I42: Shipment No.
V43: Production Team Leader | AE43: Production Section Head
