Workbook
Name CONDITION: '[1]FINISH CODES'!$B$8:$B$10
Name CONDITION: '[2]FINISH CODES'!$B$8:$B$10
Name CONDITIONS: [3]CODES!$A$3:$B$7
Name CONDITIONS: [4]CODES!$A$3:$B$7
Name COVCON: '[5]ASSEMBLY CODES'!$A$19:$A$32
Name COVCON: '[6]ASSEMBLY CODES'!$A$19:$A$32
Name GPCOLORCOMBINATIONS: [3]CODES!$P$31:$R$44
Name GPCOLORCOMBINATIONS: [4]CODES!$P$31:$R$44
Name GPHYDROEYES: [3]CODES!$P$47:$Q$54
Name GPHYDROEYES: [4]CODES!$P$47:$Q$54
Name GPSUBLIDS: [3]CODES!$P$24:$Q$27
Name GPSUBLIDS: [4]CODES!$P$24:$Q$27
Name LCODES: '[1]FINISH CODES'!$E$33:$E$52
Name LCODES: '[2]FINISH CODES'!$E$33:$E$52
Name LID: '[5]ASSEMBLY CODES'!$A$13:$A$16
Name LID: '[6]ASSEMBLY CODES'!$A$13:$A$16
Name LIST2: #REF!
Name LIST2: #REF!
Name LIST2: #REF!
Name LIST2: #REF!
Name LIST2: #REF!
Name LIST2: #REF!
Name POLARITIES: [3]CODES!$M$3:$N$24
Name POLARITIES: [4]CODES!$M$3:$N$24
Name SALESDESC: '[7]from IRN'!$B$4:$E$1375
Name SALESDESC: '[8]from IRN'!$B$4:$E$1375
Name SIZES: [3]CODES!$G$3:$H$48
Name SIZES: [4]CODES!$G$3:$H$48
Name SSSCODE: '[1]FINISH CODES'!$B$19:$B$60
Name SSSCODE: '[2]FINISH CODES'!$B$19:$B$60
Name TCODE: '[1]FINISH CODES'!$E$27:$E$28
Name TCODE: '[2]FINISH CODES'!$E$27:$E$28

Sheet SUMMARY
B2: LINE | C2: UTILIZATION | D2: RFT | E2: OEE | F2: ELOR | G2: AVAIL | H2: PER
B3: Filling | C3: ='Filling Manual'!EQ107 -> #DIV/0! | D3: ='Filling Manual'!DS107 -> #DIV/0! | E3: ='Filling Manual'!ED107 -> #DIV/0! | F3: ='Filling Manual'!EL107 -> #DIV/0! | G3: ='Filling Manual'!DG107 -> #DIV/0! | H3: ='Filling Manual'!DM107 -> #DIV/0!
B4: Milling | C4: =Milling!EQ107 -> #DIV/0! | D4: =Milling!DS107 -> #DIV/0! | E4: =Milling!ED107 -> #DIV/0! | F4: =Milling!EL107 -> #DIV/0! | G4: =Milling!DG107 -> #DIV/0! | H4: =Milling!DM107 -> #DIV/0!
B5: Mixing | C5: =Mixing!EQ107 -> #DIV/0! | D5: =Mixing!DS107 -> #DIV/0! | E5: =Mixing!ED107 -> #DIV/0! | F5: =Mixing!EL107 -> #DIV/0! | G5: =Mixing!DG107 -> #DIV/0! | H5: =Mixing!DM107 -> #DIV/0!
B6: Tinting/Letdown | C6: =Tinting!EQ107 -> #DIV/0! | D6: =Tinting!DS107 -> #DIV/0! | E6: =Tinting!ED107 -> #DIV/0! | F6: =Tinting!EL107 -> #DIV/0! | G6: =Tinting!DG107 -> #DIV/0! | H6: =Tinting!DM107 -> #DIV/0!
B7: AVERANGE: | C7: =AVERAGE(C4:C6) -> #DIV/0! | D7: =AVERAGE(D4:D6) -> #DIV/0! | E7: =AVERAGE(E4:E6) -> #DIV/0! | F7: =AVERAGE(F4:F6) -> #DIV/0! | G7: =AVERAGE(G4:G6) -> #DIV/0! | H7: =AVERAGE(H4:H6) -> #DIV/0!
H11: `

Sheet Filling Manual
K1: AVAILABLE TIME - PLANNED DOWNTIME (UNCONTROLLABLE) = LOADING TIME | AR1: SAP NOTIFICATION | AU1: LOADING TIME - UNPLANNED DOWNTIME / CONTROLLABLE = OPERATING TIME (Uptime) | CW1: AVAILABLE TIME DISTRIBUTION (%) | DD1: AVAILABILITY RATE X PERFORMANCE RATE X QUALITY RATE = OEE | DY1: GOOD OUTPUT÷ AVAILABLE CAPACITY=CHECK OEE | EG1: GOOD OUTPUT ÷ PLANNED PRODUCTION UPTIME = ELOR | EO1: Good Output ÷ (Ideal Prod Rate x 480)= ELUR
K2: Avail. Time (min) | M2: PLANNED DOWNTIME | AA2: UNCONTROLLABLE | AN2: TOTAL UNCONTROLLABLE | AP2: LOADING TIME (min) | AR2: SAP BREAKDOWN NOTIFICATION (min) | AS2: SAP NOTIFICATION NUMBER | AU2: BREAKDOWN & FAILURES | BR2: SET-UP AND ADJUSTMENTS | CD2: IDLING AND MINOR STOPPAGE | CS2: TOTAL UNPLANNED DOWNTIME | CU2: UPTIME / Operating Time (min) | DD2: total uptime / loading time = AVAILABILITY | DJ2: actual prod rate / ideal prod rate = PERFORMANCE | DP2: Good output / total output = QUALITY | DV2: OEE | DY2: Good Output (L) | DZ2: Ideal Prod Rate X Avail Time = Avail Cap | EB2: Available Capacity (L) | ED2: Check OEE | EG2: Good Output (L) | EH2: (Available time - Planned Downtime) X Ideal Prod Rate = Planned Production Time | EL2: ELOR | EO2: Good Output (L) | EP2: Ideal Production Rate (L/Min) | EQ2: ELUR | EW2: ideal prod rate X uptime | EZ2: Total Expected - Total Output | FA2: Variance÷Ideal Prod Rate
B3: DATE | C3: DAY | D3: SHIFT | E3: No of hours | G3: Loading Time | H3: PRODUCT TYPE | I3: Ideal Prod.Rate (L/min) | M3: A1 - 5S, Sanitation | N3: A2 - Breaktime | O3: A3 - CLAIR | P3: A4 - Changeover , Setup/Startup ,Change Kettle | Q3: A5 - PM (Preventitve Maintenance) | R3: A6-Flag Ceremony | S3: A7-General Assembly | T3: A8-Performance Dialogue | U3: A9-Trial Run | V3: A10-Training, Meetings | W3: A11-Company Activities | X3: A12-Emergency Drills | Y3: A13-No Production Plan | Z3: A14-No Head Count Allocation | AA3: UDT-Force Majeure | AB3: UDT-Grid Power Failure | AC3: UDT-Supply Chain Discuption | AD3: UDT-Gov't/Regulatory Issues | AE3: UDT-External Insfastructure failures | AF3: UDT-Labor related external issues | AG3: UDT-Late Shuttle Service | AU3: B1- Gear Box Problem | AV3: B2- Bearing Problem | AW3: B3- Compress Air Low Pressure | AX3: B4- Heater Problem | AY3: B5- Rampost Aluminum Piston Seal Problem | AZ3: B6- Sensor Problem | BA3: B7- Weight Problem (Leak) | BB3: B8- Weight Problem (Hoper Pressure) | BC3: B9- Pressure Gauge Problem | BD3: B10- Deffective - Foot Swith Problem | BE3: B11- Deffective -Air Motor Problem | BF3: B12- Deffective -Lower Extrusion Pump Problem | BG3: B13- Deffective Slot Chain-Conveyor Problem | BH3: B14- Deffective-Can Closer | BI3: B15- Crimping Problem | BJ3: B16-Follower Plate Problem (Rampest) | BK3: B17- Follower Plate Problem(Deformed) | BR3: EXCESS SET UP | BS3: EXCESS CHANGE OVER | BZ3: - | CA3: - | CB3: - | CD3: Delay Issuance Materials Supply (PM) | CE3: Delay Issuance Materials Supply (RM) | CF3: Out Stocks (RMPM) | CG3: Sorting/Reworking | CH3: Quality Problem | CI3: Absent Manpower | CJ3: Not Rendered Overtime (OT) | CK3: Unplanned Meeting | CL3: No available Bulkmix/Kettle | CM3: Waiting for Bulkmix Approval | CN3: Over Breaktime | CO3: Equipment Mishandling | CP3: Waiting for Forklift | CQ3: Early Quitting | CR3: - | CW3: % PLANNED | CX3: % UNCONTROLLABLE | CY3: % BREAK DOWN AND FAILURE | CZ3: % SET UP AND ADJUSTMENT | DA3: % IDLING AND MINOR STOP | DB3: %UPTIME (operating time) | DD3: Loading Time (min) | DE3: TOTAL Downtime (min) | DF3: [AvailTime-ΣDowntime] = TOTAL Uptime (min) | DG3: %Availability | DJ3: PRODUCT TYPE | DK3: Ideal Prod.Rate (L/min) | DL3: [Total Output÷Uptime] = Actual Prod. Rate (L/min) | DM3: %Performance | DP3: Good Output (L) | DQ3: Reject (L) | DR3: Total Output (L) | DS3: %Quality | DZ3: Ideal Prod.Rate (KG/min) | EA3: Loading time(min) | EH3: Available Time | EI3: Planned Downtime | EJ3: Ideal Prod Rate (L/min) | EK3: Planned Production Time | EU3: Ideal Prod. Rate (L/min) | EV3: UPTIME (min) | EW3: TOTAL expected output (L) | EX3: TOTAL output (L) | EZ3: ( VARIANCE ) OUTPUT LOSS (L) | FA3: PERFORMANCE RATE IN LOSS TIME EQUIVALENT (min) | FB3: JUSTIFICATION
I5: =IF(E5>0.0001,0,0) -> 0 | K5: =E5*60 -> 0 | AN5: =SUM(M5:AM5) -> 0 | AP5: =K5-AN5 -> 0 | CS5: =SUM(AU5:CR5) -> 0 | CU5: =AP5-CS5 -> 0 | CW5: =(SUM(M5:Z5))/K5 -> #DIV/0! | CX5: =(SUM(AA5:AM5))/K5 -> #DIV/0! | CY5: =(SUM(AU5:BQ5))/$K5 -> #DIV/0! | CZ5: =(SUM(BR5:CC5))/K5 -> #DIV/0! | DA5: =(SUM(CD5:CR5))/K5 -> #DIV/0! | DB5: =CU5/K5 -> #DIV/0! | DD5: =AP5 -> 0 | DE5: =CS5 -> 0 | DF5: =$DD5-DE5 -> 0 | DG5: =DF5/$DD5 -> #DIV/0! | DH5: =IF(AP5>0.01,1,0) -> 0 | DJ5: =H5 -> 0 | DK5: =I5 -> 0 | DL5: =DR5/DF5 -> #DIV/0! | DM5: =DL5/DK5 -> #DIV/0! | DN5: =IF(DM5>0.01,1,0) -> #DIV/0! | DR5: =DP5+DQ5 -> 0 | DS5: =IF(DL5=0,0,DP5/DR5) -> #DIV/0! | DT5: =IF(DS5>0.01,1,0) -> #DIV/0! | DV5: =DG5*DM5*DS5 -> #DIV/0! | DW5: =IF($AP5>0.01,1,0) -> 0 | DY5: =DP5 -> 0 | DZ5: =DK5 -> 0 | EA5: =+AP5 -> 0 | EB5: =DZ5*EA5 -> 0 | ED5: =DY5/EB5 -> #DIV/0! | EE5: =IF($AP5>0.01,1,0) -> 0 | EG5: =DP5 -> 0 | EH5: =K5 -> 0 | EI5: =SUM(M5:Z5) -> 0 | EJ5: =I5 -> 0 | EK5: =(EH5-EI5)*EJ5 -> 0 | EL5: =EG5/EK5 -> #DIV/0! | EM5: =IF(EK5>0.01,1,0) -> 0 | EO5: =EG5 -> 0 | EP5: =EJ5 -> 0 | EQ5: =EO5/(EP5*K5) -> #DIV/0! | ER5: =IF($K5>0.01,1,0) -> 0 | EU5: =DK5 -> 0 | EV5: =CU5 -> 0 | EW5: =I5*CU5 -> 0 | EX5: =DR5 -> 0 | EZ5: =EW5-EX5 -> 0 | FA5: =+IF(EZ5/I5<0,0,(EZ5/I5)) -> #DIV/0!
I6: =IF(E6>0.0001,0,0) -> 0 | K6: =E6*60 -> 0 | AN6: =SUM(M6:AM6) -> 0 | AP6: =K6-AN6 -> 0 | CS6: =SUM(AU6:CR6) -> 0 | CU6: =AP6-CS6 -> 0 | CW6: =(SUM(M6:Z6))/K6 -> #DIV/0! | CX6: =(SUM(AA6:AM6))/K6 -> #DIV/0! | CY6: =(SUM(AU6:BQ6))/$K6 -> #DIV/0! | CZ6: =(SUM(BR6:CC6))/K6 -> #DIV/0! | DA6: =(SUM(CD6:CR6))/K6 -> #DIV/0! | DB6: =CU6/K6 -> #DIV/0! | DD6: =AP6 -> 0 | DE6: =CS6 -> 0 | DF6: =$DD6-DE6 -> 0 | DG6: =DF6/$DD6 -> #DIV/0! | DH6: =IF(AP6>0.01,1,0) -> 0 | DJ6: =H6 -> 0 | DK6: =I6 -> 0 | DL6: =DR6/DF6 -> #DIV/0! | DM6: =DL6/DK6 -> #DIV/0! | DN6: =IF(DM6>0.01,1,0) -> #DIV/0! | DR6: =DP6+DQ6 -> 0 | DS6: =IF(DL6=0,0,DP6/DR6) -> #DIV/0! | DT6: =IF(DS6>0.01,1,0) -> #DIV/0! | DV6: =DG6*DM6*DS6 -> #DIV/0! | DW6: =IF($AP6>0.01,1,0) -> 0 | DY6: =DP6 -> 0 | DZ6: =DK6 -> 0 | EA6: =+AP6 -> 0 | EB6: =DZ6*EA6 -> 0 | ED6: =DY6/EB6 -> #DIV/0! | EE6: =IF($AP6>0.01,1,0) -> 0 | EG6: =DP6 -> 0 | EH6: =K6 -> 0 | EI6: =SUM(M6:Z6) -> 0 | EJ6: =I6 -> 0 | EK6: =(EH6-EI6)*EJ6 -> 0 | EL6: =EG6/EK6 -> #DIV/0! | EM6: =IF(EK6>0.01,1,0) -> 0 | EO6: =EG6 -> 0 | EP6: =EJ6 -> 0 | EQ6: =EO6/(EP6*K6) -> #DIV/0! | ER6: =IF($K6>0.01,1,0) -> 0 | EU6: =DK6 -> 0 | EV6: =CU6 -> 0 | EW6: =I6*CU6 -> 0 | EX6: =DR6 -> 0 | EZ6: =EW6-EX6 -> 0 | FA6: =+IF(EZ6/I6<0,0,(EZ6/I6)) -> #DIV/0!
I7: =IF(E7>0.0001,0,0) -> 0 | K7: =E7*60 -> 0 | AN7: =SUM(M7:AM7) -> 0 | AP7: =K7-AN7 -> 0 | CS7: =SUM(AU7:CR7) -> 0 | CU7: =AP7-CS7 -> 0 | CW7: =(SUM(M7:Z7))/K7 -> #DIV/0! | CX7: =(SUM(AA7:AM7))/K7 -> #DIV/0! | CY7: =(SUM(AU7:BQ7))/$K7 -> #DIV/0! | CZ7: =(SUM(BR7:CC7))/K7 -> #DIV/0! | DA7: =(SUM(CD7:CR7))/K7 -> #DIV/0! | DB7: =CU7/K7 -> #DIV/0! | DD7: =AP7 -> 0 | DE7: =CS7 -> 0 | DF7: =$DD7-DE7 -> 0 | DG7: =DF7/$DD7 -> #DIV/0! | DH7: =IF(AP7>0.01,1,0) -> 0 | DJ7: =H7 -> 0 | DK7: =I7 -> 0 | DL7: =DR7/DF7 -> #DIV/0! | DM7: =DL7/DK7 -> #DIV/0! | DN7: =IF(DM7>0.01,1,0) -> #DIV/0! | DR7: =DP7+DQ7 -> 0 | DS7: =IF(DL7=0,0,DP7/DR7) -> #DIV/0! | DT7: =IF(DS7>0.01,1,0) -> #DIV/0! | DV7: =DG7*DM7*DS7 -> #DIV/0! | DW7: =IF($AP7>0.01,1,0) -> 0 | DY7: =DP7 -> 0 | DZ7: =DK7 -> 0 | EA7: =+AP7 -> 0 | EB7: =DZ7*EA7 -> 0 | ED7: =DY7/EB7 -> #DIV/0! | EE7: =IF($AP7>0.01,1,0) -> 0 | EG7: =DP7 -> 0 | EH7: =K7 -> 0 | EI7: =SUM(M7:Z7) -> 0 | EJ7: =I7 -> 0 | EK7: =(EH7-EI7)*EJ7 -> 0 | EL7: =EG7/EK7 -> #DIV/0! | EM7: =IF(EK7>0.01,1,0) -> 0 | EO7: =EG7 -> 0 | EP7: =EJ7 -> 0 | EQ7: =EO7/(EP7*K7) -> #DIV/0! | ER7: =IF($K7>0.01,1,0) -> 0 | EU7: =DK7 -> 0 | EV7: =CU7 -> 0 | EW7: =I7*CU7 -> 0 | EX7: =DR7 -> 0 | EZ7: =EW7-EX7 -> 0 | FA7: =+IF(EZ7/I7<0,0,(EZ7/I7)) -> #DIV/0!
I8: =IF(E8>0.0001,0,0) -> 0 | K8: =E8*60 -> 0 | AN8: =SUM(M8:AM8) -> 0 | AP8: =K8-AN8 -> 0 | CS8: =SUM(AU8:CR8) -> 0 | CU8: =AP8-CS8 -> 0 | CW8: =(SUM(M8:Z8))/K8 -> #DIV/0! | CX8: =(SUM(AA8:AM8))/K8 -> #DIV/0! | CY8: =(SUM(AU8:BQ8))/$K8 -> #DIV/0! | CZ8: =(SUM(BR8:CC8))/K8 -> #DIV/0! | DA8: =(SUM(CD8:CR8))/K8 -> #DIV/0! | DB8: =CU8/K8 -> #DIV/0! | DD8: =AP8 -> 0 | DE8: =CS8 -> 0 | DF8: =$DD8-DE8 -> 0 | DG8: =DF8/$DD8 -> #DIV/0! | DH8: =IF(AP8>0.01,1,0) -> 0 | DJ8: =H8 -> 0 | DK8: =I8 -> 0 | DL8: =DR8/DF8 -> #DIV/0! | DM8: =DL8/DK8 -> #DIV/0! | DN8: =IF(DM8>0.01,1,0) -> #DIV/0! | DR8: =DP8+DQ8 -> 0 | DS8: =IF(DL8=0,0,DP8/DR8) -> #DIV/0! | DT8: =IF(DS8>0.01,1,0) -> #DIV/0! | DV8: =DG8*DM8*DS8 -> #DIV/0! | DW8: =IF($AP8>0.01,1,0) -> 0 | DY8: =DP8 -> 0 | DZ8: =DK8 -> 0 | EA8: =+AP8 -> 0 | EB8: =DZ8*EA8 -> 0 | ED8: =DY8/EB8 -> #DIV/0! | EE8: =IF($AP8>0.01,1,0) -> 0 | EG8: =DP8 -> 0 | EH8: =K8 -> 0 | EI8: =SUM(M8:Z8) -> 0 | EJ8: =I8 -> 0 | EK8: =(EH8-EI8)*EJ8 -> 0 | EL8: =EG8/EK8 -> #DIV/0! | EM8: =IF(EK8>0.01,1,0) -> 0 | EO8: =EG8 -> 0 | EP8: =EJ8 -> 0 | EQ8: =EO8/(EP8*K8) -> #DIV/0! | ER8: =IF($K8>0.01,1,0) -> 0 | EU8: =DK8 -> 0 | EV8: =CU8 -> 0 | EW8: =I8*CU8 -> 0 | EX8: =DR8 -> 0 | EZ8: =EW8-EX8 -> 0 | FA8: =+IF(EZ8/I8<0,0,(EZ8/I8)) -> #DIV/0!
I9: =IF(E9>0.0001,0,0) -> 0 | K9: =E9*60 -> 0 | AN9: =SUM(M9:AM9) -> 0 | AP9: =K9-AN9 -> 0 | CS9: =SUM(AU9:CR9) -> 0 | CU9: =AP9-CS9 -> 0 | CW9: =(SUM(M9:Z9))/K9 -> #DIV/0! | CX9: =(SUM(AA9:AM9))/K9 -> #DIV/0! | CY9: =(SUM(AU9:BQ9))/$K9 -> #DIV/0! | CZ9: =(SUM(BR9:CC9))/K9 -> #DIV/0! | DA9: =(SUM(CD9:CR9))/K9 -> #DIV/0! | DB9: =CU9/K9 -> #DIV/0! | DD9: =AP9 -> 0 | DE9: =CS9 -> 0 | DF9: =$DD9-DE9 -> 0 | DG9: =DF9/$DD9 -> #DIV/0! | DH9: =IF(AP9>0.01,1,0) -> 0 | DJ9: =H9 -> 0 | DK9: =I9 -> 0 | DL9: =DR9/DF9 -> #DIV/0! | DM9: =DL9/DK9 -> #DIV/0! | DN9: =IF(DM9>0.01,1,0) -> #DIV/0! | DR9: =DP9+DQ9 -> 0 | DS9: =IF(DL9=0,0,DP9/DR9) -> #DIV/0! | DT9: =IF(DS9>0.01,1,0) -> #DIV/0! | DV9: =DG9*DM9*DS9 -> #DIV/0! | DW9: =IF($AP9>0.01,1,0) -> 0 | DY9: =DP9 -> 0 | DZ9: =DK9 -> 0 | EA9: =+AP9 -> 0 | EB9: =DZ9*EA9 -> 0 | ED9: =DY9/EB9 -> #DIV/0! | EE9: =IF($AP9>0.01,1,0) -> 0 | EG9: =DP9 -> 0 | EH9: =K9 -> 0 | EI9: =SUM(M9:Z9) -> 0 | EJ9: =I9 -> 0 | EK9: =(EH9-EI9)*EJ9 -> 0 | EL9: =EG9/EK9 -> #DIV/0! | EM9: =IF(EK9>0.01,1,0) -> 0 | EO9: =EG9 -> 0 | EP9: =EJ9 -> 0 | EQ9: =EO9/(EP9*K9) -> #DIV/0! | ER9: =IF($K9>0.01,1,0) -> 0 | EU9: =DK9 -> 0 | EV9: =CU9 -> 0 | EW9: =I9*CU9 -> 0 | EX9: =DR9 -> 0 | EZ9: =EW9-EX9 -> 0 | FA9: =+IF(EZ9/I9<0,0,(EZ9/I9)) -> #DIV/0!
I10: =IF(E10>0.0001,0,0) -> 0 | K10: =E10*60 -> 0 | AN10: =SUM(M10:AM10) -> 0 | AP10: =K10-AN10 -> 0 | CS10: =SUM(AU10:CR10) -> 0 | CU10: =AP10-CS10 -> 0 | CW10: =(SUM(M10:Z10))/K10 -> #DIV/0! | CX10: =(SUM(AA10:AM10))/K10 -> #DIV/0! | CY10: =(SUM(AU10:BQ10))/$K10 -> #DIV/0! | CZ10: =(SUM(BR10:CC10))/K10 -> #DIV/0! | DA10: =(SUM(CD10:CR10))/K10 -> #DIV/0! | DB10: =CU10/K10 -> #DIV/0! | DD10: =AP10 -> 0 | DE10: =CS10 -> 0 | DF10: =$DD10-DE10 -> 0 | DG10: =DF10/$DD10 -> #DIV/0! | DH10: =IF(AP10>0.01,1,0) -> 0 | DJ10: =H10 -> 0 | DK10: =I10 -> 0 | DL10: =DR10/DF10 -> #DIV/0! | DM10: =DL10/DK10 -> #DIV/0! | DN10: =IF(DM10>0.01,1,0) -> #DIV/0! | DR10: =DP10+DQ10 -> 0 | DS10: =IF(DL10=0,0,DP10/DR10) -> #DIV/0! | DT10: =IF(DS10>0.01,1,0) -> #DIV/0! | DV10: =DG10*DM10*DS10 -> #DIV/0! | DW10: =IF($AP10>0.01,1,0) -> 0 | DY10: =DP10 -> 0 | DZ10: =DK10 -> 0 | EA10: =+AP10 -> 0 | EB10: =DZ10*EA10 -> 0 | ED10: =DY10/EB10 -> #DIV/0! | EE10: =IF($AP10>0.01,1,0) -> 0 | EG10: =DP10 -> 0 | EH10: =K10 -> 0 | EI10: =SUM(M10:Z10) -> 0 | EJ10: =I10 -> 0 | EK10: =(EH10-EI10)*EJ10 -> 0 | EL10: =EG10/EK10 -> #DIV/0! | EM10: =IF(EK10>0.01,1,0) -> 0 | EO10: =EG10 -> 0 | EP10: =EJ10 -> 0 | EQ10: =EO10/(EP10*K10) -> #DIV/0! | ER10: =IF($K10>0.01,1,0) -> 0 | EU10: =DK10 -> 0 | EV10: =CU10 -> 0 | EW10: =I10*CU10 -> 0 | EX10: =DR10 -> 0 | EZ10: =EW10-EX10 -> 0 | FA10: =+IF(EZ10/I10<0,0,(EZ10/I10)) -> #DIV/0!
I11: =IF(E11>0.0001,9.4,0) -> 0 | K11: =E11*60 -> 0 | AN11: =SUM(M11:AM11) -> 0 | AP11: =K11-AN11 -> 0 | CS11: =SUM(AU11:CR11) -> 0 | CU11: =AP11-CS11 -> 0 | CW11: =(SUM(M11:Z11))/K11 -> #DIV/0! | CX11: =(SUM(AA11:AM11))/K11 -> #DIV/0! | CY11: =(SUM(AU11:BQ11))/$K11 -> #DIV/0! | CZ11: =(SUM(BR11:CC11))/K11 -> #DIV/0! | DA11: =(SUM(CD11:CR11))/K11 -> #DIV/0! | DB11: =CU11/K11 -> #DIV/0! | DD11: =AP11 -> 0 | DE11: =CS11 -> 0 | DF11: =$DD11-DE11 -> 0 | DG11: =DF11/$DD11 -> #DIV/0! | DH11: =IF(AP11>0.01,1,0) -> 0 | DJ11: =H11 -> 0 | DK11: =I11 -> 0 | DL11: =DR11/DF11 -> #DIV/0! | DM11: =DL11/DK11 -> #DIV/0! | DN11: =IF(DM11>0.01,1,0) -> #DIV/0! | DR11: =DP11+DQ11 -> 0 | DS11: =IF(DL11=0,0,DP11/DR11) -> #DIV/0! | DT11: =IF(DS11>0.01,1,0) -> #DIV/0! | DV11: =DG11*DM11*DS11 -> #DIV/0! | DW11: =IF($AP11>0.01,1,0) -> 0 | DY11: =DP11 -> 0 | DZ11: =DK11 -> 0 | EA11: =+AP11 -> 0 | EB11: =DZ11*EA11 -> 0 | ED11: =DY11/EB11 -> #DIV/0! | EE11: =IF($AP11>0.01,1,0) -> 0 | EG11: =DP11 -> 0 | EH11: =K11 -> 0 | EI11: =SUM(M11:Z11) -> 0 | EJ11: =I11 -> 0 | EK11: =(EH11-EI11)*EJ11 -> 0 | EL11: =EG11/EK11 -> #DIV/0! | EM11: =IF(EK11>0.01,1,0) -> 0 | EO11: =EG11 -> 0 | EP11: =EJ11 -> 0 | EQ11: =EO11/(EP11*K11) -> #DIV/0! | ER11: =IF($K11>0.01,1,0) -> 0 | EU11: =DK11 -> 0 | EV11: =CU11 -> 0 | EW11: =I11*CU11 -> 0 | EX11: =DR11 -> 0 | EZ11: =EW11-EX11 -> 0 | FA11: =+IF(EZ11/I11<0,0,(EZ11/I11)) -> #DIV/0!
I12: =IF(E12>0.0001,0,0) -> 0 | K12: =E12*60 -> 0 | AN12: =SUM(M12:AM12) -> 0 | AP12: =K12-AN12 -> 0 | CS12: =SUM(AU12:CR12) -> 0 | CU12: =AP12-CS12 -> 0 | CW12: =(SUM(M12:Z12))/K12 -> #DIV/0! | CX12: =(SUM(AA12:AM12))/K12 -> #DIV/0! | CY12: =(SUM(AU12:BQ12))/$K12 -> #DIV/0! | CZ12: =(SUM(BR12:CC12))/K12 -> #DIV/0! | DA12: =(SUM(CD12:CR12))/K12 -> #DIV/0! | DB12: =CU12/K12 -> #DIV/0! | DD12: =AP12 -> 0 | DE12: =CS12 -> 0 | DF12: =$DD12-DE12 -> 0 | DG12: =DF12/$DD12 -> #DIV/0! | DH12: =IF(AP12>0.01,1,0) -> 0 | DJ12: =H12 -> 0 | DK12: =I12 -> 0 | DL12: =DR12/DF12 -> #DIV/0! | DM12: =DL12/DK12 -> #DIV/0! | DN12: =IF(DM12>0.01,1,0) -> #DIV/0! | DR12: =DP12+DQ12 -> 0 | DS12: =IF(DL12=0,0,DP12/DR12) -> #DIV/0! | DT12: =IF(DS12>0.01,1,0) -> #DIV/0! | DV12: =DG12*DM12*DS12 -> #DIV/0! | DW12: =IF($AP12>0.01,1,0) -> 0 | DY12: =DP12 -> 0 | DZ12: =DK12 -> 0 | EA12: =+AP12 -> 0 | EB12: =DZ12*EA12 -> 0 | ED12: =DY12/EB12 -> #DIV/0! | EE12: =IF($AP12>0.01,1,0) -> 0 | EG12: =DP12 -> 0 | EH12: =K12 -> 0 | EI12: =SUM(M12:Z12) -> 0 | EJ12: =I12 -> 0 | EK12: =(EH12-EI12)*EJ12 -> 0 | EL12: =EG12/EK12 -> #DIV/0! | EM12: =IF(EK12>0.01,1,0) -> 0 | EO12: =EG12 -> 0 | EP12: =EJ12 -> 0 | EQ12: =EO12/(EP12*K12) -> #DIV/0! | ER12: =IF($K12>0.01,1,0) -> 0 | EU12: =DK12 -> 0 | EV12: =CU12 -> 0 | EW12: =I12*CU12 -> 0 | EX12: =DR12 -> 0 | EZ12: =EW12-EX12 -> 0 | FA12: =+IF(EZ12/I12<0,0,(EZ12/I12)) -> #DIV/0!
I13: =IF(E13>0.0001,0,0) -> 0 | K13: =E13*60 -> 0 | AN13: =SUM(M13:AM13) -> 0 | AP13: =K13-AN13 -> 0 | CS13: =SUM(AU13:CR13) -> 0 | CU13: =AP13-CS13 -> 0 | CW13: =(SUM(M13:Z13))/K13 -> #DIV/0! | CX13: =(SUM(AA13:AM13))/K13 -> #DIV/0! | CY13: =(SUM(AU13:BQ13))/$K13 -> #DIV/0! | CZ13: =(SUM(BR13:CC13))/K13 -> #DIV/0! | DA13: =(SUM(CD13:CR13))/K13 -> #DIV/0! | DB13: =CU13/K13 -> #DIV/0! | DD13: =AP13 -> 0 | DE13: =CS13 -> 0 | DF13: =$DD13-DE13 -> 0 | DG13: =DF13/$DD13 -> #DIV/0! | DH13: =IF(AP13>0.01,1,0) -> 0 | DJ13: =H13 -> 0 | DK13: =I13 -> 0 | DL13: =DR13/DF13 -> #DIV/0! | DM13: =DL13/DK13 -> #DIV/0! | DN13: =IF(DM13>0.01,1,0) -> #DIV/0! | DR13: =DP13+DQ13 -> 0 | DS13: =IF(DL13=0,0,DP13/DR13) -> #DIV/0! | DT13: =IF(DS13>0.01,1,0) -> #DIV/0! | DV13: =DG13*DM13*DS13 -> #DIV/0! | DW13: =IF($AP13>0.01,1,0) -> 0 | DY13: =DP13 -> 0 | DZ13: =DK13 -> 0 | EA13: =+AP13 -> 0 | EB13: =DZ13*EA13 -> 0 | ED13: =DY13/EB13 -> #DIV/0! | EE13: =IF($AP13>0.01,1,0) -> 0 | EG13: =DP13 -> 0 | EH13: =K13 -> 0 | EI13: =SUM(M13:Z13) -> 0 | EJ13: =I13 -> 0 | EK13: =(EH13-EI13)*EJ13 -> 0 | EL13: =EG13/EK13 -> #DIV/0! | EM13: =IF(EK13>0.01,1,0) -> 0 | EO13: =EG13 -> 0 | EP13: =EJ13 -> 0 | EQ13: =EO13/(EP13*K13) -> #DIV/0! | ER13: =IF($K13>0.01,1,0) -> 0 | EU13: =DK13 -> 0 | EV13: =CU13 -> 0 | EW13: =I13*CU13 -> 0 | EX13: =DR13 -> 0 | EZ13: =EW13-EX13 -> 0 | FA13: =+IF(EZ13/I13<0,0,(EZ13/I13)) -> #DIV/0!
I14: =IF(E14>0.0001,0,0) -> 0 | K14: =E14*60 -> 0 | AN14: =SUM(M14:AM14) -> 0 | AP14: =K14-AN14 -> 0 | CS14: =SUM(AU14:CR14) -> 0 | CU14: =AP14-CS14 -> 0 | CW14: =(SUM(M14:Z14))/K14 -> #DIV/0! | CX14: =(SUM(AA14:AM14))/K14 -> #DIV/0! | CY14: =(SUM(AU14:BQ14))/$K14 -> #DIV/0! | CZ14: =(SUM(BR14:CC14))/K14 -> #DIV/0! | DA14: =(SUM(CD14:CR14))/K14 -> #DIV/0! | DB14: =CU14/K14 -> #DIV/0! | DD14: =AP14 -> 0 | DE14: =CS14 -> 0 | DF14: =$DD14-DE14 -> 0 | DG14: =DF14/$DD14 -> #DIV/0! | DH14: =IF(AP14>0.01,1,0) -> 0 | DJ14: =H14 -> 0 | DK14: =I14 -> 0 | DL14: =DR14/DF14 -> #DIV/0! | DM14: =DL14/DK14 -> #DIV/0! | DN14: =IF(DM14>0.01,1,0) -> #DIV/0! | DR14: =DP14+DQ14 -> 0 | DS14: =IF(DL14=0,0,DP14/DR14) -> #DIV/0! | DT14: =IF(DS14>0.01,1,0) -> #DIV/0! | DV14: =DG14*DM14*DS14 -> #DIV/0! | DW14: =IF($AP14>0.01,1,0) -> 0 | DY14: =DP14 -> 0 | DZ14: =DK14 -> 0 | EA14: =+AP14 -> 0 | EB14: =DZ14*EA14 -> 0 | ED14: =DY14/EB14 -> #DIV/0! | EE14: =IF($AP14>0.01,1,0) -> 0 | EG14: =DP14 -> 0 | EH14: =K14 -> 0 | EI14: =SUM(M14:Z14) -> 0 | EJ14: =I14 -> 0 | EK14: =(EH14-EI14)*EJ14 -> 0 | EL14: =EG14/EK14 -> #DIV/0! | EM14: =IF(EK14>0.01,1,0) -> 0 | EO14: =EG14 -> 0 | EP14: =EJ14 -> 0 | EQ14: =EO14/(EP14*K14) -> #DIV/0! | ER14: =IF($K14>0.01,1,0) -> 0 | EU14: =DK14 -> 0 | EV14: =CU14 -> 0 | EW14: =I14*CU14 -> 0 | EX14: =DR14 -> 0 | EZ14: =EW14-EX14 -> 0 | FA14: =+IF(EZ14/I14<0,0,(EZ14/I14)) -> #DIV/0!
I15: =IF(E15>0.0001,0,0) -> 0 | K15: =E15*60 -> 0 | AN15: =SUM(M15:AM15) -> 0 | AP15: =K15-AN15 -> 0 | CS15: =SUM(AU15:CR15) -> 0 | CU15: =AP15-CS15 -> 0 | CW15: =(SUM(M15:Z15))/K15 -> #DIV/0! | CX15: =(SUM(AA15:AM15))/K15 -> #DIV/0! | CY15: =(SUM(AU15:BQ15))/$K15 -> #DIV/0! | CZ15: =(SUM(BR15:CC15))/K15 -> #DIV/0! | DA15: =(SUM(CD15:CR15))/K15 -> #DIV/0! | DB15: =CU15/K15 -> #DIV/0! | DD15: =AP15 -> 0 | DE15: =CS15 -> 0 | DF15: =$DD15-DE15 -> 0 | DG15: =DF15/$DD15 -> #DIV/0! | DH15: =IF(AP15>0.01,1,0) -> 0 | DJ15: =H15 -> 0 | DK15: 0 | DL15: =DR15/DF15 -> #DIV/0! | DM15: =DL15/DK15 -> #DIV/0! | DN15: =IF(DM15>0.01,1,0) -> #DIV/0! | DR15: =DP15+DQ15 -> 0 | DS15: =IF(DL15=0,0,DP15/DR15) -> #DIV/0! | DT15: =IF(DS15>0.01,1,0) -> #DIV/0! | DV15: =DG15*DM15*DS15 -> #DIV/0! | DW15: =IF($AP15>0.01,1,0) -> 0 | DY15: =DP15 -> 0 | DZ15: =DK15 -> 0 | EA15: =+AP15 -> 0 | EB15: =DZ15*EA15 -> 0 | ED15: =DY15/EB15 -> #DIV/0! | EE15: =IF($AP15>0.01,1,0) -> 0 | EG15: =DP15 -> 0 | EH15: =K15 -> 0 | EI15: =SUM(M15:Z15) -> 0 | EJ15: =I15 -> 0 | EK15: =(EH15-EI15)*EJ15 -> 0 | EL15: =EG15/EK15 -> #DIV/0! | EM15: =IF(EK15>0.01,1,0) -> 0 | EO15: =EG15 -> 0 | EP15: =EJ15 -> 0 | EQ15: =EO15/(EP15*K15) -> #DIV/0! | ER15: =IF($K15>0.01,1,0) -> 0 | EU15: =DK15 -> 0 | EV15: =CU15 -> 0 | EW15: =I15*CU15 -> 0 | EX15: =DR15 -> 0 | EZ15: =EW15-EX15 -> 0 | FA15: =+IF(EZ15/I15<0,0,(EZ15/I15)) -> #DIV/0!
I16: =IF(E16>0.0001,0,0) -> 0 | K16: =E16*60 -> 0 | AN16: =SUM(M16:AM16) -> 0 | AP16: =K16-AN16 -> 0 | CS16: =SUM(AU16:CR16) -> 0 | CU16: =AP16-CS16 -> 0 | CW16: =(SUM(M16:Z16))/K16 -> #DIV/0! | CX16: =(SUM(AA16:AM16))/K16 -> #DIV/0! | CY16: =(SUM(AU16:BQ16))/$K16 -> #DIV/0! | CZ16: =(SUM(BR16:CC16))/K16 -> #DIV/0! | DA16: =(SUM(CD16:CR16))/K16 -> #DIV/0! | DB16: =CU16/K16 -> #DIV/0! | DD16: =AP16 -> 0 | DE16: =CS16 -> 0 | DF16: =$DD16-DE16 -> 0 | DG16: =DF16/$DD16 -> #DIV/0! | DH16: =IF(AP16>0.01,1,0) -> 0 | DJ16: =H16 -> 0 | DK16: =I16 -> 0 | DL16: =DR16/DF16 -> #DIV/0! | DM16: =DL16/DK16 -> #DIV/0! | DN16: =IF(DM16>0.01,1,0) -> #DIV/0! | DR16: =DP16+DQ16 -> 0 | DS16: =IF(DL16=0,0,DP16/DR16) -> #DIV/0! | DT16: =IF(DS16>0.01,1,0) -> #DIV/0! | DV16: =DG16*DM16*DS16 -> #DIV/0! | DW16: =IF($AP16>0.01,1,0) -> 0 | DY16: =DP16 -> 0 | DZ16: =DK16 -> 0 | EA16: =+AP16 -> 0 | EB16: =DZ16*EA16 -> 0 | ED16: =DY16/EB16 -> #DIV/0! | EE16: =IF($AP16>0.01,1,0) -> 0 | EG16: =DP16 -> 0 | EH16: =K16 -> 0 | EI16: =SUM(M16:Z16) -> 0 | EJ16: =I16 -> 0 | EK16: =(EH16-EI16)*EJ16 -> 0 | EL16: =EG16/EK16 -> #DIV/0! | EM16: =IF(EK16>0.01,1,0) -> 0 | EO16: =EG16 -> 0 | EP16: =EJ16 -> 0 | EQ16: =EO16/(EP16*K16) -> #DIV/0! | ER16: =IF($K16>0.01,1,0) -> 0 | EU16: =DK16 -> 0 | EV16: =CU16 -> 0 | EW16: =I16*CU16 -> 0 | EX16: =DR16 -> 0 | EZ16: =EW16-EX16 -> 0 | FA16: =+IF(EZ16/I16<0,0,(EZ16/I16)) -> #DIV/0!
I17: =IF(E17>0.0001,0,0) -> 0 | K17: =E17*60 -> 0 | AN17: =SUM(M17:AM17) -> 0 | AP17: =K17-AN17 -> 0 | CS17: =SUM(AU17:CR17) -> 0 | CU17: =AP17-CS17 -> 0 | CW17: =(SUM(M17:Z17))/K17 -> #DIV/0! | CX17: =(SUM(AA17:AM17))/K17 -> #DIV/0! | CY17: =(SUM(AU17:BQ17))/$K17 -> #DIV/0! | CZ17: =(SUM(BR17:CC17))/K17 -> #DIV/0! | DA17: =(SUM(CD17:CR17))/K17 -> #DIV/0! | DB17: =CU17/K17 -> #DIV/0! | DD17: =AP17 -> 0 | DE17: =CS17 -> 0 | DF17: =$DD17-DE17 -> 0 | DG17: =DF17/$DD17 -> #DIV/0! | DH17: =IF(AP17>0.01,1,0) -> 0 | DJ17: =H17 -> 0 | DK17: =I17 -> 0 | DL17: =DR17/DF17 -> #DIV/0! | DM17: =DL17/DK17 -> #DIV/0! | DN17: =IF(DM17>0.01,1,0) -> #DIV/0! | DR17: =DP17+DQ17 -> 0 | DS17: =IF(DL17=0,0,DP17/DR17) -> #DIV/0! | DT17: =IF(DS17>0.01,1,0) -> #DIV/0! | DV17: =DG17*DM17*DS17 -> #DIV/0! | DW17: =IF($AP17>0.01,1,0) -> 0 | DY17: =DP17 -> 0 | DZ17: =DK17 -> 0 | EA17: =+AP17 -> 0 | EB17: =DZ17*EA17 -> 0 | ED17: =DY17/EB17 -> #DIV/0! | EE17: =IF($AP17>0.01,1,0) -> 0 | EG17: =DP17 -> 0 | EH17: =K17 -> 0 | EI17: =SUM(M17:Z17) -> 0 | EJ17: =I17 -> 0 | EK17: =(EH17-EI17)*EJ17 -> 0 | EL17: =EG17/EK17 -> #DIV/0! | EM17: =IF(EK17>0.01,1,0) -> 0 | EO17: =EG17 -> 0 | EP17: =EJ17 -> 0 | EQ17: =EO17/(EP17*K17) -> #DIV/0! | ER17: =IF($K17>0.01,1,0) -> 0 | EU17: =DK17 -> 0 | EV17: =CU17 -> 0 | EW17: =I17*CU17 -> 0 | EX17: =DR17 -> 0 | EZ17: =EW17-EX17 -> 0 | FA17: =+IF(EZ17/I17<0,0,(EZ17/I17)) -> #DIV/0!
I18: =IF(E18>0.0001,0,0) -> 0 | K18: =E18*60 -> 0 | AN18: =SUM(M18:AM18) -> 0 | AP18: =K18-AN18 -> 0 | CS18: =SUM(AU18:CR18) -> 0 | CU18: =AP18-CS18 -> 0 | CW18: =(SUM(M18:Z18))/K18 -> #DIV/0! | CX18: =(SUM(AA18:AM18))/K18 -> #DIV/0! | CY18: =(SUM(AU18:BQ18))/$K18 -> #DIV/0! | CZ18: =(SUM(BR18:CC18))/K18 -> #DIV/0! | DA18: =(SUM(CD18:CR18))/K18 -> #DIV/0! | DB18: =CU18/K18 -> #DIV/0! | DD18: =AP18 -> 0 | DE18: =CS18 -> 0 | DF18: =$DD18-DE18 -> 0 | DG18: =DF18/$DD18 -> #DIV/0! | DH18: =IF(AP18>0.01,1,0) -> 0 | DJ18: =H18 -> 0 | DK18: =I18 -> 0 | DL18: =DR18/DF18 -> #DIV/0! | DM18: =DL18/DK18 -> #DIV/0! | DN18: =IF(DM18>0.01,1,0) -> #DIV/0! | DR18: =DP18+DQ18 -> 0 | DS18: =IF(DL18=0,0,DP18/DR18) -> #DIV/0! | DT18: =IF(DS18>0.01,1,0) -> #DIV/0! | DV18: =DG18*DM18*DS18 -> #DIV/0! | DW18: =IF($AP18>0.01,1,0) -> 0 | DY18: =DP18 -> 0 | DZ18: =DK18 -> 0 | EA18: =+AP18 -> 0 | EB18: =DZ18*EA18 -> 0 | ED18: =DY18/EB18 -> #DIV/0! | EE18: =IF($AP18>0.01,1,0) -> 0 | EG18: =DP18 -> 0 | EH18: =K18 -> 0 | EI18: =SUM(M18:Z18) -> 0 | EJ18: =I18 -> 0 | EK18: =(EH18-EI18)*EJ18 -> 0 | EL18: =EG18/EK18 -> #DIV/0! | EM18: =IF(EK18>0.01,1,0) -> 0 | EO18: =EG18 -> 0 | EP18: =EJ18 -> 0 | EQ18: =EO18/(EP18*K18) -> #DIV/0! | ER18: =IF($K18>0.01,1,0) -> 0 | EU18: =DK18 -> 0 | EV18: =CU18 -> 0 | EW18: =I18*CU18 -> 0 | EX18: =DR18 -> 0 | EZ18: =EW18-EX18 -> 0 | FA18: =+IF(EZ18/I18<0,0,(EZ18/I18)) -> #DIV/0!
I19: =IF(E19>0.0001,0,0) -> 0 | K19: =E19*60 -> 0 | AN19: =SUM(M19:AM19) -> 0 | AP19: =K19-AN19 -> 0 | CS19: =SUM(AU19:CR19) -> 0 | CU19: =AP19-CS19 -> 0 | CW19: =(SUM(M19:Z19))/K19 -> #DIV/0! | CX19: =(SUM(AA19:AM19))/K19 -> #DIV/0! | CY19: =(SUM(AU19:BQ19))/$K19 -> #DIV/0! | CZ19: =(SUM(BR19:CC19))/K19 -> #DIV/0! | DA19: =(SUM(CD19:CR19))/K19 -> #DIV/0! | DB19: =CU19/K19 -> #DIV/0! | DD19: =AP19 -> 0 | DE19: =CS19 -> 0 | DF19: =$DD19-DE19 -> 0 | DG19: =DF19/$DD19 -> #DIV/0! | DH19: =IF(AP19>0.01,1,0) -> 0 | DJ19: =H19 -> 0 | DK19: =I19 -> 0 | DL19: =DR19/DF19 -> #DIV/0! | DM19: =DL19/DK19 -> #DIV/0! | DN19: =IF(DM19>0.01,1,0) -> #DIV/0! | DR19: =DP19+DQ19 -> 0 | DS19: =IF(DL19=0,0,DP19/DR19) -> #DIV/0! | DT19: =IF(DS19>0.01,1,0) -> #DIV/0! | DV19: =DG19*DM19*DS19 -> #DIV/0! | DW19: =IF($AP19>0.01,1,0) -> 0 | DY19: =DP19 -> 0 | DZ19: =DK19 -> 0 | EA19: =+AP19 -> 0 | EB19: =DZ19*EA19 -> 0 | ED19: =DY19/EB19 -> #DIV/0! | EE19: =IF($AP19>0.01,1,0) -> 0 | EG19: =DP19 -> 0 | EH19: =K19 -> 0 | EI19: =SUM(M19:Z19) -> 0 | EJ19: =I19 -> 0 | EK19: =(EH19-EI19)*EJ19 -> 0 | EL19: =EG19/EK19 -> #DIV/0! | EM19: =IF(EK19>0.01,1,0) -> 0 | EO19: =EG19 -> 0 | EP19: =EJ19 -> 0 | EQ19: =EO19/(EP19*K19) -> #DIV/0! | ER19: =IF($K19>0.01,1,0) -> 0 | EU19: =DK19 -> 0 | EV19: =CU19 -> 0 | EW19: =I19*CU19 -> 0 | EX19: =DR19 -> 0 | EZ19: =EW19-EX19 -> 0 | FA19: =+IF(EZ19/I19<0,0,(EZ19/I19)) -> #DIV/0!
I20: =IF(E20>0.0001,0,0) -> 0 | K20: =E20*60 -> 0 | AN20: =SUM(M20:AM20) -> 0 | AP20: =K20-AN20 -> 0 | CS20: =SUM(AU20:CR20) -> 0 | CU20: =AP20-CS20 -> 0 | CW20: =(SUM(M20:Z20))/K20 -> #DIV/0! | CX20: =(SUM(AA20:AM20))/K20 -> #DIV/0! | CY20: =(SUM(AU20:BQ20))/$K20 -> #DIV/0! | CZ20: =(SUM(BR20:CC20))/K20 -> #DIV/0! | DA20: =(SUM(CD20:CR20))/K20 -> #DIV/0! | DB20: =CU20/K20 -> #DIV/0! | DD20: =AP20 -> 0 | DE20: =CS20 -> 0 | DF20: =$DD20-DE20 -> 0 | DG20: =DF20/$DD20 -> #DIV/0! | DH20: =IF(AP20>0.01,1,0) -> 0 | DJ20: =H20 -> 0 | DK20: =I20 -> 0 | DL20: =DR20/DF20 -> #DIV/0! | DM20: =DL20/DK20 -> #DIV/0! | DN20: =IF(DM20>0.01,1,0) -> #DIV/0! | DR20: =DP20+DQ20 -> 0 | DS20: =IF(DL20=0,0,DP20/DR20) -> #DIV/0! | DT20: =IF(DS20>0.01,1,0) -> #DIV/0! | DV20: =DG20*DM20*DS20 -> #DIV/0! | DW20: =IF($AP20>0.01,1,0) -> 0 | DY20: =DP20 -> 0 | DZ20: =DK20 -> 0 | EA20: =+AP20 -> 0 | EB20: =DZ20*EA20 -> 0 | ED20: =DY20/EB20 -> #DIV/0! | EE20: =IF($AP20>0.01,1,0) -> 0 | EG20: =DP20 -> 0 | EH20: =K20 -> 0 | EI20: =SUM(M20:Z20) -> 0 | EJ20: =I20 -> 0 | EK20: =(EH20-EI20)*EJ20 -> 0 | EL20: =EG20/EK20 -> #DIV/0! | EM20: =IF(EK20>0.01,1,0) -> 0 | EO20: =EG20 -> 0 | EP20: =EJ20 -> 0 | EQ20: =EO20/(EP20*K20) -> #DIV/0! | ER20: =IF($K20>0.01,1,0) -> 0 | EU20: =DK20 -> 0 | EV20: =CU20 -> 0 | EW20: =I20*CU20 -> 0 | EX20: =DR20 -> 0 | EZ20: =EW20-EX20 -> 0 | FA20: =+IF(EZ20/I20<0,0,(EZ20/I20)) -> #DIV/0!
I21: =IF(E21>0.0001,0,0) -> 0 | K21: =E21*60 -> 0 | AN21: =SUM(M21:AM21) -> 0 | AP21: =K21-AN21 -> 0 | CS21: =SUM(AU21:CR21) -> 0 | CU21: =AP21-CS21 -> 0 | CW21: =(SUM(M21:Z21))/K21 -> #DIV/0! | CX21: =(SUM(AA21:AM21))/K21 -> #DIV/0! | CY21: =(SUM(AU21:BQ21))/$K21 -> #DIV/0! | CZ21: =(SUM(BR21:CC21))/K21 -> #DIV/0! | DA21: =(SUM(CD21:CR21))/K21 -> #DIV/0! | DB21: =CU21/K21 -> #DIV/0! | DD21: =AP21 -> 0 | DE21: =CS21 -> 0 | DF21: =$DD21-DE21 -> 0 | DG21: =DF21/$DD21 -> #DIV/0! | DH21: =IF(AP21>0.01,1,0) -> 0 | DJ21: =H21 -> 0 | DK21: =I21 -> 0 | DL21: =DR21/DF21 -> #DIV/0! | DM21: =DL21/DK21 -> #DIV/0! | DN21: =IF(DM21>0.01,1,0) -> #DIV/0! | DR21: =DP21+DQ21 -> 0 | DS21: =IF(DL21=0,0,DP21/DR21) -> #DIV/0! | DT21: =IF(DS21>0.01,1,0) -> #DIV/0! | DV21: =DG21*DM21*DS21 -> #DIV/0! | DW21: =IF($AP21>0.01,1,0) -> 0 | DY21: =DP21 -> 0 | DZ21: =DK21 -> 0 | EA21: =+AP21 -> 0 | EB21: =DZ21*EA21 -> 0 | ED21: =DY21/EB21 -> #DIV/0! | EE21: =IF($AP21>0.01,1,0) -> 0 | EG21: =DP21 -> 0 | EH21: =K21 -> 0 | EI21: =SUM(M21:Z21) -> 0 | EJ21: =I21 -> 0 | EK21: =(EH21-EI21)*EJ21 -> 0 | EL21: =EG21/EK21 -> #DIV/0! | EM21: =IF(EK21>0.01,1,0) -> 0 | EO21: =EG21 -> 0 | EP21: =EJ21 -> 0 | EQ21: =EO21/(EP21*K21) -> #DIV/0! | ER21: =IF($K21>0.01,1,0) -> 0 | EU21: =DK21 -> 0 | EV21: =CU21 -> 0 | EW21: =I21*CU21 -> 0 | EX21: =DR21 -> 0 | EZ21: =EW21-EX21 -> 0 | FA21: =+IF(EZ21/I21<0,0,(EZ21/I21)) -> #DIV/0!
I22: =IF(E22>0.0001,0,0) -> 0 | K22: =E22*60 -> 0 | AN22: =SUM(M22:AM22) -> 0 | AP22: =K22-AN22 -> 0 | CS22: =SUM(AU22:CR22) -> 0 | CU22: =AP22-CS22 -> 0 | CW22: =(SUM(M22:Z22))/K22 -> #DIV/0! | CX22: =(SUM(AA22:AM22))/K22 -> #DIV/0! | CY22: =(SUM(AU22:BQ22))/$K22 -> #DIV/0! | CZ22: =(SUM(BR22:CC22))/K22 -> #DIV/0! | DA22: =(SUM(CD22:CR22))/K22 -> #DIV/0! | DB22: =CU22/K22 -> #DIV/0! | DD22: =AP22 -> 0 | DE22: =CS22 -> 0 | DF22: =$DD22-DE22 -> 0 | DG22: =DF22/$DD22 -> #DIV/0! | DH22: =IF(AP22>0.01,1,0) -> 0 | DJ22: =H22 -> 0 | DK22: =I22 -> 0 | DL22: =DR22/DF22 -> #DIV/0! | DM22: =DL22/DK22 -> #DIV/0! | DN22: =IF(DM22>0.01,1,0) -> #DIV/0! | DR22: =DP22+DQ22 -> 0 | DS22: =IF(DL22=0,0,DP22/DR22) -> #DIV/0! | DT22: =IF(DS22>0.01,1,0) -> #DIV/0! | DV22: =DG22*DM22*DS22 -> #DIV/0! | DW22: =IF($AP22>0.01,1,0) -> 0 | DY22: =DP22 -> 0 | DZ22: =DK22 -> 0 | EA22: =+AP22 -> 0 | EB22: =DZ22*EA22 -> 0 | ED22: =DY22/EB22 -> #DIV/0! | EE22: =IF($AP22>0.01,1,0) -> 0 | EG22: =DP22 -> 0 | EH22: =K22 -> 0 | EI22: =SUM(M22:Z22) -> 0 | EJ22: =I22 -> 0 | EK22: =(EH22-EI22)*EJ22 -> 0 | EL22: =EG22/EK22 -> #DIV/0! | EM22: =IF(EK22>0.01,1,0) -> 0 | EO22: =EG22 -> 0 | EP22: =EJ22 -> 0 | EQ22: =EO22/(EP22*K22) -> #DIV/0! | ER22: =IF($K22>0.01,1,0) -> 0 | EU22: =DK22 -> 0 | EV22: =CU22 -> 0 | EW22: =I22*CU22 -> 0 | EX22: =DR22 -> 0 | EZ22: =EW22-EX22 -> 0 | FA22: =+IF(EZ22/I22<0,0,(EZ22/I22)) -> #DIV/0!
I23: =IF(E23>0.0001,9.4,0) -> 0 | K23: =E23*60 -> 0 | AN23: =SUM(M23:AM23) -> 0 | AP23: =K23-AN23 -> 0 | CS23: =SUM(AU23:CR23) -> 0 | CU23: =AP23-CS23 -> 0 | CW23: =(SUM(M23:Z23))/K23 -> #DIV/0! | CX23: =(SUM(AA23:AM23))/K23 -> #DIV/0! | CY23: =(SUM(AU23:BQ23))/$K23 -> #DIV/0! | CZ23: =(SUM(BR23:CC23))/K23 -> #DIV/0! | DA23: =(SUM(CD23:CR23))/K23 -> #DIV/0! | DB23: =CU23/K23 -> #DIV/0! | DD23: =AP23 -> 0 | DE23: =CS23 -> 0 | DF23: =$DD23-DE23 -> 0 | DG23: =DF23/$DD23 -> #DIV/0! | DH23: =IF(AP23>0.01,1,0) -> 0 | DJ23: =H23 -> 0 | DK23: =I23 -> 0 | DL23: =DR23/DF23 -> #DIV/0! | DM23: =DL23/DK23 -> #DIV/0! | DN23: =IF(DM23>0.01,1,0) -> #DIV/0! | DR23: =DP23+DQ23 -> 0 | DS23: =IF(DL23=0,0,DP23/DR23) -> #DIV/0! | DT23: =IF(DS23>0.01,1,0) -> #DIV/0! | DV23: =DG23*DM23*DS23 -> #DIV/0! | DW23: =IF($AP23>0.01,1,0) -> 0 | DY23: =DP23 -> 0 | DZ23: =DK23 -> 0 | EA23: =+AP23 -> 0 | EB23: =DZ23*EA23 -> 0 | ED23: =DY23/EB23 -> #DIV/0! | EE23: =IF($AP23>0.01,1,0) -> 0 | EG23: =DP23 -> 0 | EH23: =K23 -> 0 | EI23: =SUM(M23:Z23) -> 0 | EJ23: =I23 -> 0 | EK23: =(EH23-EI23)*EJ23 -> 0 | EL23: =EG23/EK23 -> #DIV/0! | EM23: =IF(EK23>0.01,1,0) -> 0 | EO23: =EG23 -> 0 | EP23: =EJ23 -> 0 | EQ23: =EO23/(EP23*K23) -> #DIV/0! | ER23: =IF($K23>0.01,1,0) -> 0 | EU23: =DK23 -> 0 | EV23: =CU23 -> 0 | EW23: =I23*CU23 -> 0 | EX23: =DR23 -> 0 | EZ23: =EW23-EX23 -> 0 | FA23: =+IF(EZ23/I23<0,0,(EZ23/I23)) -> #DIV/0!
I24: =IF(E24>0.0001,0,0) -> 0 | K24: =E24*60 -> 0 | AN24: =SUM(M24:AM24) -> 0 | AP24: =K24-AN24 -> 0 | CS24: =SUM(AU24:CR24) -> 0 | CU24: =AP24-CS24 -> 0 | CW24: =(SUM(M24:Z24))/K24 -> #DIV/0! | CX24: =(SUM(AA24:AM24))/K24 -> #DIV/0! | CY24: =(SUM(AU24:BQ24))/$K24 -> #DIV/0! | CZ24: =(SUM(BR24:CC24))/K24 -> #DIV/0! | DA24: =(SUM(CD24:CR24))/K24 -> #DIV/0! | DB24: =CU24/K24 -> #DIV/0! | DD24: =AP24 -> 0 | DE24: =CS24 -> 0 | DF24: =$DD24-DE24 -> 0 | DG24: =DF24/$DD24 -> #DIV/0! | DH24: =IF(AP24>0.01,1,0) -> 0 | DJ24: =H24 -> 0 | DK24: =I24 -> 0 | DL24: =DR24/DF24 -> #DIV/0! | DM24: =DL24/DK24 -> #DIV/0! | DN24: =IF(DM24>0.01,1,0) -> #DIV/0! | DR24: =DP24+DQ24 -> 0 | DS24: =IF(DL24=0,0,DP24/DR24) -> #DIV/0! | DT24: =IF(DS24>0.01,1,0) -> #DIV/0! | DV24: =DG24*DM24*DS24 -> #DIV/0! | DW24: =IF($AP24>0.01,1,0) -> 0 | DY24: =DP24 -> 0 | DZ24: =DK24 -> 0 | EA24: =+AP24 -> 0 | EB24: =DZ24*EA24 -> 0 | ED24: =DY24/EB24 -> #DIV/0! | EE24: =IF($AP24>0.01,1,0) -> 0 | EG24: =DP24 -> 0 | EH24: =K24 -> 0 | EI24: =SUM(M24:Z24) -> 0 | EJ24: =I24 -> 0 | EK24: =(EH24-EI24)*EJ24 -> 0 | EL24: =EG24/EK24 -> #DIV/0! | EM24: =IF(EK24>0.01,1,0) -> 0 | EO24: =EG24 -> 0 | EP24: =EJ24 -> 0 | EQ24: =EO24/(EP24*K24) -> #DIV/0! | ER24: =IF($K24>0.01,1,0) -> 0 | EU24: =DK24 -> 0 | EV24: =CU24 -> 0 | EW24: =I24*CU24 -> 0 | EX24: =DR24 -> 0 | EZ24: =EW24-EX24 -> 0 | FA24: =+IF(EZ24/I24<0,0,(EZ24/I24)) -> #DIV/0!
I25: =IF(E25>0.0001,0,0) -> 0 | K25: =E25*60 -> 0 | AN25: =SUM(M25:AM25) -> 0 | AP25: =K25-AN25 -> 0 | CS25: =SUM(AU25:CR25) -> 0 | CU25: =AP25-CS25 -> 0 | CW25: =(SUM(M25:Z25))/K25 -> #DIV/0! | CX25: =(SUM(AA25:AM25))/K25 -> #DIV/0! | CY25: =(SUM(AU25:BQ25))/$K25 -> #DIV/0! | CZ25: =(SUM(BR25:CC25))/K25 -> #DIV/0! | DA25: =(SUM(CD25:CR25))/K25 -> #DIV/0! | DB25: =CU25/K25 -> #DIV/0! | DD25: =AP25 -> 0 | DE25: =CS25 -> 0 | DF25: =$DD25-DE25 -> 0 | DG25: =DF25/$DD25 -> #DIV/0! | DH25: =IF(AP25>0.01,1,0) -> 0 | DJ25: =H25 -> 0 | DK25: =I25 -> 0 | DL25: =DR25/DF25 -> #DIV/0! | DM25: =DL25/DK25 -> #DIV/0! | DN25: =IF(DM25>0.01,1,0) -> #DIV/0! | DR25: =DP25+DQ25 -> 0 | DS25: =IF(DL25=0,0,DP25/DR25) -> #DIV/0! | DT25: =IF(DS25>0.01,1,0) -> #DIV/0! | DV25: =DG25*DM25*DS25 -> #DIV/0! | DW25: =IF($AP25>0.01,1,0) -> 0 | DY25: =DP25 -> 0 | DZ25: =DK25 -> 0 | EA25: =+AP25 -> 0 | EB25: =DZ25*EA25 -> 0 | ED25: =DY25/EB25 -> #DIV/0! | EE25: =IF($AP25>0.01,1,0) -> 0 | EG25: =DP25 -> 0 | EH25: =K25 -> 0 | EI25: =SUM(M25:Z25) -> 0 | EJ25: =I25 -> 0 | EK25: =(EH25-EI25)*EJ25 -> 0 | EL25: =EG25/EK25 -> #DIV/0! | EM25: =IF(EK25>0.01,1,0) -> 0 | EO25: =EG25 -> 0 | EP25: =EJ25 -> 0 | EQ25: =EO25/(EP25*K25) -> #DIV/0! | ER25: =IF($K25>0.01,1,0) -> 0 | EU25: =DK25 -> 0 | EV25: =CU25 -> 0 | EW25: =I25*CU25 -> 0 | EX25: =DR25 -> 0 | EZ25: =EW25-EX25 -> 0 | FA25: =+IF(EZ25/I25<0,0,(EZ25/I25)) -> #DIV/0!
A26: 0 | I26: =IF(E26>0.0001,9.4,0) -> 0 | K26: =E26*60 -> 0 | AN26: =SUM(M26:AM26) -> 0 | AP26: =K26-AN26 -> 0 | CS26: =SUM(AU26:CR26) -> 0 | CU26: =AP26-CS26 -> 0 | CW26: =(SUM(M26:Z26))/K26 -> #DIV/0! | CX26: =(SUM(AA26:AM26))/K26 -> #DIV/0! | CY26: =(SUM(AU26:BQ26))/$K26 -> #DIV/0! | CZ26: =(SUM(BR26:CC26))/K26 -> #DIV/0! | DA26: =(SUM(CD26:CR26))/K26 -> #DIV/0! | DB26: =CU26/K26 -> #DIV/0! | DD26: =AP26 -> 0 | DE26: =CS26 -> 0 | DF26: =$DD26-DE26 -> 0 | DG26: =DF26/$DD26 -> #DIV/0! | DH26: =IF(AP26>0.01,1,0) -> 0 | DJ26: =H26 -> 0 | DK26: =I26 -> 0 | DL26: =DR26/DF26 -> #DIV/0! | DM26: =DL26/DK26 -> #DIV/0! | DN26: =IF(DM26>0.01,1,0) -> #DIV/0! | DR26: =DP26+DQ26 -> 0 | DS26: =IF(DL26=0,0,DP26/DR26) -> #DIV/0! | DT26: =IF(DS26>0.01,1,0) -> #DIV/0! | DV26: =DG26*DM26*DS26 -> #DIV/0! | DW26: =IF($AP26>0.01,1,0) -> 0 | DY26: =DP26 -> 0 | DZ26: =DK26 -> 0 | EA26: =+AP26 -> 0 | EB26: =DZ26*EA26 -> 0 | ED26: =DY26/EB26 -> #DIV/0! | EE26: =IF($AP26>0.01,1,0) -> 0 | EG26: =DP26 -> 0 | EH26: =K26 -> 0 | EI26: =SUM(M26:Z26) -> 0 | EJ26: =I26 -> 0 | EK26: =(EH26-EI26)*EJ26 -> 0 | EL26: =EG26/EK26 -> #DIV/0! | EM26: =IF(EK26>0.01,1,0) -> 0 | EO26: =EG26 -> 0 | EP26: =EJ26 -> 0 | EQ26: =EO26/(EP26*K26) -> #DIV/0! | ER26: =IF($K26>0.01,1,0) -> 0 | EU26: =DK26 -> 0 | EV26: =CU26 -> 0 | EW26: =I26*CU26 -> 0 | EX26: =DR26 -> 0 | EZ26: =EW26-EX26 -> 0 | FA26: =+IF(EZ26/I26<0,0,(EZ26/I26)) -> #DIV/0!
I27: =IF(E27>0.0001,0,0) -> 0 | K27: =E27*60 -> 0 | AN27: =SUM(M27:AM27) -> 0 | AP27: =K27-AN27 -> 0 | CS27: =SUM(AU27:CR27) -> 0 | CU27: =AP27-CS27 -> 0 | CW27: =(SUM(M27:Z27))/K27 -> #DIV/0! | CX27: =(SUM(AA27:AM27))/K27 -> #DIV/0! | CY27: =(SUM(AU27:BQ27))/$K27 -> #DIV/0! | CZ27: =(SUM(BR27:CC27))/K27 -> #DIV/0! | DA27: =(SUM(CD27:CR27))/K27 -> #DIV/0! | DB27: =CU27/K27 -> #DIV/0! | DD27: =AP27 -> 0 | DE27: =CS27 -> 0 | DF27: =$DD27-DE27 -> 0 | DG27: =DF27/$DD27 -> #DIV/0! | DH27: =IF(AP27>0.01,1,0) -> 0 | DJ27: =H27 -> 0 | DK27: =I27 -> 0 | DL27: =DR27/DF27 -> #DIV/0! | DM27: =DL27/DK27 -> #DIV/0! | DN27: =IF(DM27>0.01,1,0) -> #DIV/0! | DR27: =DP27+DQ27 -> 0 | DS27: =IF(DL27=0,0,DP27/DR27) -> #DIV/0! | DT27: =IF(DS27>0.01,1,0) -> #DIV/0! | DV27: =DG27*DM27*DS27 -> #DIV/0! | DW27: =IF($AP27>0.01,1,0) -> 0 | DY27: =DP27 -> 0 | DZ27: =DK27 -> 0 | EA27: =+AP27 -> 0 | EB27: =DZ27*EA27 -> 0 | ED27: =DY27/EB27 -> #DIV/0! | EE27: =IF($AP27>0.01,1,0) -> 0 | EG27: =DP27 -> 0 | EH27: =K27 -> 0 | EI27: =SUM(M27:Z27) -> 0 | EJ27: =I27 -> 0 | EK27: =(EH27-EI27)*EJ27 -> 0 | EL27: =EG27/EK27 -> #DIV/0! | EM27: =IF(EK27>0.01,1,0) -> 0 | EO27: =EG27 -> 0 | EP27: =EJ27 -> 0 | EQ27: =EO27/(EP27*K27) -> #DIV/0! | ER27: =IF($K27>0.01,1,0) -> 0 | EU27: =DK27 -> 0 | EV27: =CU27 -> 0 | EW27: =I27*CU27 -> 0 | EX27: =DR27 -> 0 | EZ27: =EW27-EX27 -> 0 | FA27: =+IF(EZ27/I27<0,0,(EZ27/I27)) -> #DIV/0!
I28: =IF(E28>0.0001,0,0) -> 0 | K28: =E28*60 -> 0 | AN28: =SUM(M28:AM28) -> 0 | AP28: =K28-AN28 -> 0 | CS28: =SUM(AU28:CR28) -> 0 | CU28: =AP28-CS28 -> 0 | CW28: =(SUM(M28:Z28))/K28 -> #DIV/0! | CX28: =(SUM(AA28:AM28))/K28 -> #DIV/0! | CY28: =(SUM(AU28:BQ28))/$K28 -> #DIV/0! | CZ28: =(SUM(BR28:CC28))/K28 -> #DIV/0! | DA28: =(SUM(CD28:CR28))/K28 -> #DIV/0! | DB28: =CU28/K28 -> #DIV/0! | DD28: =AP28 -> 0 | DE28: =CS28 -> 0 | DF28: =$DD28-DE28 -> 0 | DG28: =DF28/$DD28 -> #DIV/0! | DH28: =IF(AP28>0.01,1,0) -> 0 | DJ28: =H28 -> 0 | DK28: =I28 -> 0 | DL28: =DR28/DF28 -> #DIV/0! | DM28: =DL28/DK28 -> #DIV/0! | DN28: =IF(DM28>0.01,1,0) -> #DIV/0! | DR28: =DP28+DQ28 -> 0 | DS28: =IF(DL28=0,0,DP28/DR28) -> #DIV/0! | DT28: =IF(DS28>0.01,1,0) -> #DIV/0! | DV28: =DG28*DM28*DS28 -> #DIV/0! | DW28: =IF($AP28>0.01,1,0) -> 0 | DY28: =DP28 -> 0 | DZ28: =DK28 -> 0 | EA28: =+AP28 -> 0 | EB28: =DZ28*EA28 -> 0 | ED28: =DY28/EB28 -> #DIV/0! | EE28: =IF($AP28>0.01,1,0) -> 0 | EG28: =DP28 -> 0 | EH28: =K28 -> 0 | EI28: =SUM(M28:Z28) -> 0 | EJ28: =I28 -> 0 | EK28: =(EH28-EI28)*EJ28 -> 0 | EL28: =EG28/EK28 -> #DIV/0! | EM28: =IF(EK28>0.01,1,0) -> 0 | EO28: =EG28 -> 0 | EP28: =EJ28 -> 0 | EQ28: =EO28/(EP28*K28) -> #DIV/0! | ER28: =IF($K28>0.01,1,0) -> 0 | EU28: =DK28 -> 0 | EV28: =CU28 -> 0 | EW28: =I28*CU28 -> 0 | EX28: =DR28 -> 0 | EZ28: =EW28-EX28 -> 0 | FA28: =+IF(EZ28/I28<0,0,(EZ28/I28)) -> #DIV/0!
I29: =IF(E29>0.0001,0,0) -> 0 | K29: =E29*60 -> 0 | AN29: =SUM(M29:AM29) -> 0 | AP29: =K29-AN29 -> 0 | CS29: =SUM(AU29:CR29) -> 0 | CU29: =AP29-CS29 -> 0 | CW29: =(SUM(M29:Z29))/K29 -> #DIV/0! | CX29: =(SUM(AA29:AM29))/K29 -> #DIV/0! | CY29: =(SUM(AU29:BQ29))/$K29 -> #DIV/0! | CZ29: =(SUM(BR29:CC29))/K29 -> #DIV/0! | DA29: =(SUM(CD29:CR29))/K29 -> #DIV/0! | DB29: =CU29/K29 -> #DIV/0! | DD29: =AP29 -> 0 | DE29: =CS29 -> 0 | DF29: =$DD29-DE29 -> 0 | DG29: =DF29/$DD29 -> #DIV/0! | DH29: =IF(AP29>0.01,1,0) -> 0 | DJ29: =H29 -> 0 | DK29: =I29 -> 0 | DL29: =DR29/DF29 -> #DIV/0! | DM29: =DL29/DK29 -> #DIV/0! | DN29: =IF(DM29>0.01,1,0) -> #DIV/0! | DR29: =DP29+DQ29 -> 0 | DS29: =IF(DL29=0,0,DP29/DR29) -> #DIV/0! | DT29: =IF(DS29>0.01,1,0) -> #DIV/0! | DV29: =DG29*DM29*DS29 -> #DIV/0! | DW29: =IF($AP29>0.01,1,0) -> 0 | DY29: =DP29 -> 0 | DZ29: =DK29 -> 0 | EA29: =+AP29 -> 0 | EB29: =DZ29*EA29 -> 0 | ED29: =DY29/EB29 -> #DIV/0! | EE29: =IF($AP29>0.01,1,0) -> 0 | EG29: =DP29 -> 0 | EH29: =K29 -> 0 | EI29: =SUM(M29:Z29) -> 0 | EJ29: =I29 -> 0 | EK29: =(EH29-EI29)*EJ29 -> 0 | EL29: =EG29/EK29 -> #DIV/0! | EM29: =IF(EK29>0.01,1,0) -> 0 | EO29: =EG29 -> 0 | EP29: =EJ29 -> 0 | EQ29: =EO29/(EP29*K29) -> #DIV/0! | ER29: =IF($K29>0.01,1,0) -> 0 | EU29: =DK29 -> 0 | EV29: =CU29 -> 0 | EW29: =I29*CU29 -> 0 | EX29: =DR29 -> 0 | EZ29: =EW29-EX29 -> 0 | FA29: =+IF(EZ29/I29<0,0,(EZ29/I29)) -> #DIV/0!
I30: =IF(E30>0.0001,0,0) -> 0 | K30: =E30*60 -> 0 | AN30: =SUM(M30:AM30) -> 0 | AP30: =K30-AN30 -> 0 | CS30: =SUM(AU30:CR30) -> 0 | CU30: =AP30-CS30 -> 0 | CW30: =(SUM(M30:Z30))/K30 -> #DIV/0! | CX30: =(SUM(AA30:AM30))/K30 -> #DIV/0! | CY30: =(SUM(AU30:BQ30))/$K30 -> #DIV/0! | CZ30: =(SUM(BR30:CC30))/K30 -> #DIV/0! | DA30: =(SUM(CD30:CR30))/K30 -> #DIV/0! | DB30: =CU30/K30 -> #DIV/0! | DD30: =AP30 -> 0 | DE30: =CS30 -> 0 | DF30: =$DD30-DE30 -> 0 | DG30: =DF30/$DD30 -> #DIV/0! | DH30: =IF(AP30>0.01,1,0) -> 0 | DJ30: =H30 -> 0 | DK30: =I30 -> 0 | DL30: =DR30/DF30 -> #DIV/0! | DM30: =DL30/DK30 -> #DIV/0! | DN30: =IF(DM30>0.01,1,0) -> #DIV/0! | DR30: =DP30+DQ30 -> 0 | DS30: =IF(DL30=0,0,DP30/DR30) -> #DIV/0! | DT30: =IF(DS30>0.01,1,0) -> #DIV/0! | DV30: =DG30*DM30*DS30 -> #DIV/0! | DW30: =IF($AP30>0.01,1,0) -> 0 | DY30: =DP30 -> 0 | DZ30: =DK30 -> 0 | EA30: =+AP30 -> 0 | EB30: =DZ30*EA30 -> 0 | ED30: =DY30/EB30 -> #DIV/0! | EE30: =IF($AP30>0.01,1,0) -> 0 | EG30: =DP30 -> 0 | EH30: =K30 -> 0 | EI30: =SUM(M30:Z30) -> 0 | EJ30: =I30 -> 0 | EK30: =(EH30-EI30)*EJ30 -> 0 | EL30: =EG30/EK30 -> #DIV/0! | EM30: =IF(EK30>0.01,1,0) -> 0 | EO30: =EG30 -> 0 | EP30: =EJ30 -> 0 | EQ30: =EO30/(EP30*K30) -> #DIV/0! | ER30: =IF($K30>0.01,1,0) -> 0 | EU30: =DK30 -> 0 | EV30: =CU30 -> 0 | EW30: =I30*CU30 -> 0 | EX30: =DR30 -> 0 | EZ30: =EW30-EX30 -> 0 | FA30: =+IF(EZ30/I30<0,0,(EZ30/I30)) -> #DIV/0!
I31: =IF(E31>0.0001,0,0) -> 0 | K31: =E31*60 -> 0 | AN31: =SUM(M31:AM31) -> 0 | AP31: =K31-AN31 -> 0 | CS31: =SUM(AU31:CR31) -> 0 | CU31: =AP31-CS31 -> 0 | CW31: =(SUM(M31:Z31))/K31 -> #DIV/0! | CX31: =(SUM(AA31:AM31))/K31 -> #DIV/0! | CY31: =(SUM(AU31:BQ31))/$K31 -> #DIV/0! | CZ31: =(SUM(BR31:CC31))/K31 -> #DIV/0! | DA31: =(SUM(CD31:CR31))/K31 -> #DIV/0! | DB31: =CU31/K31 -> #DIV/0! | DD31: =AP31 -> 0 | DE31: =CS31 -> 0 | DF31: =$DD31-DE31 -> 0 | DG31: =DF31/$DD31 -> #DIV/0! | DH31: =IF(AP31>0.01,1,0) -> 0 | DJ31: =H31 -> 0 | DK31: =I31 -> 0 | DL31: =DR31/DF31 -> #DIV/0! | DM31: =DL31/DK31 -> #DIV/0! | DN31: =IF(DM31>0.01,1,0) -> #DIV/0! | DR31: =DP31+DQ31 -> 0 | DS31: =IF(DL31=0,0,DP31/DR31) -> #DIV/0! | DT31: =IF(DS31>0.01,1,0) -> #DIV/0! | DV31: =DG31*DM31*DS31 -> #DIV/0! | DW31: =IF($AP31>0.01,1,0) -> 0 | DY31: =DP31 -> 0 | DZ31: =DK31 -> 0 | EA31: =+AP31 -> 0 | EB31: =DZ31*EA31 -> 0 | ED31: =DY31/EB31 -> #DIV/0! | EE31: =IF($AP31>0.01,1,0) -> 0 | EG31: =DP31 -> 0 | EH31: =K31 -> 0 | EI31: =SUM(M31:Z31) -> 0 | EJ31: =I31 -> 0 | EK31: =(EH31-EI31)*EJ31 -> 0 | EL31: =EG31/EK31 -> #DIV/0! | EM31: =IF(EK31>0.01,1,0) -> 0 | EO31: =EG31 -> 0 | EP31: =EJ31 -> 0 | EQ31: =EO31/(EP31*K31) -> #DIV/0! | ER31: =IF($K31>0.01,1,0) -> 0 | EU31: =DK31 -> 0 | EV31: =CU31 -> 0 | EW31: =I31*CU31 -> 0 | EX31: =DR31 -> 0 | EZ31: =EW31-EX31 -> 0 | FA31: =+IF(EZ31/I31<0,0,(EZ31/I31)) -> #DIV/0!
I32: =IF(E32>0.0001,12.5,0) -> 0 | K32: =E32*60 -> 0 | AN32: =SUM(M32:AM32) -> 0 | AP32: =K32-AN32 -> 0 | CS32: =SUM(AU32:CR32) -> 0 | CU32: =AP32-CS32 -> 0 | CW32: =(SUM(M32:Z32))/K32 -> #DIV/0! | CX32: =(SUM(AA32:AM32))/K32 -> #DIV/0! | CY32: =(SUM(AU32:BQ32))/$K32 -> #DIV/0! | CZ32: =(SUM(BR32:CC32))/K32 -> #DIV/0! | DA32: =(SUM(CD32:CR32))/K32 -> #DIV/0! | DB32: =CU32/K32 -> #DIV/0! | DD32: =AP32 -> 0 | DE32: =CS32 -> 0 | DF32: =$DD32-DE32 -> 0 | DG32: =DF32/$DD32 -> #DIV/0! | DH32: =IF(AP32>0.01,1,0) -> 0 | DJ32: =H32 -> 0 | DK32: =I32 -> 0 | DL32: =DR32/DF32 -> #DIV/0! | DM32: =DL32/DK32 -> #DIV/0! | DN32: =IF(DM32>0.01,1,0) -> #DIV/0! | DR32: =DP32+DQ32 -> 0 | DS32: =IF(DL32=0,0,DP32/DR32) -> #DIV/0! | DT32: =IF(DS32>0.01,1,0) -> #DIV/0! | DV32: =DG32*DM32*DS32 -> #DIV/0! | DW32: =IF($AP32>0.01,1,0) -> 0 | DY32: =DP32 -> 0 | DZ32: =DK32 -> 0 | EA32: =+AP32 -> 0 | EB32: =DZ32*EA32 -> 0 | ED32: =DY32/EB32 -> #DIV/0! | EE32: =IF($AP32>0.01,1,0) -> 0 | EG32: =DP32 -> 0 | EH32: =K32 -> 0 | EI32: =SUM(M32:Z32) -> 0 | EJ32: =I32 -> 0 | EK32: =(EH32-EI32)*EJ32 -> 0 | EL32: =EG32/EK32 -> #DIV/0! | EM32: =IF(EK32>0.01,1,0) -> 0 | EO32: =EG32 -> 0 | EP32: =EJ32 -> 0 | EQ32: =EO32/(EP32*K32) -> #DIV/0! | ER32: =IF($K32>0.01,1,0) -> 0 | EU32: =DK32 -> 0 | EV32: =CU32 -> 0 | EW32: =I32*CU32 -> 0 | EX32: =DR32 -> 0 | EZ32: =EW32-EX32 -> 0 | FA32: =+IF(EZ32/I32<0,0,(EZ32/I32)) -> #DIV/0!
I33: =IF(E33>0.0001,12.5,0) -> 0 | K33: =E33*60 -> 0 | AN33: =SUM(M33:AM33) -> 0 | AP33: =K33-AN33 -> 0 | CS33: =SUM(AU33:CR33) -> 0 | CU33: =AP33-CS33 -> 0 | CW33: =(SUM(M33:Z33))/K33 -> #DIV/0! | CX33: =(SUM(AA33:AM33))/K33 -> #DIV/0! | CY33: =(SUM(AU33:BQ33))/$K33 -> #DIV/0! | CZ33: =(SUM(BR33:CC33))/K33 -> #DIV/0! | DA33: =(SUM(CD33:CR33))/K33 -> #DIV/0! | DB33: =CU33/K33 -> #DIV/0! | DD33: =AP33 -> 0 | DE33: =CS33 -> 0 | DF33: =$DD33-DE33 -> 0 | DG33: =DF33/$DD33 -> #DIV/0! | DH33: =IF(AP33>0.01,1,0) -> 0 | DJ33: =H33 -> 0 | DK33: =I33 -> 0 | DL33: =DR33/DF33 -> #DIV/0! | DM33: =DL33/DK33 -> #DIV/0! | DN33: =IF(DM33>0.01,1,0) -> #DIV/0! | DR33: =DP33+DQ33 -> 0 | DS33: =IF(DL33=0,0,DP33/DR33) -> #DIV/0! | DT33: =IF(DS33>0.01,1,0) -> #DIV/0! | DV33: =DG33*DM33*DS33 -> #DIV/0! | DW33: =IF($AP33>0.01,1,0) -> 0 | DY33: =DP33 -> 0 | DZ33: =DK33 -> 0 | EA33: =+AP33 -> 0 | EB33: =DZ33*EA33 -> 0 | ED33: =DY33/EB33 -> #DIV/0! | EE33: =IF($AP33>0.01,1,0) -> 0 | EG33: =DP33 -> 0 | EH33: =K33 -> 0 | EI33: =SUM(M33:Z33) -> 0 | EJ33: =I33 -> 0 | EK33: =(EH33-EI33)*EJ33 -> 0 | EL33: =EG33/EK33 -> #DIV/0! | EM33: =IF(EK33>0.01,1,0) -> 0 | EO33: =EG33 -> 0 | EP33: =EJ33 -> 0 | EQ33: =EO33/(EP33*K33) -> #DIV/0! | ER33: =IF($K33>0.01,1,0) -> 0 | EU33: =DK33 -> 0 | EV33: =CU33 -> 0 | EW33: =I33*CU33 -> 0 | EX33: =DR33 -> 0 | EZ33: =EW33-EX33 -> 0 | FA33: =+IF(EZ33/I33<0,0,(EZ33/I33)) -> #DIV/0!
I34: =IF(E34>0.0001,0,0) -> 0 | K34: =E34*60 -> 0 | AN34: =SUM(M34:AM34) -> 0 | AP34: =K34-AN34 -> 0 | CS34: =SUM(AU34:CR34) -> 0 | CU34: =AP34-CS34 -> 0 | CW34: =(SUM(M34:Z34))/K34 -> #DIV/0! | CX34: =(SUM(AA34:AM34))/K34 -> #DIV/0! | CY34: =(SUM(AU34:BQ34))/$K34 -> #DIV/0! | CZ34: =(SUM(BR34:CC34))/K34 -> #DIV/0! | DA34: =(SUM(CD34:CR34))/K34 -> #DIV/0! | DB34: =CU34/K34 -> #DIV/0! | DD34: =AP34 -> 0 | DE34: =CS34 -> 0 | DF34: =$DD34-DE34 -> 0 | DG34: =DF34/$DD34 -> #DIV/0! | DH34: =IF(AP34>0.01,1,0) -> 0 | DJ34: =H34 -> 0 | DK34: =I34 -> 0 | DL34: =DR34/DF34 -> #DIV/0! | DM34: =DL34/DK34 -> #DIV/0! | DN34: =IF(DM34>0.01,1,0) -> #DIV/0! | DR34: =DP34+DQ34 -> 0 | DS34: =IF(DL34=0,0,DP34/DR34) -> #DIV/0! | DT34: =IF(DS34>0.01,1,0) -> #DIV/0! | DV34: =DG34*DM34*DS34 -> #DIV/0! | DW34: =IF($AP34>0.01,1,0) -> 0 | DY34: =DP34 -> 0 | DZ34: =DK34 -> 0 | EA34: =+AP34 -> 0 | EB34: =DZ34*EA34 -> 0 | ED34: =DY34/EB34 -> #DIV/0! | EE34: =IF($AP34>0.01,1,0) -> 0 | EG34: =DP34 -> 0 | EH34: =K34 -> 0 | EI34: =SUM(M34:Z34) -> 0 | EJ34: =I34 -> 0 | EK34: =(EH34-EI34)*EJ34 -> 0 | EL34: =EG34/EK34 -> #DIV/0! | EM34: =IF(EK34>0.01,1,0) -> 0 | EO34: =EG34 -> 0 | EP34: =EJ34 -> 0 | EQ34: =EO34/(EP34*K34) -> #DIV/0! | ER34: =IF($K34>0.01,1,0) -> 0 | EU34: =DK34 -> 0 | EV34: =CU34 -> 0 | EW34: =I34*CU34 -> 0 | EX34: =DR34 -> 0 | EZ34: =EW34-EX34 -> 0 | FA34: =+IF(EZ34/I34<0,0,(EZ34/I34)) -> #DIV/0!
I35: =IF(E35>0.0001,12.5,0) -> 0 | K35: =E35*60 -> 0 | AN35: =SUM(M35:AM35) -> 0 | AP35: =K35-AN35 -> 0 | CS35: =SUM(AU35:CR35) -> 0 | CU35: =AP35-CS35 -> 0 | CW35: =(SUM(M35:Z35))/K35 -> #DIV/0! | CX35: =(SUM(AA35:AM35))/K35 -> #DIV/0! | CY35: =(SUM(AU35:BQ35))/$K35 -> #DIV/0! | CZ35: =(SUM(BR35:CC35))/K35 -> #DIV/0! | DA35: =(SUM(CD35:CR35))/K35 -> #DIV/0! | DB35: =CU35/K35 -> #DIV/0! | DD35: =AP35 -> 0 | DE35: =CS35 -> 0 | DF35: =$DD35-DE35 -> 0 | DG35: =DF35/$DD35 -> #DIV/0! | DH35: =IF(AP35>0.01,1,0) -> 0 | DJ35: =H35 -> 0 | DK35: =I35 -> 0 | DL35: =DR35/DF35 -> #DIV/0! | DM35: =DL35/DK35 -> #DIV/0! | DN35: =IF(DM35>0.01,1,0) -> #DIV/0! | DR35: =DP35+DQ35 -> 0 | DS35: =IF(DL35=0,0,DP35/DR35) -> #DIV/0! | DT35: =IF(DS35>0.01,1,0) -> #DIV/0! | DV35: =DG35*DM35*DS35 -> #DIV/0! | DW35: =IF($AP35>0.01,1,0) -> 0 | DY35: =DP35 -> 0 | DZ35: =DK35 -> 0 | EA35: =+AP35 -> 0 | EB35: =DZ35*EA35 -> 0 | ED35: =DY35/EB35 -> #DIV/0! | EE35: =IF($AP35>0.01,1,0) -> 0 | EG35: =DP35 -> 0 | EH35: =K35 -> 0 | EI35: =SUM(M35:Z35) -> 0 | EJ35: =I35 -> 0 | EK35: =(EH35-EI35)*EJ35 -> 0 | EL35: =EG35/EK35 -> #DIV/0! | EM35: =IF(EK35>0.01,1,0) -> 0 | EO35: =EG35 -> 0 | EP35: =EJ35 -> 0 | EQ35: =EO35/(EP35*K35) -> #DIV/0! | ER35: =IF($K35>0.01,1,0) -> 0 | EU35: =DK35 -> 0 | EV35: =CU35 -> 0 | EW35: =I35*CU35 -> 0 | EX35: =DR35 -> 0 | EZ35: =EW35-EX35 -> 0 | FA35: =+IF(EZ35/I35<0,0,(EZ35/I35)) -> #DIV/0!
I36: =IF(E36>0.0001,0,0) -> 0 | K36: =E36*60 -> 0 | AN36: =SUM(M36:AM36) -> 0 | AP36: =K36-AN36 -> 0 | CS36: =SUM(AU36:CR36) -> 0 | CU36: =AP36-CS36 -> 0 | CW36: =(SUM(M36:Z36))/K36 -> #DIV/0! | CX36: =(SUM(AA36:AM36))/K36 -> #DIV/0! | CY36: =(SUM(AU36:BQ36))/$K36 -> #DIV/0! | CZ36: =(SUM(BR36:CC36))/K36 -> #DIV/0! | DA36: =(SUM(CD36:CR36))/K36 -> #DIV/0! | DB36: =CU36/K36 -> #DIV/0! | DD36: =AP36 -> 0 | DE36: =CS36 -> 0 | DF36: =$DD36-DE36 -> 0 | DG36: =DF36/$DD36 -> #DIV/0! | DH36: =IF(AP36>0.01,1,0) -> 0 | DJ36: =H36 -> 0 | DK36: 0 | DL36: =DR36/DF36 -> #DIV/0! | DM36: =DL36/DK36 -> #DIV/0! | DN36: =IF(DM36>0.01,1,0) -> #DIV/0! | DR36: =DP36+DQ36 -> 0 | DS36: =IF(DL36=0,0,DP36/DR36) -> #DIV/0! | DT36: =IF(DS36>0.01,1,0) -> #DIV/0! | DV36: =DG36*DM36*DS36 -> #DIV/0! | DW36: =IF($AP36>0.01,1,0) -> 0 | DY36: =DP36 -> 0 | DZ36: =DK36 -> 0 | EA36: =+AP36 -> 0 | EB36: =DZ36*EA36 -> 0 | ED36: =DY36/EB36 -> #DIV/0! | EE36: =IF($AP36>0.01,1,0) -> 0 | EG36: =DP36 -> 0 | EH36: =K36 -> 0 | EI36: =SUM(M36:Z36) -> 0 | EJ36: =I36 -> 0 | EK36: =(EH36-EI36)*EJ36 -> 0 | EL36: =EG36/EK36 -> #DIV/0! | EM36: =IF(EK36>0.01,1,0) -> 0 | EO36: =EG36 -> 0 | EP36: =EJ36 -> 0 | EQ36: =EO36/(EP36*K36) -> #DIV/0! | ER36: =IF($K36>0.01,1,0) -> 0 | EU36: =DK36 -> 0 | EV36: =CU36 -> 0 | EW36: =I36*CU36 -> 0 | EX36: =DR36 -> 0 | EZ36: =EW36-EX36 -> 0 | FA36: =+IF(EZ36/I36<0,0,(EZ36/I36)) -> #DIV/0!
I37: =IF(E37>0.0001,0,0) -> 0 | K37: =E37*60 -> 0 | AN37: =SUM(M37:AM37) -> 0 | AP37: =K37-AN37 -> 0 | CS37: =SUM(AU37:CR37) -> 0 | CU37: =AP37-CS37 -> 0 | CW37: =(SUM(M37:Z37))/K37 -> #DIV/0! | CX37: =(SUM(AA37:AM37))/K37 -> #DIV/0! | CY37: =(SUM(AU37:BQ37))/$K37 -> #DIV/0! | CZ37: =(SUM(BR37:CC37))/K37 -> #DIV/0! | DA37: =(SUM(CD37:CR37))/K37 -> #DIV/0! | DB37: =CU37/K37 -> #DIV/0! | DD37: =AP37 -> 0 | DE37: =CS37 -> 0 | DF37: =$DD37-DE37 -> 0 | DG37: =DF37/$DD37 -> #DIV/0! | DH37: =IF(AP37>0.01,1,0) -> 0 | DJ37: =H37 -> 0 | DK37: 0 | DL37: =DR37/DF37 -> #DIV/0! | DM37: =DL37/DK37 -> #DIV/0! | DN37: =IF(DM37>0.01,1,0) -> #DIV/0! | DR37: =DP37+DQ37 -> 0 | DS37: =IF(DL37=0,0,DP37/DR37) -> #DIV/0! | DT37: =IF(DS37>0.01,1,0) -> #DIV/0! | DV37: =DG37*DM37*DS37 -> #DIV/0! | DW37: =IF($AP37>0.01,1,0) -> 0 | DY37: =DP37 -> 0 | DZ37: =DK37 -> 0 | EA37: =+AP37 -> 0 | EB37: =DZ37*EA37 -> 0 | ED37: =DY37/EB37 -> #DIV/0! | EE37: =IF($AP37>0.01,1,0) -> 0 | EG37: =DP37 -> 0 | EH37: =K37 -> 0 | EI37: =SUM(M37:Z37) -> 0 | EJ37: =I37 -> 0 | EK37: =(EH37-EI37)*EJ37 -> 0 | EL37: =EG37/EK37 -> #DIV/0! | EM37: =IF(EK37>0.01,1,0) -> 0 | EO37: =EG37 -> 0 | EP37: =EJ37 -> 0 | EQ37: =EO37/(EP37*K37) -> #DIV/0! | ER37: =IF($K37>0.01,1,0) -> 0 | EU37: =DK37 -> 0 | EV37: =CU37 -> 0 | EW37: =I37*CU37 -> 0 | EX37: =DR37 -> 0 | EZ37: =EW37-EX37 -> 0 | FA37: =+IF(EZ37/I37<0,0,(EZ37/I37)) -> #DIV/0!
I38: =IF(E38>0.0001,0,0) -> 0 | K38: =E38*60 -> 0 | AN38: =SUM(M38:AM38) -> 0 | AP38: =K38-AN38 -> 0 | CS38: =SUM(AU38:CR38) -> 0 | CU38: =AP38-CS38 -> 0 | CW38: =(SUM(M38:Z38))/K38 -> #DIV/0! | CX38: =(SUM(AA38:AM38))/K38 -> #DIV/0! | CY38: =(SUM(AU38:BQ38))/$K38 -> #DIV/0! | CZ38: =(SUM(BR38:CC38))/K38 -> #DIV/0! | DA38: =(SUM(CD38:CR38))/K38 -> #DIV/0! | DB38: =CU38/K38 -> #DIV/0! | DD38: =AP38 -> 0 | DE38: =CS38 -> 0 | DF38: =$DD38-DE38 -> 0 | DG38: =DF38/$DD38 -> #DIV/0! | DH38: =IF(AP38>0.01,1,0) -> 0 | DJ38: =H38 -> 0 | DK38: =I38 -> 0 | DL38: =DR38/DF38 -> #DIV/0! | DM38: =DL38/DK38 -> #DIV/0! | DN38: =IF(DM38>0.01,1,0) -> #DIV/0! | DR38: =DP38+DQ38 -> 0 | DS38: =IF(DL38=0,0,DP38/DR38) -> #DIV/0! | DT38: =IF(DS38>0.01,1,0) -> #DIV/0! | DV38: =DG38*DM38*DS38 -> #DIV/0! | DW38: =IF($AP38>0.01,1,0) -> 0 | DY38: =DP38 -> 0 | DZ38: =DK38 -> 0 | EA38: =+AP38 -> 0 | EB38: =DZ38*EA38 -> 0 | ED38: =DY38/EB38 -> #DIV/0! | EE38: =IF($AP38>0.01,1,0) -> 0 | EG38: =DP38 -> 0 | EH38: =K38 -> 0 | EI38: =SUM(M38:Z38) -> 0 | EJ38: =I38 -> 0 | EK38: =(EH38-EI38)*EJ38 -> 0 | EL38: =EG38/EK38 -> #DIV/0! | EM38: =IF(EK38>0.01,1,0) -> 0 | EO38: =EG38 -> 0 | EP38: =EJ38 -> 0 | EQ38: =EO38/(EP38*K38) -> #DIV/0! | ER38: =IF($K38>0.01,1,0) -> 0 | EU38: =DK38 -> 0 | EV38: =CU38 -> 0 | EW38: =I38*CU38 -> 0 | EX38: =DR38 -> 0 | EZ38: =EW38-EX38 -> 0 | FA38: =+IF(EZ38/I38<0,0,(EZ38/I38)) -> #DIV/0!
I39: =IF(E39>0.0001,0,0) -> 0 | K39: =E39*60 -> 0 | AN39: =SUM(M39:AM39) -> 0 | AP39: =K39-AN39 -> 0 | CS39: =SUM(AU39:CR39) -> 0 | CU39: =AP39-CS39 -> 0 | CW39: =(SUM(M39:Z39))/K39 -> #DIV/0! | CX39: =(SUM(AA39:AM39))/K39 -> #DIV/0! | CY39: =(SUM(AU39:BQ39))/$K39 -> #DIV/0! | CZ39: =(SUM(BR39:CC39))/K39 -> #DIV/0! | DA39: =(SUM(CD39:CR39))/K39 -> #DIV/0! | DB39: =CU39/K39 -> #DIV/0! | DD39: =AP39 -> 0 | DE39: =CS39 -> 0 | DF39: =$DD39-DE39 -> 0 | DG39: =DF39/$DD39 -> #DIV/0! | DH39: =IF(AP39>0.01,1,0) -> 0 | DJ39: =H39 -> 0 | DK39: 0 | DL39: =DR39/DF39 -> #DIV/0! | DM39: =DL39/DK39 -> #DIV/0! | DN39: =IF(DM39>0.01,1,0) -> #DIV/0! | DR39: =DP39+DQ39 -> 0 | DS39: =IF(DL39=0,0,DP39/DR39) -> #DIV/0! | DT39: =IF(DS39>0.01,1,0) -> #DIV/0! | DV39: =DG39*DM39*DS39 -> #DIV/0! | DW39: =IF($AP39>0.01,1,0) -> 0 | DY39: =DP39 -> 0 | DZ39: =DK39 -> 0 | EA39: =+AP39 -> 0 | EB39: =DZ39*EA39 -> 0 | ED39: =DY39/EB39 -> #DIV/0! | EE39: =IF($AP39>0.01,1,0) -> 0 | EG39: =DP39 -> 0 | EH39: =K39 -> 0 | EI39: =SUM(M39:Z39) -> 0 | EJ39: =I39 -> 0 | EK39: =(EH39-EI39)*EJ39 -> 0 | EL39: =EG39/EK39 -> #DIV/0! | EM39: =IF(EK39>0.01,1,0) -> 0 | EO39: =EG39 -> 0 | EP39: =EJ39 -> 0 | EQ39: =EO39/(EP39*K39) -> #DIV/0! | ER39: =IF($K39>0.01,1,0) -> 0 | EU39: =DK39 -> 0 | EV39: =CU39 -> 0 | EW39: =I39*CU39 -> 0 | EX39: =DR39 -> 0 | EZ39: =EW39-EX39 -> 0 | FA39: =+IF(EZ39/I39<0,0,(EZ39/I39)) -> #DIV/0!
I40: =IF(E40>0.0001,0,0) -> 0 | K40: =E40*60 -> 0 | AN40: =SUM(M40:AM40) -> 0 | AP40: =K40-AN40 -> 0 | CS40: =SUM(AU40:CR40) -> 0 | CU40: =AP40-CS40 -> 0 | CW40: =(SUM(M40:Z40))/K40 -> #DIV/0! | CX40: =(SUM(AA40:AM40))/K40 -> #DIV/0! | CY40: =(SUM(AU40:BQ40))/$K40 -> #DIV/0! | CZ40: =(SUM(BR40:CC40))/K40 -> #DIV/0! | DA40: =(SUM(CD40:CR40))/K40 -> #DIV/0! | DB40: =CU40/K40 -> #DIV/0! | DD40: =AP40 -> 0 | DE40: =CS40 -> 0 | DF40: =$DD40-DE40 -> 0 | DG40: =DF40/$DD40 -> #DIV/0! | DH40: =IF(AP40>0.01,1,0) -> 0 | DJ40: =H40 -> 0 | DK40: 0 | DL40: =DR40/DF40 -> #DIV/0! | DM40: =DL40/DK40 -> #DIV/0! | DN40: =IF(DM40>0.01,1,0) -> #DIV/0! | DR40: =DP40+DQ40 -> 0 | DS40: =IF(DL40=0,0,DP40/DR40) -> #DIV/0! | DT40: =IF(DS40>0.01,1,0) -> #DIV/0! | DV40: =DG40*DM40*DS40 -> #DIV/0! | DW40: =IF($AP40>0.01,1,0) -> 0 | DY40: =DP40 -> 0 | DZ40: =DK40 -> 0 | EA40: =+AP40 -> 0 | EB40: =DZ40*EA40 -> 0 | ED40: =DY40/EB40 -> #DIV/0! | EE40: =IF($AP40>0.01,1,0) -> 0 | EG40: =DP40 -> 0 | EH40: =K40 -> 0 | EI40: =SUM(M40:Z40) -> 0 | EJ40: =I40 -> 0 | EK40: =(EH40-EI40)*EJ40 -> 0 | EL40: =EG40/EK40 -> #DIV/0! | EM40: =IF(EK40>0.01,1,0) -> 0 | EO40: =EG40 -> 0 | EP40: =EJ40 -> 0 | EQ40: =EO40/(EP40*K40) -> #DIV/0! | ER40: =IF($K40>0.01,1,0) -> 0 | EU40: =DK40 -> 0 | EV40: =CU40 -> 0 | EW40: =I40*CU40 -> 0 | EX40: =DR40 -> 0 | EZ40: =EW40-EX40 -> 0 | FA40: =+IF(EZ40/I40<0,0,(EZ40/I40)) -> #DIV/0!
I41: =IF(E41>0.0001,0,0) -> 0 | K41: =E41*60 -> 0 | AN41: =SUM(M41:AM41) -> 0 | AP41: =K41-AN41 -> 0 | CS41: =SUM(AU41:CR41) -> 0 | CU41: =AP41-CS41 -> 0 | CW41: =(SUM(M41:Z41))/K41 -> #DIV/0! | CX41: =(SUM(AA41:AM41))/K41 -> #DIV/0! | CY41: =(SUM(AU41:BQ41))/$K41 -> #DIV/0! | CZ41: =(SUM(BR41:CC41))/K41 -> #DIV/0! | DA41: =(SUM(CD41:CR41))/K41 -> #DIV/0! | DB41: =CU41/K41 -> #DIV/0! | DD41: =AP41 -> 0 | DE41: =CS41 -> 0 | DF41: =$DD41-DE41 -> 0 | DG41: =DF41/$DD41 -> #DIV/0! | DH41: =IF(AP41>0.01,1,0) -> 0 | DJ41: =H41 -> 0 | DK41: =I41 -> 0 | DL41: =DR41/DF41 -> #DIV/0! | DM41: =DL41/DK41 -> #DIV/0! | DN41: =IF(DM41>0.01,1,0) -> #DIV/0! | DR41: =DP41+DQ41 -> 0 | DS41: =IF(DL41=0,0,DP41/DR41) -> #DIV/0! | DT41: =IF(DS41>0.01,1,0) -> #DIV/0! | DV41: =DG41*DM41*DS41 -> #DIV/0! | DW41: =IF($AP41>0.01,1,0) -> 0 | DY41: =DP41 -> 0 | DZ41: =DK41 -> 0 | EA41: =+AP41 -> 0 | EB41: =DZ41*EA41 -> 0 | ED41: =DY41/EB41 -> #DIV/0! | EE41: =IF($AP41>0.01,1,0) -> 0 | EG41: =DP41 -> 0 | EH41: =K41 -> 0 | EI41: =SUM(M41:Z41) -> 0 | EJ41: =I41 -> 0 | EK41: =(EH41-EI41)*EJ41 -> 0 | EL41: =EG41/EK41 -> #DIV/0! | EM41: =IF(EK41>0.01,1,0) -> 0 | EO41: =EG41 -> 0 | EP41: =EJ41 -> 0 | EQ41: =EO41/(EP41*K41) -> #DIV/0! | ER41: =IF($K41>0.01,1,0) -> 0 | EU41: =DK41 -> 0 | EV41: =CU41 -> 0 | EW41: =I41*CU41 -> 0 | EX41: =DR41 -> 0 | EZ41: =EW41-EX41 -> 0 | FA41: =+IF(EZ41/I41<0,0,(EZ41/I41)) -> #DIV/0!
...

Sheet Milling
K1: AVAILABLE TIME - PLANNED DOWNTIME (UNCONTROLLABLE) = LOADING TIME | AR1: SAP NOTIFICATION | AU1: LOADING TIME - UNPLANNED DOWNTIME / CONTROLLABLE = OPERATING TIME (Uptime) | CW1: AVAILABLE TIME DISTRIBUTION (%) | DD1: AVAILABILITY RATE X PERFORMANCE RATE X QUALITY RATE = OEE | DY1: GOOD OUTPUT÷ AVAILABLE CAPACITY=CHECK OEE | EG1: GOOD OUTPUT ÷ PLANNED PRODUCTION UPTIME = ELOR | EO1: Good Output ÷ (Ideal Prod Rate x 480)= ELUR
K2: Avail. Time (min) | M2: PLANNED DOWNTIME | AA2: UNCONTROLLABLE | AN2: TOTAL UNCONTROLLABLE | AP2: LOADING TIME (min) | AR2: SAP BREAKDOWN NOTIFICATION (min) | AS2: SAP NOTIFICATION NUMBER | AU2: BREAKDOWN & FAILURES | BR2: SET-UP AND ADJUSTMENTS | CD2: IDLING AND MINOR STOPPAGE | CS2: TOTAL UNPLANNED DOWNTIME | CU2: UPTIME / Operating Time (min) | DD2: total uptime / loading time = AVAILABILITY | DJ2: actual prod rate / ideal prod rate = PERFORMANCE | DP2: Good output / total output = QUALITY | DV2: OEE | DY2: Good Output (L) | DZ2: Ideal Prod Rate X Avail Time = Avail Cap | EB2: Available Capacity (L) | ED2: Check OEE | EG2: Good Output (L) | EH2: (Available time - Planned Downtime) X Ideal Prod Rate = Planned Production Time | EL2: ELOR | EO2: Good Output (L) | EP2: Ideal Production Rate (L/Min) | EQ2: ELUR | EW2: ideal prod rate X uptime | EZ2: Total Expected - Total Output | FA2: Variance÷Ideal Prod Rate
